2025-01-28 02:26:45,607 - __main__ - INFO - 
STARTING THE BOT

2025-01-28 02:26:46,394 - __main__ - INFO - 
BOT HAS STARTED

2025-01-28 02:26:46,394 - __main__ - INFO - 
BOT IS RUNNING

2025-01-28 02:26:46,394 - __main__ - INFO - 
WAITING FOR USER INTERACTIONS...

2025-01-28 02:26:47,417 - httpx - INFO - HTTP Request: POST https://api.telegram.org/bot8077274379:AAFawJIixuMK47T9RpxiMv0TC_FnYLA6LWI/getMe "HTTP/1.1 200 OK"
2025-01-28 02:26:47,619 - httpx - INFO - HTTP Request: POST https://api.telegram.org/bot8077274379:AAFawJIixuMK47T9RpxiMv0TC_FnYLA6LWI/deleteWebhook "HTTP/1.1 200 OK"
2025-01-28 02:26:47,622 - telegram.ext.Application - INFO - Application started
2025-01-28 02:26:52,345 - httpx - INFO - HTTP Request: POST https://api.telegram.org/bot8077274379:AAFawJIixuMK47T9RpxiMv0TC_FnYLA6LWI/getUpdates "HTTP/1.1 409 Conflict"
2025-01-28 02:26:52,384 - telegram.ext.Application - ERROR - No error handlers are registered, logging exception.
Traceback (most recent call last):
  File "C:\Users\atikm\AppData\Local\Programs\Python\Python313\Lib\site-packages\telegram\ext\_updater.py", line 750, in _network_loop_retry
    if not await do_action():
           ^^^^^^^^^^^^^^^^^
  File "C:\Users\atikm\AppData\Local\Programs\Python\Python313\Lib\site-packages\telegram\ext\_updater.py", line 744, in do_action
    return action_cb_task.result()
           ~~~~~~~~~~~~~~~~~~~~~^^
  File "C:\Users\atikm\AppData\Local\Programs\Python\Python313\Lib\asyncio\futures.py", line 199, in result
    raise self._exception.with_traceback(self._exception_tb)
  File "C:\Users\atikm\AppData\Local\Programs\Python\Python313\Lib\asyncio\tasks.py", line 304, in __step_run_and_handle_result
    result = coro.send(None)
  File "C:\Users\atikm\AppData\Local\Programs\Python\Python313\Lib\site-packages\telegram\ext\_updater.py", line 371, in polling_action_cb
    updates = await self.bot.get_updates(
              ^^^^^^^^^^^^^^^^^^^^^^^^^^^
    ...<7 lines>...
    )
    ^
  File "C:\Users\atikm\AppData\Local\Programs\Python\Python313\Lib\site-packages\telegram\ext\_extbot.py", line 650, in get_updates
    updates = await super().get_updates(
              ^^^^^^^^^^^^^^^^^^^^^^^^^^
    ...<9 lines>...
    )
    ^
  File "C:\Users\atikm\AppData\Local\Programs\Python\Python313\Lib\site-packages\telegram\_bot.py", line 4480, in get_updates
    await self._post(
    ^^^^^^^^^^^^^^^^^
    ...<7 lines>...
    ),
    ^
  File "C:\Users\atikm\AppData\Local\Programs\Python\Python313\Lib\site-packages\telegram\_bot.py", line 619, in _post
    return await self._do_post(
           ^^^^^^^^^^^^^^^^^^^^
    ...<6 lines>...
    )
    ^
  File "C:\Users\atikm\AppData\Local\Programs\Python\Python313\Lib\site-packages\telegram\ext\_extbot.py", line 354, in _do_post
    return await super()._do_post(
           ^^^^^^^^^^^^^^^^^^^^^^^
    ...<6 lines>...
    )
    ^
  File "C:\Users\atikm\AppData\Local\Programs\Python\Python313\Lib\site-packages\telegram\_bot.py", line 648, in _do_post
    result = await request.post(
             ^^^^^^^^^^^^^^^^^^^
    ...<6 lines>...
    )
    ^
  File "C:\Users\atikm\AppData\Local\Programs\Python\Python313\Lib\site-packages\telegram\request\_baserequest.py", line 202, in post
    result = await self._request_wrapper(
             ^^^^^^^^^^^^^^^^^^^^^^^^^^^^
    ...<7 lines>...
    )
    ^
  File "C:\Users\atikm\AppData\Local\Programs\Python\Python313\Lib\site-packages\telegram\request\_baserequest.py", line 385, in _request_wrapper
    raise Conflict(message)
telegram.error.Conflict: Conflict: terminated by other getUpdates request; make sure that only one bot instance is running
2025-01-28 02:26:54,168 - httpx - INFO - HTTP Request: POST https://api.telegram.org/bot8077274379:AAFawJIixuMK47T9RpxiMv0TC_FnYLA6LWI/getUpdates "HTTP/1.1 200 OK"
2025-01-28 02:26:54,171 - __main__ - INFO - INFO - User ERROR (ID: 2142334821) started the bot.
2025-01-28 02:26:54,789 - httpx - INFO - HTTP Request: POST https://api.telegram.org/bot8077274379:AAFawJIixuMK47T9RpxiMv0TC_FnYLA6LWI/sendMessage "HTTP/1.1 200 OK"
2025-01-28 02:26:58,336 - httpx - INFO - HTTP Request: POST https://api.telegram.org/bot8077274379:AAFawJIixuMK47T9RpxiMv0TC_FnYLA6LWI/getUpdates "HTTP/1.1 409 Conflict"
2025-01-28 02:26:58,338 - telegram.ext.Application - ERROR - No error handlers are registered, logging exception.
Traceback (most recent call last):
  File "C:\Users\atikm\AppData\Local\Programs\Python\Python313\Lib\site-packages\telegram\ext\_updater.py", line 750, in _network_loop_retry
    if not await do_action():
           ^^^^^^^^^^^^^^^^^
  File "C:\Users\atikm\AppData\Local\Programs\Python\Python313\Lib\site-packages\telegram\ext\_updater.py", line 744, in do_action
    return action_cb_task.result()
           ~~~~~~~~~~~~~~~~~~~~~^^
  File "C:\Users\atikm\AppData\Local\Programs\Python\Python313\Lib\asyncio\futures.py", line 199, in result
    raise self._exception.with_traceback(self._exception_tb)
  File "C:\Users\atikm\AppData\Local\Programs\Python\Python313\Lib\asyncio\tasks.py", line 304, in __step_run_and_handle_result
    result = coro.send(None)
  File "C:\Users\atikm\AppData\Local\Programs\Python\Python313\Lib\site-packages\telegram\ext\_updater.py", line 371, in polling_action_cb
    updates = await self.bot.get_updates(
              ^^^^^^^^^^^^^^^^^^^^^^^^^^^
    ...<7 lines>...
    )
    ^
  File "C:\Users\atikm\AppData\Local\Programs\Python\Python313\Lib\site-packages\telegram\ext\_extbot.py", line 650, in get_updates
    updates = await super().get_updates(
              ^^^^^^^^^^^^^^^^^^^^^^^^^^
    ...<9 lines>...
    )
    ^
  File "C:\Users\atikm\AppData\Local\Programs\Python\Python313\Lib\site-packages\telegram\_bot.py", line 4480, in get_updates
    await self._post(
    ^^^^^^^^^^^^^^^^^
    ...<7 lines>...
    ),
    ^
  File "C:\Users\atikm\AppData\Local\Programs\Python\Python313\Lib\site-packages\telegram\_bot.py", line 619, in _post
    return await self._do_post(
           ^^^^^^^^^^^^^^^^^^^^
    ...<6 lines>...
    )
    ^
  File "C:\Users\atikm\AppData\Local\Programs\Python\Python313\Lib\site-packages\telegram\ext\_extbot.py", line 354, in _do_post
    return await super()._do_post(
           ^^^^^^^^^^^^^^^^^^^^^^^
    ...<6 lines>...
    )
    ^
  File "C:\Users\atikm\AppData\Local\Programs\Python\Python313\Lib\site-packages\telegram\_bot.py", line 648, in _do_post
    result = await request.post(
             ^^^^^^^^^^^^^^^^^^^
    ...<6 lines>...
    )
    ^
  File "C:\Users\atikm\AppData\Local\Programs\Python\Python313\Lib\site-packages\telegram\request\_baserequest.py", line 202, in post
    result = await self._request_wrapper(
             ^^^^^^^^^^^^^^^^^^^^^^^^^^^^
    ...<7 lines>...
    )
    ^
  File "C:\Users\atikm\AppData\Local\Programs\Python\Python313\Lib\site-packages\telegram\request\_baserequest.py", line 385, in _request_wrapper
    raise Conflict(message)
telegram.error.Conflict: Conflict: terminated by other getUpdates request; make sure that only one bot instance is running
2025-01-28 02:27:04,905 - httpx - INFO - HTTP Request: POST https://api.telegram.org/bot8077274379:AAFawJIixuMK47T9RpxiMv0TC_FnYLA6LWI/getUpdates "HTTP/1.1 409 Conflict"
2025-01-28 02:27:04,907 - telegram.ext.Application - ERROR - No error handlers are registered, logging exception.
Traceback (most recent call last):
  File "C:\Users\atikm\AppData\Local\Programs\Python\Python313\Lib\site-packages\telegram\ext\_updater.py", line 750, in _network_loop_retry
    if not await do_action():
           ^^^^^^^^^^^^^^^^^
  File "C:\Users\atikm\AppData\Local\Programs\Python\Python313\Lib\site-packages\telegram\ext\_updater.py", line 744, in do_action
    return action_cb_task.result()
           ~~~~~~~~~~~~~~~~~~~~~^^
  File "C:\Users\atikm\AppData\Local\Programs\Python\Python313\Lib\asyncio\futures.py", line 199, in result
    raise self._exception.with_traceback(self._exception_tb)
  File "C:\Users\atikm\AppData\Local\Programs\Python\Python313\Lib\asyncio\tasks.py", line 304, in __step_run_and_handle_result
    result = coro.send(None)
  File "C:\Users\atikm\AppData\Local\Programs\Python\Python313\Lib\site-packages\telegram\ext\_updater.py", line 371, in polling_action_cb
    updates = await self.bot.get_updates(
              ^^^^^^^^^^^^^^^^^^^^^^^^^^^
    ...<7 lines>...
    )
    ^
  File "C:\Users\atikm\AppData\Local\Programs\Python\Python313\Lib\site-packages\telegram\ext\_extbot.py", line 650, in get_updates
    updates = await super().get_updates(
              ^^^^^^^^^^^^^^^^^^^^^^^^^^
    ...<9 lines>...
    )
    ^
  File "C:\Users\atikm\AppData\Local\Programs\Python\Python313\Lib\site-packages\telegram\_bot.py", line 4480, in get_updates
    await self._post(
    ^^^^^^^^^^^^^^^^^
    ...<7 lines>...
    ),
    ^
  File "C:\Users\atikm\AppData\Local\Programs\Python\Python313\Lib\site-packages\telegram\_bot.py", line 619, in _post
    return await self._do_post(
           ^^^^^^^^^^^^^^^^^^^^
    ...<6 lines>...
    )
    ^
  File "C:\Users\atikm\AppData\Local\Programs\Python\Python313\Lib\site-packages\telegram\ext\_extbot.py", line 354, in _do_post
    return await super()._do_post(
           ^^^^^^^^^^^^^^^^^^^^^^^
    ...<6 lines>...
    )
    ^
  File "C:\Users\atikm\AppData\Local\Programs\Python\Python313\Lib\site-packages\telegram\_bot.py", line 648, in _do_post
    result = await request.post(
             ^^^^^^^^^^^^^^^^^^^
    ...<6 lines>...
    )
    ^
  File "C:\Users\atikm\AppData\Local\Programs\Python\Python313\Lib\site-packages\telegram\request\_baserequest.py", line 202, in post
    result = await self._request_wrapper(
             ^^^^^^^^^^^^^^^^^^^^^^^^^^^^
    ...<7 lines>...
    )
    ^
  File "C:\Users\atikm\AppData\Local\Programs\Python\Python313\Lib\site-packages\telegram\request\_baserequest.py", line 385, in _request_wrapper
    raise Conflict(message)
telegram.error.Conflict: Conflict: terminated by other getUpdates request; make sure that only one bot instance is running
2025-01-28 02:27:08,509 - httpx - INFO - HTTP Request: POST https://api.telegram.org/bot8077274379:AAFawJIixuMK47T9RpxiMv0TC_FnYLA6LWI/getUpdates "HTTP/1.1 200 OK"
2025-01-28 02:27:08,511 - __main__ - INFO - INFO - User ERROR (ID: 2142334821) started the bot.
2025-01-28 02:27:09,729 - httpx - INFO - HTTP Request: POST https://api.telegram.org/bot8077274379:AAFawJIixuMK47T9RpxiMv0TC_FnYLA6LWI/sendMessage "HTTP/1.1 200 OK"
2025-01-28 02:27:10,145 - httpx - INFO - HTTP Request: POST https://api.telegram.org/bot8077274379:AAFawJIixuMK47T9RpxiMv0TC_FnYLA6LWI/getUpdates "HTTP/1.1 409 Conflict"
2025-01-28 02:27:10,146 - telegram.ext.Application - ERROR - No error handlers are registered, logging exception.
Traceback (most recent call last):
  File "C:\Users\atikm\AppData\Local\Programs\Python\Python313\Lib\site-packages\telegram\ext\_updater.py", line 750, in _network_loop_retry
    if not await do_action():
           ^^^^^^^^^^^^^^^^^
  File "C:\Users\atikm\AppData\Local\Programs\Python\Python313\Lib\site-packages\telegram\ext\_updater.py", line 744, in do_action
    return action_cb_task.result()
           ~~~~~~~~~~~~~~~~~~~~~^^
  File "C:\Users\atikm\AppData\Local\Programs\Python\Python313\Lib\asyncio\futures.py", line 199, in result
    raise self._exception.with_traceback(self._exception_tb)
  File "C:\Users\atikm\AppData\Local\Programs\Python\Python313\Lib\asyncio\tasks.py", line 304, in __step_run_and_handle_result
    result = coro.send(None)
  File "C:\Users\atikm\AppData\Local\Programs\Python\Python313\Lib\site-packages\telegram\ext\_updater.py", line 371, in polling_action_cb
    updates = await self.bot.get_updates(
              ^^^^^^^^^^^^^^^^^^^^^^^^^^^
    ...<7 lines>...
    )
    ^
  File "C:\Users\atikm\AppData\Local\Programs\Python\Python313\Lib\site-packages\telegram\ext\_extbot.py", line 650, in get_updates
    updates = await super().get_updates(
              ^^^^^^^^^^^^^^^^^^^^^^^^^^
    ...<9 lines>...
    )
    ^
  File "C:\Users\atikm\AppData\Local\Programs\Python\Python313\Lib\site-packages\telegram\_bot.py", line 4480, in get_updates
    await self._post(
    ^^^^^^^^^^^^^^^^^
    ...<7 lines>...
    ),
    ^
  File "C:\Users\atikm\AppData\Local\Programs\Python\Python313\Lib\site-packages\telegram\_bot.py", line 619, in _post
    return await self._do_post(
           ^^^^^^^^^^^^^^^^^^^^
    ...<6 lines>...
    )
    ^
  File "C:\Users\atikm\AppData\Local\Programs\Python\Python313\Lib\site-packages\telegram\ext\_extbot.py", line 354, in _do_post
    return await super()._do_post(
           ^^^^^^^^^^^^^^^^^^^^^^^
    ...<6 lines>...
    )
    ^
  File "C:\Users\atikm\AppData\Local\Programs\Python\Python313\Lib\site-packages\telegram\_bot.py", line 648, in _do_post
    result = await request.post(
             ^^^^^^^^^^^^^^^^^^^
    ...<6 lines>...
    )
    ^
  File "C:\Users\atikm\AppData\Local\Programs\Python\Python313\Lib\site-packages\telegram\request\_baserequest.py", line 202, in post
    result = await self._request_wrapper(
             ^^^^^^^^^^^^^^^^^^^^^^^^^^^^
    ...<7 lines>...
    )
    ^
  File "C:\Users\atikm\AppData\Local\Programs\Python\Python313\Lib\site-packages\telegram\request\_baserequest.py", line 385, in _request_wrapper
    raise Conflict(message)
telegram.error.Conflict: Conflict: terminated by other getUpdates request; make sure that only one bot instance is running
2025-01-28 02:27:19,986 - httpx - INFO - HTTP Request: POST https://api.telegram.org/bot8077274379:AAFawJIixuMK47T9RpxiMv0TC_FnYLA6LWI/getUpdates "HTTP/1.1 409 Conflict"
2025-01-28 02:27:19,987 - telegram.ext.Application - ERROR - No error handlers are registered, logging exception.
Traceback (most recent call last):
  File "C:\Users\atikm\AppData\Local\Programs\Python\Python313\Lib\site-packages\telegram\ext\_updater.py", line 750, in _network_loop_retry
    if not await do_action():
           ^^^^^^^^^^^^^^^^^
  File "C:\Users\atikm\AppData\Local\Programs\Python\Python313\Lib\site-packages\telegram\ext\_updater.py", line 744, in do_action
    return action_cb_task.result()
           ~~~~~~~~~~~~~~~~~~~~~^^
  File "C:\Users\atikm\AppData\Local\Programs\Python\Python313\Lib\asyncio\futures.py", line 199, in result
    raise self._exception.with_traceback(self._exception_tb)
  File "C:\Users\atikm\AppData\Local\Programs\Python\Python313\Lib\asyncio\tasks.py", line 304, in __step_run_and_handle_result
    result = coro.send(None)
  File "C:\Users\atikm\AppData\Local\Programs\Python\Python313\Lib\site-packages\telegram\ext\_updater.py", line 371, in polling_action_cb
    updates = await self.bot.get_updates(
              ^^^^^^^^^^^^^^^^^^^^^^^^^^^
    ...<7 lines>...
    )
    ^
  File "C:\Users\atikm\AppData\Local\Programs\Python\Python313\Lib\site-packages\telegram\ext\_extbot.py", line 650, in get_updates
    updates = await super().get_updates(
              ^^^^^^^^^^^^^^^^^^^^^^^^^^
    ...<9 lines>...
    )
    ^
  File "C:\Users\atikm\AppData\Local\Programs\Python\Python313\Lib\site-packages\telegram\_bot.py", line 4480, in get_updates
    await self._post(
    ^^^^^^^^^^^^^^^^^
    ...<7 lines>...
    ),
    ^
  File "C:\Users\atikm\AppData\Local\Programs\Python\Python313\Lib\site-packages\telegram\_bot.py", line 619, in _post
    return await self._do_post(
           ^^^^^^^^^^^^^^^^^^^^
    ...<6 lines>...
    )
    ^
  File "C:\Users\atikm\AppData\Local\Programs\Python\Python313\Lib\site-packages\telegram\ext\_extbot.py", line 354, in _do_post
    return await super()._do_post(
           ^^^^^^^^^^^^^^^^^^^^^^^
    ...<6 lines>...
    )
    ^
  File "C:\Users\atikm\AppData\Local\Programs\Python\Python313\Lib\site-packages\telegram\_bot.py", line 648, in _do_post
    result = await request.post(
             ^^^^^^^^^^^^^^^^^^^
    ...<6 lines>...
    )
    ^
  File "C:\Users\atikm\AppData\Local\Programs\Python\Python313\Lib\site-packages\telegram\request\_baserequest.py", line 202, in post
    result = await self._request_wrapper(
             ^^^^^^^^^^^^^^^^^^^^^^^^^^^^
    ...<7 lines>...
    )
    ^
  File "C:\Users\atikm\AppData\Local\Programs\Python\Python313\Lib\site-packages\telegram\request\_baserequest.py", line 385, in _request_wrapper
    raise Conflict(message)
telegram.error.Conflict: Conflict: terminated by other getUpdates request; make sure that only one bot instance is running
2025-01-28 02:27:24,281 - httpx - INFO - HTTP Request: POST https://api.telegram.org/bot8077274379:AAFawJIixuMK47T9RpxiMv0TC_FnYLA6LWI/getUpdates "HTTP/1.1 200 OK"
2025-01-28 02:27:25,140 - httpx - INFO - HTTP Request: POST https://api.telegram.org/bot8077274379:AAFawJIixuMK47T9RpxiMv0TC_FnYLA6LWI/sendMessage "HTTP/1.1 200 OK"
2025-01-28 02:27:32,776 - httpx - INFO - HTTP Request: POST https://api.telegram.org/bot8077274379:AAFawJIixuMK47T9RpxiMv0TC_FnYLA6LWI/getUpdates "HTTP/1.1 409 Conflict"
2025-01-28 02:27:32,778 - telegram.ext.Application - ERROR - No error handlers are registered, logging exception.
Traceback (most recent call last):
  File "C:\Users\atikm\AppData\Local\Programs\Python\Python313\Lib\site-packages\telegram\ext\_updater.py", line 750, in _network_loop_retry
    if not await do_action():
           ^^^^^^^^^^^^^^^^^
  File "C:\Users\atikm\AppData\Local\Programs\Python\Python313\Lib\site-packages\telegram\ext\_updater.py", line 744, in do_action
    return action_cb_task.result()
           ~~~~~~~~~~~~~~~~~~~~~^^
  File "C:\Users\atikm\AppData\Local\Programs\Python\Python313\Lib\asyncio\futures.py", line 199, in result
    raise self._exception.with_traceback(self._exception_tb)
  File "C:\Users\atikm\AppData\Local\Programs\Python\Python313\Lib\asyncio\tasks.py", line 304, in __step_run_and_handle_result
    result = coro.send(None)
  File "C:\Users\atikm\AppData\Local\Programs\Python\Python313\Lib\site-packages\telegram\ext\_updater.py", line 371, in polling_action_cb
    updates = await self.bot.get_updates(
              ^^^^^^^^^^^^^^^^^^^^^^^^^^^
    ...<7 lines>...
    )
    ^
  File "C:\Users\atikm\AppData\Local\Programs\Python\Python313\Lib\site-packages\telegram\ext\_extbot.py", line 650, in get_updates
    updates = await super().get_updates(
              ^^^^^^^^^^^^^^^^^^^^^^^^^^
    ...<9 lines>...
    )
    ^
  File "C:\Users\atikm\AppData\Local\Programs\Python\Python313\Lib\site-packages\telegram\_bot.py", line 4480, in get_updates
    await self._post(
    ^^^^^^^^^^^^^^^^^
    ...<7 lines>...
    ),
    ^
  File "C:\Users\atikm\AppData\Local\Programs\Python\Python313\Lib\site-packages\telegram\_bot.py", line 619, in _post
    return await self._do_post(
           ^^^^^^^^^^^^^^^^^^^^
    ...<6 lines>...
    )
    ^
  File "C:\Users\atikm\AppData\Local\Programs\Python\Python313\Lib\site-packages\telegram\ext\_extbot.py", line 354, in _do_post
    return await super()._do_post(
           ^^^^^^^^^^^^^^^^^^^^^^^
    ...<6 lines>...
    )
    ^
  File "C:\Users\atikm\AppData\Local\Programs\Python\Python313\Lib\site-packages\telegram\_bot.py", line 648, in _do_post
    result = await request.post(
             ^^^^^^^^^^^^^^^^^^^
    ...<6 lines>...
    )
    ^
  File "C:\Users\atikm\AppData\Local\Programs\Python\Python313\Lib\site-packages\telegram\request\_baserequest.py", line 202, in post
    result = await self._request_wrapper(
             ^^^^^^^^^^^^^^^^^^^^^^^^^^^^
    ...<7 lines>...
    )
    ^
  File "C:\Users\atikm\AppData\Local\Programs\Python\Python313\Lib\site-packages\telegram\request\_baserequest.py", line 385, in _request_wrapper
    raise Conflict(message)
telegram.error.Conflict: Conflict: terminated by other getUpdates request; make sure that only one bot instance is running
2025-01-28 02:27:43,943 - httpx - INFO - HTTP Request: POST https://api.telegram.org/bot8077274379:AAFawJIixuMK47T9RpxiMv0TC_FnYLA6LWI/getUpdates "HTTP/1.1 200 OK"
2025-01-28 02:27:48,840 - httpx - INFO - HTTP Request: POST https://api.telegram.org/bot8077274379:AAFawJIixuMK47T9RpxiMv0TC_FnYLA6LWI/getUpdates "HTTP/1.1 409 Conflict"
2025-01-28 02:27:48,842 - telegram.ext.Application - ERROR - No error handlers are registered, logging exception.
Traceback (most recent call last):
  File "C:\Users\atikm\AppData\Local\Programs\Python\Python313\Lib\site-packages\telegram\ext\_updater.py", line 750, in _network_loop_retry
    if not await do_action():
           ^^^^^^^^^^^^^^^^^
  File "C:\Users\atikm\AppData\Local\Programs\Python\Python313\Lib\site-packages\telegram\ext\_updater.py", line 744, in do_action
    return action_cb_task.result()
           ~~~~~~~~~~~~~~~~~~~~~^^
  File "C:\Users\atikm\AppData\Local\Programs\Python\Python313\Lib\asyncio\futures.py", line 199, in result
    raise self._exception.with_traceback(self._exception_tb)
  File "C:\Users\atikm\AppData\Local\Programs\Python\Python313\Lib\asyncio\tasks.py", line 304, in __step_run_and_handle_result
    result = coro.send(None)
  File "C:\Users\atikm\AppData\Local\Programs\Python\Python313\Lib\site-packages\telegram\ext\_updater.py", line 371, in polling_action_cb
    updates = await self.bot.get_updates(
              ^^^^^^^^^^^^^^^^^^^^^^^^^^^
    ...<7 lines>...
    )
    ^
  File "C:\Users\atikm\AppData\Local\Programs\Python\Python313\Lib\site-packages\telegram\ext\_extbot.py", line 650, in get_updates
    updates = await super().get_updates(
              ^^^^^^^^^^^^^^^^^^^^^^^^^^
    ...<9 lines>...
    )
    ^
  File "C:\Users\atikm\AppData\Local\Programs\Python\Python313\Lib\site-packages\telegram\_bot.py", line 4480, in get_updates
    await self._post(
    ^^^^^^^^^^^^^^^^^
    ...<7 lines>...
    ),
    ^
  File "C:\Users\atikm\AppData\Local\Programs\Python\Python313\Lib\site-packages\telegram\_bot.py", line 619, in _post
    return await self._do_post(
           ^^^^^^^^^^^^^^^^^^^^
    ...<6 lines>...
    )
    ^
  File "C:\Users\atikm\AppData\Local\Programs\Python\Python313\Lib\site-packages\telegram\ext\_extbot.py", line 354, in _do_post
    return await super()._do_post(
           ^^^^^^^^^^^^^^^^^^^^^^^
    ...<6 lines>...
    )
    ^
  File "C:\Users\atikm\AppData\Local\Programs\Python\Python313\Lib\site-packages\telegram\_bot.py", line 648, in _do_post
    result = await request.post(
             ^^^^^^^^^^^^^^^^^^^
    ...<6 lines>...
    )
    ^
  File "C:\Users\atikm\AppData\Local\Programs\Python\Python313\Lib\site-packages\telegram\request\_baserequest.py", line 202, in post
    result = await self._request_wrapper(
             ^^^^^^^^^^^^^^^^^^^^^^^^^^^^
    ...<7 lines>...
    )
    ^
  File "C:\Users\atikm\AppData\Local\Programs\Python\Python313\Lib\site-packages\telegram\request\_baserequest.py", line 385, in _request_wrapper
    raise Conflict(message)
telegram.error.Conflict: Conflict: terminated by other getUpdates request; make sure that only one bot instance is running
2025-01-28 02:28:00,121 - httpx - INFO - HTTP Request: POST https://api.telegram.org/bot8077274379:AAFawJIixuMK47T9RpxiMv0TC_FnYLA6LWI/getUpdates "HTTP/1.1 200 OK"
2025-01-28 02:28:10,273 - httpx - INFO - HTTP Request: POST https://api.telegram.org/bot8077274379:AAFawJIixuMK47T9RpxiMv0TC_FnYLA6LWI/getUpdates "HTTP/1.1 200 OK"
2025-01-28 02:28:10,579 - httpx - INFO - HTTP Request: POST https://api.telegram.org/bot8077274379:AAFawJIixuMK47T9RpxiMv0TC_FnYLA6LWI/getUpdates "HTTP/1.1 409 Conflict"
2025-01-28 02:28:10,598 - telegram.ext.Application - ERROR - No error handlers are registered, logging exception.
Traceback (most recent call last):
  File "C:\Users\atikm\AppData\Local\Programs\Python\Python313\Lib\site-packages\telegram\ext\_updater.py", line 750, in _network_loop_retry
    if not await do_action():
           ^^^^^^^^^^^^^^^^^
  File "C:\Users\atikm\AppData\Local\Programs\Python\Python313\Lib\site-packages\telegram\ext\_updater.py", line 744, in do_action
    return action_cb_task.result()
           ~~~~~~~~~~~~~~~~~~~~~^^
  File "C:\Users\atikm\AppData\Local\Programs\Python\Python313\Lib\asyncio\futures.py", line 199, in result
    raise self._exception.with_traceback(self._exception_tb)
  File "C:\Users\atikm\AppData\Local\Programs\Python\Python313\Lib\asyncio\tasks.py", line 304, in __step_run_and_handle_result
    result = coro.send(None)
  File "C:\Users\atikm\AppData\Local\Programs\Python\Python313\Lib\site-packages\telegram\ext\_updater.py", line 371, in polling_action_cb
    updates = await self.bot.get_updates(
              ^^^^^^^^^^^^^^^^^^^^^^^^^^^
    ...<7 lines>...
    )
    ^
  File "C:\Users\atikm\AppData\Local\Programs\Python\Python313\Lib\site-packages\telegram\ext\_extbot.py", line 650, in get_updates
    updates = await super().get_updates(
              ^^^^^^^^^^^^^^^^^^^^^^^^^^
    ...<9 lines>...
    )
    ^
  File "C:\Users\atikm\AppData\Local\Programs\Python\Python313\Lib\site-packages\telegram\_bot.py", line 4480, in get_updates
    await self._post(
    ^^^^^^^^^^^^^^^^^
    ...<7 lines>...
    ),
    ^
  File "C:\Users\atikm\AppData\Local\Programs\Python\Python313\Lib\site-packages\telegram\_bot.py", line 619, in _post
    return await self._do_post(
           ^^^^^^^^^^^^^^^^^^^^
    ...<6 lines>...
    )
    ^
  File "C:\Users\atikm\AppData\Local\Programs\Python\Python313\Lib\site-packages\telegram\ext\_extbot.py", line 354, in _do_post
    return await super()._do_post(
           ^^^^^^^^^^^^^^^^^^^^^^^
    ...<6 lines>...
    )
    ^
  File "C:\Users\atikm\AppData\Local\Programs\Python\Python313\Lib\site-packages\telegram\_bot.py", line 648, in _do_post
    result = await request.post(
             ^^^^^^^^^^^^^^^^^^^
    ...<6 lines>...
    )
    ^
  File "C:\Users\atikm\AppData\Local\Programs\Python\Python313\Lib\site-packages\telegram\request\_baserequest.py", line 202, in post
    result = await self._request_wrapper(
             ^^^^^^^^^^^^^^^^^^^^^^^^^^^^
    ...<7 lines>...
    )
    ^
  File "C:\Users\atikm\AppData\Local\Programs\Python\Python313\Lib\site-packages\telegram\request\_baserequest.py", line 385, in _request_wrapper
    raise Conflict(message)
telegram.error.Conflict: Conflict: terminated by other getUpdates request; make sure that only one bot instance is running
2025-01-28 02:28:21,749 - httpx - INFO - HTTP Request: POST https://api.telegram.org/bot8077274379:AAFawJIixuMK47T9RpxiMv0TC_FnYLA6LWI/getUpdates "HTTP/1.1 200 OK"
2025-01-28 02:28:31,924 - httpx - INFO - HTTP Request: POST https://api.telegram.org/bot8077274379:AAFawJIixuMK47T9RpxiMv0TC_FnYLA6LWI/getUpdates "HTTP/1.1 200 OK"
2025-01-28 02:28:40,976 - httpx - INFO - HTTP Request: POST https://api.telegram.org/bot8077274379:AAFawJIixuMK47T9RpxiMv0TC_FnYLA6LWI/getUpdates "HTTP/1.1 409 Conflict"
2025-01-28 02:28:40,984 - telegram.ext.Application - ERROR - No error handlers are registered, logging exception.
Traceback (most recent call last):
  File "C:\Users\atikm\AppData\Local\Programs\Python\Python313\Lib\site-packages\telegram\ext\_updater.py", line 750, in _network_loop_retry
    if not await do_action():
           ^^^^^^^^^^^^^^^^^
  File "C:\Users\atikm\AppData\Local\Programs\Python\Python313\Lib\site-packages\telegram\ext\_updater.py", line 744, in do_action
    return action_cb_task.result()
           ~~~~~~~~~~~~~~~~~~~~~^^
  File "C:\Users\atikm\AppData\Local\Programs\Python\Python313\Lib\asyncio\futures.py", line 199, in result
    raise self._exception.with_traceback(self._exception_tb)
  File "C:\Users\atikm\AppData\Local\Programs\Python\Python313\Lib\asyncio\tasks.py", line 304, in __step_run_and_handle_result
    result = coro.send(None)
  File "C:\Users\atikm\AppData\Local\Programs\Python\Python313\Lib\site-packages\telegram\ext\_updater.py", line 371, in polling_action_cb
    updates = await self.bot.get_updates(
              ^^^^^^^^^^^^^^^^^^^^^^^^^^^
    ...<7 lines>...
    )
    ^
  File "C:\Users\atikm\AppData\Local\Programs\Python\Python313\Lib\site-packages\telegram\ext\_extbot.py", line 650, in get_updates
    updates = await super().get_updates(
              ^^^^^^^^^^^^^^^^^^^^^^^^^^
    ...<9 lines>...
    )
    ^
  File "C:\Users\atikm\AppData\Local\Programs\Python\Python313\Lib\site-packages\telegram\_bot.py", line 4480, in get_updates
    await self._post(
    ^^^^^^^^^^^^^^^^^
    ...<7 lines>...
    ),
    ^
  File "C:\Users\atikm\AppData\Local\Programs\Python\Python313\Lib\site-packages\telegram\_bot.py", line 619, in _post
    return await self._do_post(
           ^^^^^^^^^^^^^^^^^^^^
    ...<6 lines>...
    )
    ^
  File "C:\Users\atikm\AppData\Local\Programs\Python\Python313\Lib\site-packages\telegram\ext\_extbot.py", line 354, in _do_post
    return await super()._do_post(
           ^^^^^^^^^^^^^^^^^^^^^^^
    ...<6 lines>...
    )
    ^
  File "C:\Users\atikm\AppData\Local\Programs\Python\Python313\Lib\site-packages\telegram\_bot.py", line 648, in _do_post
    result = await request.post(
             ^^^^^^^^^^^^^^^^^^^
    ...<6 lines>...
    )
    ^
  File "C:\Users\atikm\AppData\Local\Programs\Python\Python313\Lib\site-packages\telegram\request\_baserequest.py", line 202, in post
    result = await self._request_wrapper(
             ^^^^^^^^^^^^^^^^^^^^^^^^^^^^
    ...<7 lines>...
    )
    ^
  File "C:\Users\atikm\AppData\Local\Programs\Python\Python313\Lib\site-packages\telegram\request\_baserequest.py", line 385, in _request_wrapper
    raise Conflict(message)
telegram.error.Conflict: Conflict: terminated by other getUpdates request; make sure that only one bot instance is running
2025-01-28 02:28:52,252 - httpx - INFO - HTTP Request: POST https://api.telegram.org/bot8077274379:AAFawJIixuMK47T9RpxiMv0TC_FnYLA6LWI/getUpdates "HTTP/1.1 200 OK"
2025-01-28 02:29:02,479 - httpx - INFO - HTTP Request: POST https://api.telegram.org/bot8077274379:AAFawJIixuMK47T9RpxiMv0TC_FnYLA6LWI/getUpdates "HTTP/1.1 200 OK"
2025-01-28 02:29:12,715 - httpx - INFO - HTTP Request: POST https://api.telegram.org/bot8077274379:AAFawJIixuMK47T9RpxiMv0TC_FnYLA6LWI/getUpdates "HTTP/1.1 200 OK"
2025-01-28 02:29:15,641 - httpx - INFO - HTTP Request: POST https://api.telegram.org/bot8077274379:AAFawJIixuMK47T9RpxiMv0TC_FnYLA6LWI/getUpdates "HTTP/1.1 409 Conflict"
2025-01-28 02:29:15,643 - telegram.ext.Application - ERROR - No error handlers are registered, logging exception.
Traceback (most recent call last):
  File "C:\Users\atikm\AppData\Local\Programs\Python\Python313\Lib\site-packages\telegram\ext\_updater.py", line 750, in _network_loop_retry
    if not await do_action():
           ^^^^^^^^^^^^^^^^^
  File "C:\Users\atikm\AppData\Local\Programs\Python\Python313\Lib\site-packages\telegram\ext\_updater.py", line 744, in do_action
    return action_cb_task.result()
           ~~~~~~~~~~~~~~~~~~~~~^^
  File "C:\Users\atikm\AppData\Local\Programs\Python\Python313\Lib\asyncio\futures.py", line 199, in result
    raise self._exception.with_traceback(self._exception_tb)
  File "C:\Users\atikm\AppData\Local\Programs\Python\Python313\Lib\asyncio\tasks.py", line 304, in __step_run_and_handle_result
    result = coro.send(None)
  File "C:\Users\atikm\AppData\Local\Programs\Python\Python313\Lib\site-packages\telegram\ext\_updater.py", line 371, in polling_action_cb
    updates = await self.bot.get_updates(
              ^^^^^^^^^^^^^^^^^^^^^^^^^^^
    ...<7 lines>...
    )
    ^
  File "C:\Users\atikm\AppData\Local\Programs\Python\Python313\Lib\site-packages\telegram\ext\_extbot.py", line 650, in get_updates
    updates = await super().get_updates(
              ^^^^^^^^^^^^^^^^^^^^^^^^^^
    ...<9 lines>...
    )
    ^
  File "C:\Users\atikm\AppData\Local\Programs\Python\Python313\Lib\site-packages\telegram\_bot.py", line 4480, in get_updates
    await self._post(
    ^^^^^^^^^^^^^^^^^
    ...<7 lines>...
    ),
    ^
  File "C:\Users\atikm\AppData\Local\Programs\Python\Python313\Lib\site-packages\telegram\_bot.py", line 619, in _post
    return await self._do_post(
           ^^^^^^^^^^^^^^^^^^^^
    ...<6 lines>...
    )
    ^
  File "C:\Users\atikm\AppData\Local\Programs\Python\Python313\Lib\site-packages\telegram\ext\_extbot.py", line 354, in _do_post
    return await super()._do_post(
           ^^^^^^^^^^^^^^^^^^^^^^^
    ...<6 lines>...
    )
    ^
  File "C:\Users\atikm\AppData\Local\Programs\Python\Python313\Lib\site-packages\telegram\_bot.py", line 648, in _do_post
    result = await request.post(
             ^^^^^^^^^^^^^^^^^^^
    ...<6 lines>...
    )
    ^
  File "C:\Users\atikm\AppData\Local\Programs\Python\Python313\Lib\site-packages\telegram\request\_baserequest.py", line 202, in post
    result = await self._request_wrapper(
             ^^^^^^^^^^^^^^^^^^^^^^^^^^^^
    ...<7 lines>...
    )
    ^
  File "C:\Users\atikm\AppData\Local\Programs\Python\Python313\Lib\site-packages\telegram\request\_baserequest.py", line 385, in _request_wrapper
    raise Conflict(message)
telegram.error.Conflict: Conflict: terminated by other getUpdates request; make sure that only one bot instance is running
2025-01-28 02:29:26,858 - httpx - INFO - HTTP Request: POST https://api.telegram.org/bot8077274379:AAFawJIixuMK47T9RpxiMv0TC_FnYLA6LWI/getUpdates "HTTP/1.1 200 OK"
2025-01-28 02:29:37,092 - httpx - INFO - HTTP Request: POST https://api.telegram.org/bot8077274379:AAFawJIixuMK47T9RpxiMv0TC_FnYLA6LWI/getUpdates "HTTP/1.1 200 OK"
2025-01-28 02:29:47,328 - httpx - INFO - HTTP Request: POST https://api.telegram.org/bot8077274379:AAFawJIixuMK47T9RpxiMv0TC_FnYLA6LWI/getUpdates "HTTP/1.1 200 OK"
2025-01-28 02:29:50,296 - httpx - INFO - HTTP Request: POST https://api.telegram.org/bot8077274379:AAFawJIixuMK47T9RpxiMv0TC_FnYLA6LWI/getUpdates "HTTP/1.1 409 Conflict"
2025-01-28 02:29:50,299 - telegram.ext.Application - ERROR - No error handlers are registered, logging exception.
Traceback (most recent call last):
  File "C:\Users\atikm\AppData\Local\Programs\Python\Python313\Lib\site-packages\telegram\ext\_updater.py", line 750, in _network_loop_retry
    if not await do_action():
           ^^^^^^^^^^^^^^^^^
  File "C:\Users\atikm\AppData\Local\Programs\Python\Python313\Lib\site-packages\telegram\ext\_updater.py", line 744, in do_action
    return action_cb_task.result()
           ~~~~~~~~~~~~~~~~~~~~~^^
  File "C:\Users\atikm\AppData\Local\Programs\Python\Python313\Lib\asyncio\futures.py", line 199, in result
    raise self._exception.with_traceback(self._exception_tb)
  File "C:\Users\atikm\AppData\Local\Programs\Python\Python313\Lib\asyncio\tasks.py", line 304, in __step_run_and_handle_result
    result = coro.send(None)
  File "C:\Users\atikm\AppData\Local\Programs\Python\Python313\Lib\site-packages\telegram\ext\_updater.py", line 371, in polling_action_cb
    updates = await self.bot.get_updates(
              ^^^^^^^^^^^^^^^^^^^^^^^^^^^
    ...<7 lines>...
    )
    ^
  File "C:\Users\atikm\AppData\Local\Programs\Python\Python313\Lib\site-packages\telegram\ext\_extbot.py", line 650, in get_updates
    updates = await super().get_updates(
              ^^^^^^^^^^^^^^^^^^^^^^^^^^
    ...<9 lines>...
    )
    ^
  File "C:\Users\atikm\AppData\Local\Programs\Python\Python313\Lib\site-packages\telegram\_bot.py", line 4480, in get_updates
    await self._post(
    ^^^^^^^^^^^^^^^^^
    ...<7 lines>...
    ),
    ^
  File "C:\Users\atikm\AppData\Local\Programs\Python\Python313\Lib\site-packages\telegram\_bot.py", line 619, in _post
    return await self._do_post(
           ^^^^^^^^^^^^^^^^^^^^
    ...<6 lines>...
    )
    ^
  File "C:\Users\atikm\AppData\Local\Programs\Python\Python313\Lib\site-packages\telegram\ext\_extbot.py", line 354, in _do_post
    return await super()._do_post(
           ^^^^^^^^^^^^^^^^^^^^^^^
    ...<6 lines>...
    )
    ^
  File "C:\Users\atikm\AppData\Local\Programs\Python\Python313\Lib\site-packages\telegram\_bot.py", line 648, in _do_post
    result = await request.post(
             ^^^^^^^^^^^^^^^^^^^
    ...<6 lines>...
    )
    ^
  File "C:\Users\atikm\AppData\Local\Programs\Python\Python313\Lib\site-packages\telegram\request\_baserequest.py", line 202, in post
    result = await self._request_wrapper(
             ^^^^^^^^^^^^^^^^^^^^^^^^^^^^
    ...<7 lines>...
    )
    ^
  File "C:\Users\atikm\AppData\Local\Programs\Python\Python313\Lib\site-packages\telegram\request\_baserequest.py", line 385, in _request_wrapper
    raise Conflict(message)
telegram.error.Conflict: Conflict: terminated by other getUpdates request; make sure that only one bot instance is running
2025-01-28 02:30:01,572 - httpx - INFO - HTTP Request: POST https://api.telegram.org/bot8077274379:AAFawJIixuMK47T9RpxiMv0TC_FnYLA6LWI/getUpdates "HTTP/1.1 200 OK"
2025-01-28 02:30:11,815 - httpx - INFO - HTTP Request: POST https://api.telegram.org/bot8077274379:AAFawJIixuMK47T9RpxiMv0TC_FnYLA6LWI/getUpdates "HTTP/1.1 200 OK"
2025-01-28 02:30:21,985 - httpx - INFO - HTTP Request: POST https://api.telegram.org/bot8077274379:AAFawJIixuMK47T9RpxiMv0TC_FnYLA6LWI/getUpdates "HTTP/1.1 200 OK"
2025-01-28 02:30:25,013 - httpx - INFO - HTTP Request: POST https://api.telegram.org/bot8077274379:AAFawJIixuMK47T9RpxiMv0TC_FnYLA6LWI/getUpdates "HTTP/1.1 409 Conflict"
2025-01-28 02:30:25,015 - telegram.ext.Application - ERROR - No error handlers are registered, logging exception.
Traceback (most recent call last):
  File "C:\Users\atikm\AppData\Local\Programs\Python\Python313\Lib\site-packages\telegram\ext\_updater.py", line 750, in _network_loop_retry
    if not await do_action():
           ^^^^^^^^^^^^^^^^^
  File "C:\Users\atikm\AppData\Local\Programs\Python\Python313\Lib\site-packages\telegram\ext\_updater.py", line 744, in do_action
    return action_cb_task.result()
           ~~~~~~~~~~~~~~~~~~~~~^^
  File "C:\Users\atikm\AppData\Local\Programs\Python\Python313\Lib\asyncio\futures.py", line 199, in result
    raise self._exception.with_traceback(self._exception_tb)
  File "C:\Users\atikm\AppData\Local\Programs\Python\Python313\Lib\asyncio\tasks.py", line 304, in __step_run_and_handle_result
    result = coro.send(None)
  File "C:\Users\atikm\AppData\Local\Programs\Python\Python313\Lib\site-packages\telegram\ext\_updater.py", line 371, in polling_action_cb
    updates = await self.bot.get_updates(
              ^^^^^^^^^^^^^^^^^^^^^^^^^^^
    ...<7 lines>...
    )
    ^
  File "C:\Users\atikm\AppData\Local\Programs\Python\Python313\Lib\site-packages\telegram\ext\_extbot.py", line 650, in get_updates
    updates = await super().get_updates(
              ^^^^^^^^^^^^^^^^^^^^^^^^^^
    ...<9 lines>...
    )
    ^
  File "C:\Users\atikm\AppData\Local\Programs\Python\Python313\Lib\site-packages\telegram\_bot.py", line 4480, in get_updates
    await self._post(
    ^^^^^^^^^^^^^^^^^
    ...<7 lines>...
    ),
    ^
  File "C:\Users\atikm\AppData\Local\Programs\Python\Python313\Lib\site-packages\telegram\_bot.py", line 619, in _post
    return await self._do_post(
           ^^^^^^^^^^^^^^^^^^^^
    ...<6 lines>...
    )
    ^
  File "C:\Users\atikm\AppData\Local\Programs\Python\Python313\Lib\site-packages\telegram\ext\_extbot.py", line 354, in _do_post
    return await super()._do_post(
           ^^^^^^^^^^^^^^^^^^^^^^^
    ...<6 lines>...
    )
    ^
  File "C:\Users\atikm\AppData\Local\Programs\Python\Python313\Lib\site-packages\telegram\_bot.py", line 648, in _do_post
    result = await request.post(
             ^^^^^^^^^^^^^^^^^^^
    ...<6 lines>...
    )
    ^
  File "C:\Users\atikm\AppData\Local\Programs\Python\Python313\Lib\site-packages\telegram\request\_baserequest.py", line 202, in post
    result = await self._request_wrapper(
             ^^^^^^^^^^^^^^^^^^^^^^^^^^^^
    ...<7 lines>...
    )
    ^
  File "C:\Users\atikm\AppData\Local\Programs\Python\Python313\Lib\site-packages\telegram\request\_baserequest.py", line 385, in _request_wrapper
    raise Conflict(message)
telegram.error.Conflict: Conflict: terminated by other getUpdates request; make sure that only one bot instance is running
2025-01-28 02:30:36,276 - httpx - INFO - HTTP Request: POST https://api.telegram.org/bot8077274379:AAFawJIixuMK47T9RpxiMv0TC_FnYLA6LWI/getUpdates "HTTP/1.1 200 OK"
2025-01-28 02:30:46,529 - httpx - INFO - HTTP Request: POST https://api.telegram.org/bot8077274379:AAFawJIixuMK47T9RpxiMv0TC_FnYLA6LWI/getUpdates "HTTP/1.1 200 OK"
2025-01-28 02:30:58,689 - __main__ - INFO - 
STARTING THE BOT

