2025-01-28 02:26:45,607 - __main__ - INFO - 
STARTING THE BOT

2025-01-28 02:26:46,394 - __main__ - INFO - 
BOT HAS STARTED

2025-01-28 02:26:46,394 - __main__ - INFO - 
BOT IS RUNNING

2025-01-28 02:26:46,394 - __main__ - INFO - 
WAITING FOR USER INTERACTIONS...

2025-01-28 02:26:47,417 - httpx - INFO - HTTP Request: POST https://api.telegram.org/bot8077274379:AAFawJIixuMK47T9RpxiMv0TC_FnYLA6LWI/getMe "HTTP/1.1 200 OK"
2025-01-28 02:26:47,619 - httpx - INFO - HTTP Request: POST https://api.telegram.org/bot8077274379:AAFawJIixuMK47T9RpxiMv0TC_FnYLA6LWI/deleteWebhook "HTTP/1.1 200 OK"
2025-01-28 02:26:47,622 - telegram.ext.Application - INFO - Application started
2025-01-28 02:26:52,345 - httpx - INFO - HTTP Request: POST https://api.telegram.org/bot8077274379:AAFawJIixuMK47T9RpxiMv0TC_FnYLA6LWI/getUpdates "HTTP/1.1 409 Conflict"
2025-01-28 02:26:52,384 - telegram.ext.Application - ERROR - No error handlers are registered, logging exception.
Traceback (most recent call last):
  File "C:\Users\atikm\AppData\Local\Programs\Python\Python313\Lib\site-packages\telegram\ext\_updater.py", line 750, in _network_loop_retry
    if not await do_action():
           ^^^^^^^^^^^^^^^^^
  File "C:\Users\atikm\AppData\Local\Programs\Python\Python313\Lib\site-packages\telegram\ext\_updater.py", line 744, in do_action
    return action_cb_task.result()
           ~~~~~~~~~~~~~~~~~~~~~^^
  File "C:\Users\atikm\AppData\Local\Programs\Python\Python313\Lib\asyncio\futures.py", line 199, in result
    raise self._exception.with_traceback(self._exception_tb)
  File "C:\Users\atikm\AppData\Local\Programs\Python\Python313\Lib\asyncio\tasks.py", line 304, in __step_run_and_handle_result
    result = coro.send(None)
  File "C:\Users\atikm\AppData\Local\Programs\Python\Python313\Lib\site-packages\telegram\ext\_updater.py", line 371, in polling_action_cb
    updates = await self.bot.get_updates(
              ^^^^^^^^^^^^^^^^^^^^^^^^^^^
    ...<7 lines>...
    )
    ^
  File "C:\Users\atikm\AppData\Local\Programs\Python\Python313\Lib\site-packages\telegram\ext\_extbot.py", line 650, in get_updates
    updates = await super().get_updates(
              ^^^^^^^^^^^^^^^^^^^^^^^^^^
    ...<9 lines>...
    )
    ^
  File "C:\Users\atikm\AppData\Local\Programs\Python\Python313\Lib\site-packages\telegram\_bot.py", line 4480, in get_updates
    await self._post(
    ^^^^^^^^^^^^^^^^^
    ...<7 lines>...
    ),
    ^
  File "C:\Users\atikm\AppData\Local\Programs\Python\Python313\Lib\site-packages\telegram\_bot.py", line 619, in _post
    return await self._do_post(
           ^^^^^^^^^^^^^^^^^^^^
    ...<6 lines>...
    )
    ^
  File "C:\Users\atikm\AppData\Local\Programs\Python\Python313\Lib\site-packages\telegram\ext\_extbot.py", line 354, in _do_post
    return await super()._do_post(
           ^^^^^^^^^^^^^^^^^^^^^^^
    ...<6 lines>...
    )
    ^
  File "C:\Users\atikm\AppData\Local\Programs\Python\Python313\Lib\site-packages\telegram\_bot.py", line 648, in _do_post
    result = await request.post(
             ^^^^^^^^^^^^^^^^^^^
    ...<6 lines>...
    )
    ^
  File "C:\Users\atikm\AppData\Local\Programs\Python\Python313\Lib\site-packages\telegram\request\_baserequest.py", line 202, in post
    result = await self._request_wrapper(
             ^^^^^^^^^^^^^^^^^^^^^^^^^^^^
    ...<7 lines>...
    )
    ^
  File "C:\Users\atikm\AppData\Local\Programs\Python\Python313\Lib\site-packages\telegram\request\_baserequest.py", line 385, in _request_wrapper
    raise Conflict(message)
telegram.error.Conflict: Conflict: terminated by other getUpdates request; make sure that only one bot instance is running
2025-01-28 02:26:54,168 - httpx - INFO - HTTP Request: POST https://api.telegram.org/bot8077274379:AAFawJIixuMK47T9RpxiMv0TC_FnYLA6LWI/getUpdates "HTTP/1.1 200 OK"
2025-01-28 02:26:54,171 - __main__ - INFO - INFO - User ERROR (ID: 2142334821) started the bot.
2025-01-28 02:26:54,789 - httpx - INFO - HTTP Request: POST https://api.telegram.org/bot8077274379:AAFawJIixuMK47T9RpxiMv0TC_FnYLA6LWI/sendMessage "HTTP/1.1 200 OK"
2025-01-28 02:26:58,336 - httpx - INFO - HTTP Request: POST https://api.telegram.org/bot8077274379:AAFawJIixuMK47T9RpxiMv0TC_FnYLA6LWI/getUpdates "HTTP/1.1 409 Conflict"
2025-01-28 02:26:58,338 - telegram.ext.Application - ERROR - No error handlers are registered, logging exception.
Traceback (most recent call last):
  File "C:\Users\atikm\AppData\Local\Programs\Python\Python313\Lib\site-packages\telegram\ext\_updater.py", line 750, in _network_loop_retry
    if not await do_action():
           ^^^^^^^^^^^^^^^^^
  File "C:\Users\atikm\AppData\Local\Programs\Python\Python313\Lib\site-packages\telegram\ext\_updater.py", line 744, in do_action
    return action_cb_task.result()
           ~~~~~~~~~~~~~~~~~~~~~^^
  File "C:\Users\atikm\AppData\Local\Programs\Python\Python313\Lib\asyncio\futures.py", line 199, in result
    raise self._exception.with_traceback(self._exception_tb)
  File "C:\Users\atikm\AppData\Local\Programs\Python\Python313\Lib\asyncio\tasks.py", line 304, in __step_run_and_handle_result
    result = coro.send(None)
  File "C:\Users\atikm\AppData\Local\Programs\Python\Python313\Lib\site-packages\telegram\ext\_updater.py", line 371, in polling_action_cb
    updates = await self.bot.get_updates(
              ^^^^^^^^^^^^^^^^^^^^^^^^^^^
    ...<7 lines>...
    )
    ^
  File "C:\Users\atikm\AppData\Local\Programs\Python\Python313\Lib\site-packages\telegram\ext\_extbot.py", line 650, in get_updates
    updates = await super().get_updates(
              ^^^^^^^^^^^^^^^^^^^^^^^^^^
    ...<9 lines>...
    )
    ^
  File "C:\Users\atikm\AppData\Local\Programs\Python\Python313\Lib\site-packages\telegram\_bot.py", line 4480, in get_updates
    await self._post(
    ^^^^^^^^^^^^^^^^^
    ...<7 lines>...
    ),
    ^
  File "C:\Users\atikm\AppData\Local\Programs\Python\Python313\Lib\site-packages\telegram\_bot.py", line 619, in _post
    return await self._do_post(
           ^^^^^^^^^^^^^^^^^^^^
    ...<6 lines>...
    )
    ^
  File "C:\Users\atikm\AppData\Local\Programs\Python\Python313\Lib\site-packages\telegram\ext\_extbot.py", line 354, in _do_post
    return await super()._do_post(
           ^^^^^^^^^^^^^^^^^^^^^^^
    ...<6 lines>...
    )
    ^
  File "C:\Users\atikm\AppData\Local\Programs\Python\Python313\Lib\site-packages\telegram\_bot.py", line 648, in _do_post
    result = await request.post(
             ^^^^^^^^^^^^^^^^^^^
    ...<6 lines>...
    )
    ^
  File "C:\Users\atikm\AppData\Local\Programs\Python\Python313\Lib\site-packages\telegram\request\_baserequest.py", line 202, in post
    result = await self._request_wrapper(
             ^^^^^^^^^^^^^^^^^^^^^^^^^^^^
    ...<7 lines>...
    )
    ^
  File "C:\Users\atikm\AppData\Local\Programs\Python\Python313\Lib\site-packages\telegram\request\_baserequest.py", line 385, in _request_wrapper
    raise Conflict(message)
telegram.error.Conflict: Conflict: terminated by other getUpdates request; make sure that only one bot instance is running
2025-01-28 02:27:04,905 - httpx - INFO - HTTP Request: POST https://api.telegram.org/bot8077274379:AAFawJIixuMK47T9RpxiMv0TC_FnYLA6LWI/getUpdates "HTTP/1.1 409 Conflict"
2025-01-28 02:27:04,907 - telegram.ext.Application - ERROR - No error handlers are registered, logging exception.
Traceback (most recent call last):
  File "C:\Users\atikm\AppData\Local\Programs\Python\Python313\Lib\site-packages\telegram\ext\_updater.py", line 750, in _network_loop_retry
    if not await do_action():
           ^^^^^^^^^^^^^^^^^
  File "C:\Users\atikm\AppData\Local\Programs\Python\Python313\Lib\site-packages\telegram\ext\_updater.py", line 744, in do_action
    return action_cb_task.result()
           ~~~~~~~~~~~~~~~~~~~~~^^
  File "C:\Users\atikm\AppData\Local\Programs\Python\Python313\Lib\asyncio\futures.py", line 199, in result
    raise self._exception.with_traceback(self._exception_tb)
  File "C:\Users\atikm\AppData\Local\Programs\Python\Python313\Lib\asyncio\tasks.py", line 304, in __step_run_and_handle_result
    result = coro.send(None)
  File "C:\Users\atikm\AppData\Local\Programs\Python\Python313\Lib\site-packages\telegram\ext\_updater.py", line 371, in polling_action_cb
    updates = await self.bot.get_updates(
              ^^^^^^^^^^^^^^^^^^^^^^^^^^^
    ...<7 lines>...
    )
    ^
  File "C:\Users\atikm\AppData\Local\Programs\Python\Python313\Lib\site-packages\telegram\ext\_extbot.py", line 650, in get_updates
    updates = await super().get_updates(
              ^^^^^^^^^^^^^^^^^^^^^^^^^^
    ...<9 lines>...
    )
    ^
  File "C:\Users\atikm\AppData\Local\Programs\Python\Python313\Lib\site-packages\telegram\_bot.py", line 4480, in get_updates
    await self._post(
    ^^^^^^^^^^^^^^^^^
    ...<7 lines>...
    ),
    ^
  File "C:\Users\atikm\AppData\Local\Programs\Python\Python313\Lib\site-packages\telegram\_bot.py", line 619, in _post
    return await self._do_post(
           ^^^^^^^^^^^^^^^^^^^^
    ...<6 lines>...
    )
    ^
  File "C:\Users\atikm\AppData\Local\Programs\Python\Python313\Lib\site-packages\telegram\ext\_extbot.py", line 354, in _do_post
    return await super()._do_post(
           ^^^^^^^^^^^^^^^^^^^^^^^
    ...<6 lines>...
    )
    ^
  File "C:\Users\atikm\AppData\Local\Programs\Python\Python313\Lib\site-packages\telegram\_bot.py", line 648, in _do_post
    result = await request.post(
             ^^^^^^^^^^^^^^^^^^^
    ...<6 lines>...
    )
    ^
  File "C:\Users\atikm\AppData\Local\Programs\Python\Python313\Lib\site-packages\telegram\request\_baserequest.py", line 202, in post
    result = await self._request_wrapper(
             ^^^^^^^^^^^^^^^^^^^^^^^^^^^^
    ...<7 lines>...
    )
    ^
  File "C:\Users\atikm\AppData\Local\Programs\Python\Python313\Lib\site-packages\telegram\request\_baserequest.py", line 385, in _request_wrapper
    raise Conflict(message)
telegram.error.Conflict: Conflict: terminated by other getUpdates request; make sure that only one bot instance is running
2025-01-28 02:27:08,509 - httpx - INFO - HTTP Request: POST https://api.telegram.org/bot8077274379:AAFawJIixuMK47T9RpxiMv0TC_FnYLA6LWI/getUpdates "HTTP/1.1 200 OK"
2025-01-28 02:27:08,511 - __main__ - INFO - INFO - User ERROR (ID: 2142334821) started the bot.
2025-01-28 02:27:09,729 - httpx - INFO - HTTP Request: POST https://api.telegram.org/bot8077274379:AAFawJIixuMK47T9RpxiMv0TC_FnYLA6LWI/sendMessage "HTTP/1.1 200 OK"
2025-01-28 02:27:10,145 - httpx - INFO - HTTP Request: POST https://api.telegram.org/bot8077274379:AAFawJIixuMK47T9RpxiMv0TC_FnYLA6LWI/getUpdates "HTTP/1.1 409 Conflict"
2025-01-28 02:27:10,146 - telegram.ext.Application - ERROR - No error handlers are registered, logging exception.
Traceback (most recent call last):
  File "C:\Users\atikm\AppData\Local\Programs\Python\Python313\Lib\site-packages\telegram\ext\_updater.py", line 750, in _network_loop_retry
    if not await do_action():
           ^^^^^^^^^^^^^^^^^
  File "C:\Users\atikm\AppData\Local\Programs\Python\Python313\Lib\site-packages\telegram\ext\_updater.py", line 744, in do_action
    return action_cb_task.result()
           ~~~~~~~~~~~~~~~~~~~~~^^
  File "C:\Users\atikm\AppData\Local\Programs\Python\Python313\Lib\asyncio\futures.py", line 199, in result
    raise self._exception.with_traceback(self._exception_tb)
  File "C:\Users\atikm\AppData\Local\Programs\Python\Python313\Lib\asyncio\tasks.py", line 304, in __step_run_and_handle_result
    result = coro.send(None)
  File "C:\Users\atikm\AppData\Local\Programs\Python\Python313\Lib\site-packages\telegram\ext\_updater.py", line 371, in polling_action_cb
    updates = await self.bot.get_updates(
              ^^^^^^^^^^^^^^^^^^^^^^^^^^^
    ...<7 lines>...
    )
    ^
  File "C:\Users\atikm\AppData\Local\Programs\Python\Python313\Lib\site-packages\telegram\ext\_extbot.py", line 650, in get_updates
    updates = await super().get_updates(
              ^^^^^^^^^^^^^^^^^^^^^^^^^^
    ...<9 lines>...
    )
    ^
  File "C:\Users\atikm\AppData\Local\Programs\Python\Python313\Lib\site-packages\telegram\_bot.py", line 4480, in get_updates
    await self._post(
    ^^^^^^^^^^^^^^^^^
    ...<7 lines>...
    ),
    ^
  File "C:\Users\atikm\AppData\Local\Programs\Python\Python313\Lib\site-packages\telegram\_bot.py", line 619, in _post
    return await self._do_post(
           ^^^^^^^^^^^^^^^^^^^^
    ...<6 lines>...
    )
    ^
  File "C:\Users\atikm\AppData\Local\Programs\Python\Python313\Lib\site-packages\telegram\ext\_extbot.py", line 354, in _do_post
    return await super()._do_post(
           ^^^^^^^^^^^^^^^^^^^^^^^
    ...<6 lines>...
    )
    ^
  File "C:\Users\atikm\AppData\Local\Programs\Python\Python313\Lib\site-packages\telegram\_bot.py", line 648, in _do_post
    result = await request.post(
             ^^^^^^^^^^^^^^^^^^^
    ...<6 lines>...
    )
    ^
  File "C:\Users\atikm\AppData\Local\Programs\Python\Python313\Lib\site-packages\telegram\request\_baserequest.py", line 202, in post
    result = await self._request_wrapper(
             ^^^^^^^^^^^^^^^^^^^^^^^^^^^^
    ...<7 lines>...
    )
    ^
  File "C:\Users\atikm\AppData\Local\Programs\Python\Python313\Lib\site-packages\telegram\request\_baserequest.py", line 385, in _request_wrapper
    raise Conflict(message)
telegram.error.Conflict: Conflict: terminated by other getUpdates request; make sure that only one bot instance is running
2025-01-28 02:27:19,986 - httpx - INFO - HTTP Request: POST https://api.telegram.org/bot8077274379:AAFawJIixuMK47T9RpxiMv0TC_FnYLA6LWI/getUpdates "HTTP/1.1 409 Conflict"
2025-01-28 02:27:19,987 - telegram.ext.Application - ERROR - No error handlers are registered, logging exception.
Traceback (most recent call last):
  File "C:\Users\atikm\AppData\Local\Programs\Python\Python313\Lib\site-packages\telegram\ext\_updater.py", line 750, in _network_loop_retry
    if not await do_action():
           ^^^^^^^^^^^^^^^^^
  File "C:\Users\atikm\AppData\Local\Programs\Python\Python313\Lib\site-packages\telegram\ext\_updater.py", line 744, in do_action
    return action_cb_task.result()
           ~~~~~~~~~~~~~~~~~~~~~^^
  File "C:\Users\atikm\AppData\Local\Programs\Python\Python313\Lib\asyncio\futures.py", line 199, in result
    raise self._exception.with_traceback(self._exception_tb)
  File "C:\Users\atikm\AppData\Local\Programs\Python\Python313\Lib\asyncio\tasks.py", line 304, in __step_run_and_handle_result
    result = coro.send(None)
  File "C:\Users\atikm\AppData\Local\Programs\Python\Python313\Lib\site-packages\telegram\ext\_updater.py", line 371, in polling_action_cb
    updates = await self.bot.get_updates(
              ^^^^^^^^^^^^^^^^^^^^^^^^^^^
    ...<7 lines>...
    )
    ^
  File "C:\Users\atikm\AppData\Local\Programs\Python\Python313\Lib\site-packages\telegram\ext\_extbot.py", line 650, in get_updates
    updates = await super().get_updates(
              ^^^^^^^^^^^^^^^^^^^^^^^^^^
    ...<9 lines>...
    )
    ^
  File "C:\Users\atikm\AppData\Local\Programs\Python\Python313\Lib\site-packages\telegram\_bot.py", line 4480, in get_updates
    await self._post(
    ^^^^^^^^^^^^^^^^^
    ...<7 lines>...
    ),
    ^
  File "C:\Users\atikm\AppData\Local\Programs\Python\Python313\Lib\site-packages\telegram\_bot.py", line 619, in _post
    return await self._do_post(
           ^^^^^^^^^^^^^^^^^^^^
    ...<6 lines>...
    )
    ^
  File "C:\Users\atikm\AppData\Local\Programs\Python\Python313\Lib\site-packages\telegram\ext\_extbot.py", line 354, in _do_post
    return await super()._do_post(
           ^^^^^^^^^^^^^^^^^^^^^^^
    ...<6 lines>...
    )
    ^
  File "C:\Users\atikm\AppData\Local\Programs\Python\Python313\Lib\site-packages\telegram\_bot.py", line 648, in _do_post
    result = await request.post(
             ^^^^^^^^^^^^^^^^^^^
    ...<6 lines>...
    )
    ^
  File "C:\Users\atikm\AppData\Local\Programs\Python\Python313\Lib\site-packages\telegram\request\_baserequest.py", line 202, in post
    result = await self._request_wrapper(
             ^^^^^^^^^^^^^^^^^^^^^^^^^^^^
    ...<7 lines>...
    )
    ^
  File "C:\Users\atikm\AppData\Local\Programs\Python\Python313\Lib\site-packages\telegram\request\_baserequest.py", line 385, in _request_wrapper
    raise Conflict(message)
telegram.error.Conflict: Conflict: terminated by other getUpdates request; make sure that only one bot instance is running
2025-01-28 02:27:24,281 - httpx - INFO - HTTP Request: POST https://api.telegram.org/bot8077274379:AAFawJIixuMK47T9RpxiMv0TC_FnYLA6LWI/getUpdates "HTTP/1.1 200 OK"
2025-01-28 02:27:25,140 - httpx - INFO - HTTP Request: POST https://api.telegram.org/bot8077274379:AAFawJIixuMK47T9RpxiMv0TC_FnYLA6LWI/sendMessage "HTTP/1.1 200 OK"
2025-01-28 02:27:32,776 - httpx - INFO - HTTP Request: POST https://api.telegram.org/bot8077274379:AAFawJIixuMK47T9RpxiMv0TC_FnYLA6LWI/getUpdates "HTTP/1.1 409 Conflict"
2025-01-28 02:27:32,778 - telegram.ext.Application - ERROR - No error handlers are registered, logging exception.
Traceback (most recent call last):
  File "C:\Users\atikm\AppData\Local\Programs\Python\Python313\Lib\site-packages\telegram\ext\_updater.py", line 750, in _network_loop_retry
    if not await do_action():
           ^^^^^^^^^^^^^^^^^
  File "C:\Users\atikm\AppData\Local\Programs\Python\Python313\Lib\site-packages\telegram\ext\_updater.py", line 744, in do_action
    return action_cb_task.result()
           ~~~~~~~~~~~~~~~~~~~~~^^
  File "C:\Users\atikm\AppData\Local\Programs\Python\Python313\Lib\asyncio\futures.py", line 199, in result
    raise self._exception.with_traceback(self._exception_tb)
  File "C:\Users\atikm\AppData\Local\Programs\Python\Python313\Lib\asyncio\tasks.py", line 304, in __step_run_and_handle_result
    result = coro.send(None)
  File "C:\Users\atikm\AppData\Local\Programs\Python\Python313\Lib\site-packages\telegram\ext\_updater.py", line 371, in polling_action_cb
    updates = await self.bot.get_updates(
              ^^^^^^^^^^^^^^^^^^^^^^^^^^^
    ...<7 lines>...
    )
    ^
  File "C:\Users\atikm\AppData\Local\Programs\Python\Python313\Lib\site-packages\telegram\ext\_extbot.py", line 650, in get_updates
    updates = await super().get_updates(
              ^^^^^^^^^^^^^^^^^^^^^^^^^^
    ...<9 lines>...
    )
    ^
  File "C:\Users\atikm\AppData\Local\Programs\Python\Python313\Lib\site-packages\telegram\_bot.py", line 4480, in get_updates
    await self._post(
    ^^^^^^^^^^^^^^^^^
    ...<7 lines>...
    ),
    ^
  File "C:\Users\atikm\AppData\Local\Programs\Python\Python313\Lib\site-packages\telegram\_bot.py", line 619, in _post
    return await self._do_post(
           ^^^^^^^^^^^^^^^^^^^^
    ...<6 lines>...
    )
    ^
  File "C:\Users\atikm\AppData\Local\Programs\Python\Python313\Lib\site-packages\telegram\ext\_extbot.py", line 354, in _do_post
    return await super()._do_post(
           ^^^^^^^^^^^^^^^^^^^^^^^
    ...<6 lines>...
    )
    ^
  File "C:\Users\atikm\AppData\Local\Programs\Python\Python313\Lib\site-packages\telegram\_bot.py", line 648, in _do_post
    result = await request.post(
             ^^^^^^^^^^^^^^^^^^^
    ...<6 lines>...
    )
    ^
  File "C:\Users\atikm\AppData\Local\Programs\Python\Python313\Lib\site-packages\telegram\request\_baserequest.py", line 202, in post
    result = await self._request_wrapper(
             ^^^^^^^^^^^^^^^^^^^^^^^^^^^^
    ...<7 lines>...
    )
    ^
  File "C:\Users\atikm\AppData\Local\Programs\Python\Python313\Lib\site-packages\telegram\request\_baserequest.py", line 385, in _request_wrapper
    raise Conflict(message)
telegram.error.Conflict: Conflict: terminated by other getUpdates request; make sure that only one bot instance is running
2025-01-28 02:27:43,943 - httpx - INFO - HTTP Request: POST https://api.telegram.org/bot8077274379:AAFawJIixuMK47T9RpxiMv0TC_FnYLA6LWI/getUpdates "HTTP/1.1 200 OK"
2025-01-28 02:27:48,840 - httpx - INFO - HTTP Request: POST https://api.telegram.org/bot8077274379:AAFawJIixuMK47T9RpxiMv0TC_FnYLA6LWI/getUpdates "HTTP/1.1 409 Conflict"
2025-01-28 02:27:48,842 - telegram.ext.Application - ERROR - No error handlers are registered, logging exception.
Traceback (most recent call last):
  File "C:\Users\atikm\AppData\Local\Programs\Python\Python313\Lib\site-packages\telegram\ext\_updater.py", line 750, in _network_loop_retry
    if not await do_action():
           ^^^^^^^^^^^^^^^^^
  File "C:\Users\atikm\AppData\Local\Programs\Python\Python313\Lib\site-packages\telegram\ext\_updater.py", line 744, in do_action
    return action_cb_task.result()
           ~~~~~~~~~~~~~~~~~~~~~^^
  File "C:\Users\atikm\AppData\Local\Programs\Python\Python313\Lib\asyncio\futures.py", line 199, in result
    raise self._exception.with_traceback(self._exception_tb)
  File "C:\Users\atikm\AppData\Local\Programs\Python\Python313\Lib\asyncio\tasks.py", line 304, in __step_run_and_handle_result
    result = coro.send(None)
  File "C:\Users\atikm\AppData\Local\Programs\Python\Python313\Lib\site-packages\telegram\ext\_updater.py", line 371, in polling_action_cb
    updates = await self.bot.get_updates(
              ^^^^^^^^^^^^^^^^^^^^^^^^^^^
    ...<7 lines>...
    )
    ^
  File "C:\Users\atikm\AppData\Local\Programs\Python\Python313\Lib\site-packages\telegram\ext\_extbot.py", line 650, in get_updates
    updates = await super().get_updates(
              ^^^^^^^^^^^^^^^^^^^^^^^^^^
    ...<9 lines>...
    )
    ^
  File "C:\Users\atikm\AppData\Local\Programs\Python\Python313\Lib\site-packages\telegram\_bot.py", line 4480, in get_updates
    await self._post(
    ^^^^^^^^^^^^^^^^^
    ...<7 lines>...
    ),
    ^
  File "C:\Users\atikm\AppData\Local\Programs\Python\Python313\Lib\site-packages\telegram\_bot.py", line 619, in _post
    return await self._do_post(
           ^^^^^^^^^^^^^^^^^^^^
    ...<6 lines>...
    )
    ^
  File "C:\Users\atikm\AppData\Local\Programs\Python\Python313\Lib\site-packages\telegram\ext\_extbot.py", line 354, in _do_post
    return await super()._do_post(
           ^^^^^^^^^^^^^^^^^^^^^^^
    ...<6 lines>...
    )
    ^
  File "C:\Users\atikm\AppData\Local\Programs\Python\Python313\Lib\site-packages\telegram\_bot.py", line 648, in _do_post
    result = await request.post(
             ^^^^^^^^^^^^^^^^^^^
    ...<6 lines>...
    )
    ^
  File "C:\Users\atikm\AppData\Local\Programs\Python\Python313\Lib\site-packages\telegram\request\_baserequest.py", line 202, in post
    result = await self._request_wrapper(
             ^^^^^^^^^^^^^^^^^^^^^^^^^^^^
    ...<7 lines>...
    )
    ^
  File "C:\Users\atikm\AppData\Local\Programs\Python\Python313\Lib\site-packages\telegram\request\_baserequest.py", line 385, in _request_wrapper
    raise Conflict(message)
telegram.error.Conflict: Conflict: terminated by other getUpdates request; make sure that only one bot instance is running
2025-01-28 02:28:00,121 - httpx - INFO - HTTP Request: POST https://api.telegram.org/bot8077274379:AAFawJIixuMK47T9RpxiMv0TC_FnYLA6LWI/getUpdates "HTTP/1.1 200 OK"
2025-01-28 02:28:10,273 - httpx - INFO - HTTP Request: POST https://api.telegram.org/bot8077274379:AAFawJIixuMK47T9RpxiMv0TC_FnYLA6LWI/getUpdates "HTTP/1.1 200 OK"
2025-01-28 02:28:10,579 - httpx - INFO - HTTP Request: POST https://api.telegram.org/bot8077274379:AAFawJIixuMK47T9RpxiMv0TC_FnYLA6LWI/getUpdates "HTTP/1.1 409 Conflict"
2025-01-28 02:28:10,598 - telegram.ext.Application - ERROR - No error handlers are registered, logging exception.
Traceback (most recent call last):
  File "C:\Users\atikm\AppData\Local\Programs\Python\Python313\Lib\site-packages\telegram\ext\_updater.py", line 750, in _network_loop_retry
    if not await do_action():
           ^^^^^^^^^^^^^^^^^
  File "C:\Users\atikm\AppData\Local\Programs\Python\Python313\Lib\site-packages\telegram\ext\_updater.py", line 744, in do_action
    return action_cb_task.result()
           ~~~~~~~~~~~~~~~~~~~~~^^
  File "C:\Users\atikm\AppData\Local\Programs\Python\Python313\Lib\asyncio\futures.py", line 199, in result
    raise self._exception.with_traceback(self._exception_tb)
  File "C:\Users\atikm\AppData\Local\Programs\Python\Python313\Lib\asyncio\tasks.py", line 304, in __step_run_and_handle_result
    result = coro.send(None)
  File "C:\Users\atikm\AppData\Local\Programs\Python\Python313\Lib\site-packages\telegram\ext\_updater.py", line 371, in polling_action_cb
    updates = await self.bot.get_updates(
              ^^^^^^^^^^^^^^^^^^^^^^^^^^^
    ...<7 lines>...
    )
    ^
  File "C:\Users\atikm\AppData\Local\Programs\Python\Python313\Lib\site-packages\telegram\ext\_extbot.py", line 650, in get_updates
    updates = await super().get_updates(
              ^^^^^^^^^^^^^^^^^^^^^^^^^^
    ...<9 lines>...
    )
    ^
  File "C:\Users\atikm\AppData\Local\Programs\Python\Python313\Lib\site-packages\telegram\_bot.py", line 4480, in get_updates
    await self._post(
    ^^^^^^^^^^^^^^^^^
    ...<7 lines>...
    ),
    ^
  File "C:\Users\atikm\AppData\Local\Programs\Python\Python313\Lib\site-packages\telegram\_bot.py", line 619, in _post
    return await self._do_post(
           ^^^^^^^^^^^^^^^^^^^^
    ...<6 lines>...
    )
    ^
  File "C:\Users\atikm\AppData\Local\Programs\Python\Python313\Lib\site-packages\telegram\ext\_extbot.py", line 354, in _do_post
    return await super()._do_post(
           ^^^^^^^^^^^^^^^^^^^^^^^
    ...<6 lines>...
    )
    ^
  File "C:\Users\atikm\AppData\Local\Programs\Python\Python313\Lib\site-packages\telegram\_bot.py", line 648, in _do_post
    result = await request.post(
             ^^^^^^^^^^^^^^^^^^^
    ...<6 lines>...
    )
    ^
  File "C:\Users\atikm\AppData\Local\Programs\Python\Python313\Lib\site-packages\telegram\request\_baserequest.py", line 202, in post
    result = await self._request_wrapper(
             ^^^^^^^^^^^^^^^^^^^^^^^^^^^^
    ...<7 lines>...
    )
    ^
  File "C:\Users\atikm\AppData\Local\Programs\Python\Python313\Lib\site-packages\telegram\request\_baserequest.py", line 385, in _request_wrapper
    raise Conflict(message)
telegram.error.Conflict: Conflict: terminated by other getUpdates request; make sure that only one bot instance is running
2025-01-28 02:28:21,749 - httpx - INFO - HTTP Request: POST https://api.telegram.org/bot8077274379:AAFawJIixuMK47T9RpxiMv0TC_FnYLA6LWI/getUpdates "HTTP/1.1 200 OK"
2025-01-28 02:28:31,924 - httpx - INFO - HTTP Request: POST https://api.telegram.org/bot8077274379:AAFawJIixuMK47T9RpxiMv0TC_FnYLA6LWI/getUpdates "HTTP/1.1 200 OK"
2025-01-28 02:28:40,976 - httpx - INFO - HTTP Request: POST https://api.telegram.org/bot8077274379:AAFawJIixuMK47T9RpxiMv0TC_FnYLA6LWI/getUpdates "HTTP/1.1 409 Conflict"
2025-01-28 02:28:40,984 - telegram.ext.Application - ERROR - No error handlers are registered, logging exception.
Traceback (most recent call last):
  File "C:\Users\atikm\AppData\Local\Programs\Python\Python313\Lib\site-packages\telegram\ext\_updater.py", line 750, in _network_loop_retry
    if not await do_action():
           ^^^^^^^^^^^^^^^^^
  File "C:\Users\atikm\AppData\Local\Programs\Python\Python313\Lib\site-packages\telegram\ext\_updater.py", line 744, in do_action
    return action_cb_task.result()
           ~~~~~~~~~~~~~~~~~~~~~^^
  File "C:\Users\atikm\AppData\Local\Programs\Python\Python313\Lib\asyncio\futures.py", line 199, in result
    raise self._exception.with_traceback(self._exception_tb)
  File "C:\Users\atikm\AppData\Local\Programs\Python\Python313\Lib\asyncio\tasks.py", line 304, in __step_run_and_handle_result
    result = coro.send(None)
  File "C:\Users\atikm\AppData\Local\Programs\Python\Python313\Lib\site-packages\telegram\ext\_updater.py", line 371, in polling_action_cb
    updates = await self.bot.get_updates(
              ^^^^^^^^^^^^^^^^^^^^^^^^^^^
    ...<7 lines>...
    )
    ^
  File "C:\Users\atikm\AppData\Local\Programs\Python\Python313\Lib\site-packages\telegram\ext\_extbot.py", line 650, in get_updates
    updates = await super().get_updates(
              ^^^^^^^^^^^^^^^^^^^^^^^^^^
    ...<9 lines>...
    )
    ^
  File "C:\Users\atikm\AppData\Local\Programs\Python\Python313\Lib\site-packages\telegram\_bot.py", line 4480, in get_updates
    await self._post(
    ^^^^^^^^^^^^^^^^^
    ...<7 lines>...
    ),
    ^
  File "C:\Users\atikm\AppData\Local\Programs\Python\Python313\Lib\site-packages\telegram\_bot.py", line 619, in _post
    return await self._do_post(
           ^^^^^^^^^^^^^^^^^^^^
    ...<6 lines>...
    )
    ^
  File "C:\Users\atikm\AppData\Local\Programs\Python\Python313\Lib\site-packages\telegram\ext\_extbot.py", line 354, in _do_post
    return await super()._do_post(
           ^^^^^^^^^^^^^^^^^^^^^^^
    ...<6 lines>...
    )
    ^
  File "C:\Users\atikm\AppData\Local\Programs\Python\Python313\Lib\site-packages\telegram\_bot.py", line 648, in _do_post
    result = await request.post(
             ^^^^^^^^^^^^^^^^^^^
    ...<6 lines>...
    )
    ^
  File "C:\Users\atikm\AppData\Local\Programs\Python\Python313\Lib\site-packages\telegram\request\_baserequest.py", line 202, in post
    result = await self._request_wrapper(
             ^^^^^^^^^^^^^^^^^^^^^^^^^^^^
    ...<7 lines>...
    )
    ^
  File "C:\Users\atikm\AppData\Local\Programs\Python\Python313\Lib\site-packages\telegram\request\_baserequest.py", line 385, in _request_wrapper
    raise Conflict(message)
telegram.error.Conflict: Conflict: terminated by other getUpdates request; make sure that only one bot instance is running
2025-01-28 02:28:52,252 - httpx - INFO - HTTP Request: POST https://api.telegram.org/bot8077274379:AAFawJIixuMK47T9RpxiMv0TC_FnYLA6LWI/getUpdates "HTTP/1.1 200 OK"
2025-01-28 02:29:02,479 - httpx - INFO - HTTP Request: POST https://api.telegram.org/bot8077274379:AAFawJIixuMK47T9RpxiMv0TC_FnYLA6LWI/getUpdates "HTTP/1.1 200 OK"
2025-01-28 02:29:12,715 - httpx - INFO - HTTP Request: POST https://api.telegram.org/bot8077274379:AAFawJIixuMK47T9RpxiMv0TC_FnYLA6LWI/getUpdates "HTTP/1.1 200 OK"
2025-01-28 02:29:15,641 - httpx - INFO - HTTP Request: POST https://api.telegram.org/bot8077274379:AAFawJIixuMK47T9RpxiMv0TC_FnYLA6LWI/getUpdates "HTTP/1.1 409 Conflict"
2025-01-28 02:29:15,643 - telegram.ext.Application - ERROR - No error handlers are registered, logging exception.
Traceback (most recent call last):
  File "C:\Users\atikm\AppData\Local\Programs\Python\Python313\Lib\site-packages\telegram\ext\_updater.py", line 750, in _network_loop_retry
    if not await do_action():
           ^^^^^^^^^^^^^^^^^
  File "C:\Users\atikm\AppData\Local\Programs\Python\Python313\Lib\site-packages\telegram\ext\_updater.py", line 744, in do_action
    return action_cb_task.result()
           ~~~~~~~~~~~~~~~~~~~~~^^
  File "C:\Users\atikm\AppData\Local\Programs\Python\Python313\Lib\asyncio\futures.py", line 199, in result
    raise self._exception.with_traceback(self._exception_tb)
  File "C:\Users\atikm\AppData\Local\Programs\Python\Python313\Lib\asyncio\tasks.py", line 304, in __step_run_and_handle_result
    result = coro.send(None)
  File "C:\Users\atikm\AppData\Local\Programs\Python\Python313\Lib\site-packages\telegram\ext\_updater.py", line 371, in polling_action_cb
    updates = await self.bot.get_updates(
              ^^^^^^^^^^^^^^^^^^^^^^^^^^^
    ...<7 lines>...
    )
    ^
  File "C:\Users\atikm\AppData\Local\Programs\Python\Python313\Lib\site-packages\telegram\ext\_extbot.py", line 650, in get_updates
    updates = await super().get_updates(
              ^^^^^^^^^^^^^^^^^^^^^^^^^^
    ...<9 lines>...
    )
    ^
  File "C:\Users\atikm\AppData\Local\Programs\Python\Python313\Lib\site-packages\telegram\_bot.py", line 4480, in get_updates
    await self._post(
    ^^^^^^^^^^^^^^^^^
    ...<7 lines>...
    ),
    ^
  File "C:\Users\atikm\AppData\Local\Programs\Python\Python313\Lib\site-packages\telegram\_bot.py", line 619, in _post
    return await self._do_post(
           ^^^^^^^^^^^^^^^^^^^^
    ...<6 lines>...
    )
    ^
  File "C:\Users\atikm\AppData\Local\Programs\Python\Python313\Lib\site-packages\telegram\ext\_extbot.py", line 354, in _do_post
    return await super()._do_post(
           ^^^^^^^^^^^^^^^^^^^^^^^
    ...<6 lines>...
    )
    ^
  File "C:\Users\atikm\AppData\Local\Programs\Python\Python313\Lib\site-packages\telegram\_bot.py", line 648, in _do_post
    result = await request.post(
             ^^^^^^^^^^^^^^^^^^^
    ...<6 lines>...
    )
    ^
  File "C:\Users\atikm\AppData\Local\Programs\Python\Python313\Lib\site-packages\telegram\request\_baserequest.py", line 202, in post
    result = await self._request_wrapper(
             ^^^^^^^^^^^^^^^^^^^^^^^^^^^^
    ...<7 lines>...
    )
    ^
  File "C:\Users\atikm\AppData\Local\Programs\Python\Python313\Lib\site-packages\telegram\request\_baserequest.py", line 385, in _request_wrapper
    raise Conflict(message)
telegram.error.Conflict: Conflict: terminated by other getUpdates request; make sure that only one bot instance is running
2025-01-28 02:29:26,858 - httpx - INFO - HTTP Request: POST https://api.telegram.org/bot8077274379:AAFawJIixuMK47T9RpxiMv0TC_FnYLA6LWI/getUpdates "HTTP/1.1 200 OK"
2025-01-28 02:29:37,092 - httpx - INFO - HTTP Request: POST https://api.telegram.org/bot8077274379:AAFawJIixuMK47T9RpxiMv0TC_FnYLA6LWI/getUpdates "HTTP/1.1 200 OK"
2025-01-28 02:29:47,328 - httpx - INFO - HTTP Request: POST https://api.telegram.org/bot8077274379:AAFawJIixuMK47T9RpxiMv0TC_FnYLA6LWI/getUpdates "HTTP/1.1 200 OK"
2025-01-28 02:29:50,296 - httpx - INFO - HTTP Request: POST https://api.telegram.org/bot8077274379:AAFawJIixuMK47T9RpxiMv0TC_FnYLA6LWI/getUpdates "HTTP/1.1 409 Conflict"
2025-01-28 02:29:50,299 - telegram.ext.Application - ERROR - No error handlers are registered, logging exception.
Traceback (most recent call last):
  File "C:\Users\atikm\AppData\Local\Programs\Python\Python313\Lib\site-packages\telegram\ext\_updater.py", line 750, in _network_loop_retry
    if not await do_action():
           ^^^^^^^^^^^^^^^^^
  File "C:\Users\atikm\AppData\Local\Programs\Python\Python313\Lib\site-packages\telegram\ext\_updater.py", line 744, in do_action
    return action_cb_task.result()
           ~~~~~~~~~~~~~~~~~~~~~^^
  File "C:\Users\atikm\AppData\Local\Programs\Python\Python313\Lib\asyncio\futures.py", line 199, in result
    raise self._exception.with_traceback(self._exception_tb)
  File "C:\Users\atikm\AppData\Local\Programs\Python\Python313\Lib\asyncio\tasks.py", line 304, in __step_run_and_handle_result
    result = coro.send(None)
  File "C:\Users\atikm\AppData\Local\Programs\Python\Python313\Lib\site-packages\telegram\ext\_updater.py", line 371, in polling_action_cb
    updates = await self.bot.get_updates(
              ^^^^^^^^^^^^^^^^^^^^^^^^^^^
    ...<7 lines>...
    )
    ^
  File "C:\Users\atikm\AppData\Local\Programs\Python\Python313\Lib\site-packages\telegram\ext\_extbot.py", line 650, in get_updates
    updates = await super().get_updates(
              ^^^^^^^^^^^^^^^^^^^^^^^^^^
    ...<9 lines>...
    )
    ^
  File "C:\Users\atikm\AppData\Local\Programs\Python\Python313\Lib\site-packages\telegram\_bot.py", line 4480, in get_updates
    await self._post(
    ^^^^^^^^^^^^^^^^^
    ...<7 lines>...
    ),
    ^
  File "C:\Users\atikm\AppData\Local\Programs\Python\Python313\Lib\site-packages\telegram\_bot.py", line 619, in _post
    return await self._do_post(
           ^^^^^^^^^^^^^^^^^^^^
    ...<6 lines>...
    )
    ^
  File "C:\Users\atikm\AppData\Local\Programs\Python\Python313\Lib\site-packages\telegram\ext\_extbot.py", line 354, in _do_post
    return await super()._do_post(
           ^^^^^^^^^^^^^^^^^^^^^^^
    ...<6 lines>...
    )
    ^
  File "C:\Users\atikm\AppData\Local\Programs\Python\Python313\Lib\site-packages\telegram\_bot.py", line 648, in _do_post
    result = await request.post(
             ^^^^^^^^^^^^^^^^^^^
    ...<6 lines>...
    )
    ^
  File "C:\Users\atikm\AppData\Local\Programs\Python\Python313\Lib\site-packages\telegram\request\_baserequest.py", line 202, in post
    result = await self._request_wrapper(
             ^^^^^^^^^^^^^^^^^^^^^^^^^^^^
    ...<7 lines>...
    )
    ^
  File "C:\Users\atikm\AppData\Local\Programs\Python\Python313\Lib\site-packages\telegram\request\_baserequest.py", line 385, in _request_wrapper
    raise Conflict(message)
telegram.error.Conflict: Conflict: terminated by other getUpdates request; make sure that only one bot instance is running
2025-01-28 02:30:01,572 - httpx - INFO - HTTP Request: POST https://api.telegram.org/bot8077274379:AAFawJIixuMK47T9RpxiMv0TC_FnYLA6LWI/getUpdates "HTTP/1.1 200 OK"
2025-01-28 02:30:11,815 - httpx - INFO - HTTP Request: POST https://api.telegram.org/bot8077274379:AAFawJIixuMK47T9RpxiMv0TC_FnYLA6LWI/getUpdates "HTTP/1.1 200 OK"
2025-01-28 02:30:21,985 - httpx - INFO - HTTP Request: POST https://api.telegram.org/bot8077274379:AAFawJIixuMK47T9RpxiMv0TC_FnYLA6LWI/getUpdates "HTTP/1.1 200 OK"
2025-01-28 02:30:25,013 - httpx - INFO - HTTP Request: POST https://api.telegram.org/bot8077274379:AAFawJIixuMK47T9RpxiMv0TC_FnYLA6LWI/getUpdates "HTTP/1.1 409 Conflict"
2025-01-28 02:30:25,015 - telegram.ext.Application - ERROR - No error handlers are registered, logging exception.
Traceback (most recent call last):
  File "C:\Users\atikm\AppData\Local\Programs\Python\Python313\Lib\site-packages\telegram\ext\_updater.py", line 750, in _network_loop_retry
    if not await do_action():
           ^^^^^^^^^^^^^^^^^
  File "C:\Users\atikm\AppData\Local\Programs\Python\Python313\Lib\site-packages\telegram\ext\_updater.py", line 744, in do_action
    return action_cb_task.result()
           ~~~~~~~~~~~~~~~~~~~~~^^
  File "C:\Users\atikm\AppData\Local\Programs\Python\Python313\Lib\asyncio\futures.py", line 199, in result
    raise self._exception.with_traceback(self._exception_tb)
  File "C:\Users\atikm\AppData\Local\Programs\Python\Python313\Lib\asyncio\tasks.py", line 304, in __step_run_and_handle_result
    result = coro.send(None)
  File "C:\Users\atikm\AppData\Local\Programs\Python\Python313\Lib\site-packages\telegram\ext\_updater.py", line 371, in polling_action_cb
    updates = await self.bot.get_updates(
              ^^^^^^^^^^^^^^^^^^^^^^^^^^^
    ...<7 lines>...
    )
    ^
  File "C:\Users\atikm\AppData\Local\Programs\Python\Python313\Lib\site-packages\telegram\ext\_extbot.py", line 650, in get_updates
    updates = await super().get_updates(
              ^^^^^^^^^^^^^^^^^^^^^^^^^^
    ...<9 lines>...
    )
    ^
  File "C:\Users\atikm\AppData\Local\Programs\Python\Python313\Lib\site-packages\telegram\_bot.py", line 4480, in get_updates
    await self._post(
    ^^^^^^^^^^^^^^^^^
    ...<7 lines>...
    ),
    ^
  File "C:\Users\atikm\AppData\Local\Programs\Python\Python313\Lib\site-packages\telegram\_bot.py", line 619, in _post
    return await self._do_post(
           ^^^^^^^^^^^^^^^^^^^^
    ...<6 lines>...
    )
    ^
  File "C:\Users\atikm\AppData\Local\Programs\Python\Python313\Lib\site-packages\telegram\ext\_extbot.py", line 354, in _do_post
    return await super()._do_post(
           ^^^^^^^^^^^^^^^^^^^^^^^
    ...<6 lines>...
    )
    ^
  File "C:\Users\atikm\AppData\Local\Programs\Python\Python313\Lib\site-packages\telegram\_bot.py", line 648, in _do_post
    result = await request.post(
             ^^^^^^^^^^^^^^^^^^^
    ...<6 lines>...
    )
    ^
  File "C:\Users\atikm\AppData\Local\Programs\Python\Python313\Lib\site-packages\telegram\request\_baserequest.py", line 202, in post
    result = await self._request_wrapper(
             ^^^^^^^^^^^^^^^^^^^^^^^^^^^^
    ...<7 lines>...
    )
    ^
  File "C:\Users\atikm\AppData\Local\Programs\Python\Python313\Lib\site-packages\telegram\request\_baserequest.py", line 385, in _request_wrapper
    raise Conflict(message)
telegram.error.Conflict: Conflict: terminated by other getUpdates request; make sure that only one bot instance is running
2025-01-28 02:30:36,276 - httpx - INFO - HTTP Request: POST https://api.telegram.org/bot8077274379:AAFawJIixuMK47T9RpxiMv0TC_FnYLA6LWI/getUpdates "HTTP/1.1 200 OK"
2025-01-28 02:30:46,529 - httpx - INFO - HTTP Request: POST https://api.telegram.org/bot8077274379:AAFawJIixuMK47T9RpxiMv0TC_FnYLA6LWI/getUpdates "HTTP/1.1 200 OK"
2025-01-28 02:30:58,689 - __main__ - INFO - 
STARTING THE BOT

2025-01-28 02:32:16,599 - __main__ - INFO - 
STARTING THE BOT

2025-01-28 02:34:17,048 - __main__ - INFO - 
STARTING THE BOT

2025-01-28 02:34:18,692 - httpx - INFO - HTTP Request: POST https://api.telegram.org/bot8077274379:AAFawJIixuMK47T9RpxiMv0TC_FnYLA6LWI/setMyCommands "HTTP/1.1 200 OK"
2025-01-28 02:34:18,695 - __main__ - INFO - 
BOT HAS STARTED

2025-01-28 02:34:18,695 - __main__ - INFO - 
BOT IS RUNNING

2025-01-28 02:34:18,695 - __main__ - INFO - 
WAITING FOR USER INTERACTIONS...

2025-01-28 02:34:19,171 - httpx - INFO - HTTP Request: POST https://api.telegram.org/bot8077274379:AAFawJIixuMK47T9RpxiMv0TC_FnYLA6LWI/getMe "HTTP/1.1 200 OK"
2025-01-28 02:34:19,420 - httpx - INFO - HTTP Request: POST https://api.telegram.org/bot8077274379:AAFawJIixuMK47T9RpxiMv0TC_FnYLA6LWI/deleteWebhook "HTTP/1.1 200 OK"
2025-01-28 02:34:19,433 - telegram.ext.Application - INFO - Application started
2025-01-28 02:34:24,221 - httpx - INFO - HTTP Request: POST https://api.telegram.org/bot8077274379:AAFawJIixuMK47T9RpxiMv0TC_FnYLA6LWI/getUpdates "HTTP/1.1 409 Conflict"
2025-01-28 02:34:24,222 - telegram.ext.Application - ERROR - No error handlers are registered, logging exception.
Traceback (most recent call last):
  File "C:\Users\atikm\AppData\Local\Programs\Python\Python313\Lib\site-packages\telegram\ext\_updater.py", line 750, in _network_loop_retry
    if not await do_action():
           ^^^^^^^^^^^^^^^^^
  File "C:\Users\atikm\AppData\Local\Programs\Python\Python313\Lib\site-packages\telegram\ext\_updater.py", line 744, in do_action
    return action_cb_task.result()
           ~~~~~~~~~~~~~~~~~~~~~^^
  File "C:\Users\atikm\AppData\Local\Programs\Python\Python313\Lib\asyncio\futures.py", line 199, in result
    raise self._exception.with_traceback(self._exception_tb)
  File "C:\Users\atikm\AppData\Local\Programs\Python\Python313\Lib\asyncio\tasks.py", line 304, in __step_run_and_handle_result
    result = coro.send(None)
  File "C:\Users\atikm\AppData\Local\Programs\Python\Python313\Lib\site-packages\telegram\ext\_updater.py", line 371, in polling_action_cb
    updates = await self.bot.get_updates(
              ^^^^^^^^^^^^^^^^^^^^^^^^^^^
    ...<7 lines>...
    )
    ^
  File "C:\Users\atikm\AppData\Local\Programs\Python\Python313\Lib\site-packages\telegram\ext\_extbot.py", line 650, in get_updates
    updates = await super().get_updates(
              ^^^^^^^^^^^^^^^^^^^^^^^^^^
    ...<9 lines>...
    )
    ^
  File "C:\Users\atikm\AppData\Local\Programs\Python\Python313\Lib\site-packages\telegram\_bot.py", line 4480, in get_updates
    await self._post(
    ^^^^^^^^^^^^^^^^^
    ...<7 lines>...
    ),
    ^
  File "C:\Users\atikm\AppData\Local\Programs\Python\Python313\Lib\site-packages\telegram\_bot.py", line 619, in _post
    return await self._do_post(
           ^^^^^^^^^^^^^^^^^^^^
    ...<6 lines>...
    )
    ^
  File "C:\Users\atikm\AppData\Local\Programs\Python\Python313\Lib\site-packages\telegram\ext\_extbot.py", line 354, in _do_post
    return await super()._do_post(
           ^^^^^^^^^^^^^^^^^^^^^^^
    ...<6 lines>...
    )
    ^
  File "C:\Users\atikm\AppData\Local\Programs\Python\Python313\Lib\site-packages\telegram\_bot.py", line 648, in _do_post
    result = await request.post(
             ^^^^^^^^^^^^^^^^^^^
    ...<6 lines>...
    )
    ^
  File "C:\Users\atikm\AppData\Local\Programs\Python\Python313\Lib\site-packages\telegram\request\_baserequest.py", line 202, in post
    result = await self._request_wrapper(
             ^^^^^^^^^^^^^^^^^^^^^^^^^^^^
    ...<7 lines>...
    )
    ^
  File "C:\Users\atikm\AppData\Local\Programs\Python\Python313\Lib\site-packages\telegram\request\_baserequest.py", line 385, in _request_wrapper
    raise Conflict(message)
telegram.error.Conflict: Conflict: terminated by other getUpdates request; make sure that only one bot instance is running
2025-01-28 02:34:25,514 - httpx - INFO - HTTP Request: POST https://api.telegram.org/bot8077274379:AAFawJIixuMK47T9RpxiMv0TC_FnYLA6LWI/getUpdates "HTTP/1.1 200 OK"
2025-01-28 02:34:25,516 - __main__ - INFO - INFO - User ERROR (ID: 2142334821) started the bot.
2025-01-28 02:34:26,366 - httpx - INFO - HTTP Request: POST https://api.telegram.org/bot8077274379:AAFawJIixuMK47T9RpxiMv0TC_FnYLA6LWI/sendMessage "HTTP/1.1 200 OK"
2025-01-28 02:34:33,643 - httpx - INFO - HTTP Request: POST https://api.telegram.org/bot8077274379:AAFawJIixuMK47T9RpxiMv0TC_FnYLA6LWI/getUpdates "HTTP/1.1 200 OK"
2025-01-28 02:34:33,647 - __main__ - INFO - INFO - User ERROR (ID: 2142334821) started the bot.
2025-01-28 02:34:34,457 - httpx - INFO - HTTP Request: POST https://api.telegram.org/bot8077274379:AAFawJIixuMK47T9RpxiMv0TC_FnYLA6LWI/sendMessage "HTTP/1.1 200 OK"
2025-01-28 02:34:39,068 - httpx - INFO - HTTP Request: POST https://api.telegram.org/bot8077274379:AAFawJIixuMK47T9RpxiMv0TC_FnYLA6LWI/getUpdates "HTTP/1.1 200 OK"
2025-01-28 02:34:39,071 - __main__ - INFO - INFO - User ERROR (ID: 2142334821) started the bot.
2025-01-28 02:34:39,477 - httpx - INFO - HTTP Request: POST https://api.telegram.org/bot8077274379:AAFawJIixuMK47T9RpxiMv0TC_FnYLA6LWI/sendMessage "HTTP/1.1 200 OK"
2025-01-28 02:34:43,102 - httpx - INFO - HTTP Request: POST https://api.telegram.org/bot8077274379:AAFawJIixuMK47T9RpxiMv0TC_FnYLA6LWI/getUpdates "HTTP/1.1 200 OK"
2025-01-28 02:34:43,492 - httpx - INFO - HTTP Request: POST https://api.telegram.org/bot8077274379:AAFawJIixuMK47T9RpxiMv0TC_FnYLA6LWI/answerCallbackQuery "HTTP/1.1 200 OK"
2025-01-28 02:34:43,882 - httpx - INFO - HTTP Request: POST https://api.telegram.org/bot8077274379:AAFawJIixuMK47T9RpxiMv0TC_FnYLA6LWI/editMessageText "HTTP/1.1 200 OK"
2025-01-28 02:34:47,477 - httpx - INFO - HTTP Request: POST https://api.telegram.org/bot8077274379:AAFawJIixuMK47T9RpxiMv0TC_FnYLA6LWI/getUpdates "HTTP/1.1 200 OK"
2025-01-28 02:34:47,856 - httpx - INFO - HTTP Request: POST https://api.telegram.org/bot8077274379:AAFawJIixuMK47T9RpxiMv0TC_FnYLA6LWI/sendMessage "HTTP/1.1 200 OK"
2025-01-28 02:35:01,209 - httpx - INFO - HTTP Request: POST https://api.telegram.org/bot8077274379:AAFawJIixuMK47T9RpxiMv0TC_FnYLA6LWI/getUpdates "HTTP/1.1 200 OK"
2025-01-28 02:35:11,341 - httpx - INFO - HTTP Request: POST https://api.telegram.org/bot8077274379:AAFawJIixuMK47T9RpxiMv0TC_FnYLA6LWI/getUpdates "HTTP/1.1 200 OK"
2025-01-28 02:35:21,481 - httpx - INFO - HTTP Request: POST https://api.telegram.org/bot8077274379:AAFawJIixuMK47T9RpxiMv0TC_FnYLA6LWI/getUpdates "HTTP/1.1 200 OK"
2025-01-28 02:35:21,738 - __main__ - ERROR - Error downloading video: Timed out
2025-01-28 02:35:22,368 - httpx - INFO - HTTP Request: POST https://api.telegram.org/bot8077274379:AAFawJIixuMK47T9RpxiMv0TC_FnYLA6LWI/sendMessage "HTTP/1.1 200 OK"
2025-01-28 02:35:22,726 - httpx - INFO - HTTP Request: POST https://api.telegram.org/bot8077274379:AAFawJIixuMK47T9RpxiMv0TC_FnYLA6LWI/sendMessage "HTTP/1.1 200 OK"
2025-01-28 02:35:31,702 - httpx - INFO - HTTP Request: POST https://api.telegram.org/bot8077274379:AAFawJIixuMK47T9RpxiMv0TC_FnYLA6LWI/getUpdates "HTTP/1.1 200 OK"
2025-01-28 02:35:41,944 - httpx - INFO - HTTP Request: POST https://api.telegram.org/bot8077274379:AAFawJIixuMK47T9RpxiMv0TC_FnYLA6LWI/getUpdates "HTTP/1.1 200 OK"
2025-01-28 02:35:52,173 - httpx - INFO - HTTP Request: POST https://api.telegram.org/bot8077274379:AAFawJIixuMK47T9RpxiMv0TC_FnYLA6LWI/getUpdates "HTTP/1.1 200 OK"
2025-01-28 02:36:02,427 - httpx - INFO - HTTP Request: POST https://api.telegram.org/bot8077274379:AAFawJIixuMK47T9RpxiMv0TC_FnYLA6LWI/getUpdates "HTTP/1.1 200 OK"
2025-01-28 02:36:12,567 - httpx - INFO - HTTP Request: POST https://api.telegram.org/bot8077274379:AAFawJIixuMK47T9RpxiMv0TC_FnYLA6LWI/getUpdates "HTTP/1.1 200 OK"
2025-01-28 02:36:22,800 - httpx - INFO - HTTP Request: POST https://api.telegram.org/bot8077274379:AAFawJIixuMK47T9RpxiMv0TC_FnYLA6LWI/getUpdates "HTTP/1.1 200 OK"
2025-01-28 02:36:32,976 - httpx - INFO - HTTP Request: POST https://api.telegram.org/bot8077274379:AAFawJIixuMK47T9RpxiMv0TC_FnYLA6LWI/getUpdates "HTTP/1.1 200 OK"
2025-01-28 02:36:43,275 - httpx - INFO - HTTP Request: POST https://api.telegram.org/bot8077274379:AAFawJIixuMK47T9RpxiMv0TC_FnYLA6LWI/getUpdates "HTTP/1.1 200 OK"
2025-01-28 02:36:53,424 - httpx - INFO - HTTP Request: POST https://api.telegram.org/bot8077274379:AAFawJIixuMK47T9RpxiMv0TC_FnYLA6LWI/getUpdates "HTTP/1.1 200 OK"
2025-01-28 02:37:03,556 - httpx - INFO - HTTP Request: POST https://api.telegram.org/bot8077274379:AAFawJIixuMK47T9RpxiMv0TC_FnYLA6LWI/getUpdates "HTTP/1.1 200 OK"
2025-01-28 02:37:13,746 - httpx - INFO - HTTP Request: POST https://api.telegram.org/bot8077274379:AAFawJIixuMK47T9RpxiMv0TC_FnYLA6LWI/getUpdates "HTTP/1.1 200 OK"
2025-01-28 02:37:23,939 - httpx - INFO - HTTP Request: POST https://api.telegram.org/bot8077274379:AAFawJIixuMK47T9RpxiMv0TC_FnYLA6LWI/getUpdates "HTTP/1.1 200 OK"
2025-01-28 02:37:34,177 - httpx - INFO - HTTP Request: POST https://api.telegram.org/bot8077274379:AAFawJIixuMK47T9RpxiMv0TC_FnYLA6LWI/getUpdates "HTTP/1.1 200 OK"
2025-01-28 02:37:44,417 - httpx - INFO - HTTP Request: POST https://api.telegram.org/bot8077274379:AAFawJIixuMK47T9RpxiMv0TC_FnYLA6LWI/getUpdates "HTTP/1.1 200 OK"
2025-01-28 02:37:54,656 - httpx - INFO - HTTP Request: POST https://api.telegram.org/bot8077274379:AAFawJIixuMK47T9RpxiMv0TC_FnYLA6LWI/getUpdates "HTTP/1.1 200 OK"
2025-01-28 02:38:04,909 - httpx - INFO - HTTP Request: POST https://api.telegram.org/bot8077274379:AAFawJIixuMK47T9RpxiMv0TC_FnYLA6LWI/getUpdates "HTTP/1.1 200 OK"
2025-01-28 02:38:15,053 - httpx - INFO - HTTP Request: POST https://api.telegram.org/bot8077274379:AAFawJIixuMK47T9RpxiMv0TC_FnYLA6LWI/getUpdates "HTTP/1.1 200 OK"
2025-01-28 02:38:25,268 - httpx - INFO - HTTP Request: POST https://api.telegram.org/bot8077274379:AAFawJIixuMK47T9RpxiMv0TC_FnYLA6LWI/getUpdates "HTTP/1.1 200 OK"
2025-01-28 02:38:35,530 - httpx - INFO - HTTP Request: POST https://api.telegram.org/bot8077274379:AAFawJIixuMK47T9RpxiMv0TC_FnYLA6LWI/getUpdates "HTTP/1.1 200 OK"
2025-01-28 02:38:45,754 - httpx - INFO - HTTP Request: POST https://api.telegram.org/bot8077274379:AAFawJIixuMK47T9RpxiMv0TC_FnYLA6LWI/getUpdates "HTTP/1.1 200 OK"
2025-01-28 02:38:55,890 - httpx - INFO - HTTP Request: POST https://api.telegram.org/bot8077274379:AAFawJIixuMK47T9RpxiMv0TC_FnYLA6LWI/getUpdates "HTTP/1.1 200 OK"
2025-01-28 02:39:06,028 - httpx - INFO - HTTP Request: POST https://api.telegram.org/bot8077274379:AAFawJIixuMK47T9RpxiMv0TC_FnYLA6LWI/getUpdates "HTTP/1.1 200 OK"
2025-01-28 02:39:16,272 - httpx - INFO - HTTP Request: POST https://api.telegram.org/bot8077274379:AAFawJIixuMK47T9RpxiMv0TC_FnYLA6LWI/getUpdates "HTTP/1.1 200 OK"
2025-01-28 02:39:26,415 - httpx - INFO - HTTP Request: POST https://api.telegram.org/bot8077274379:AAFawJIixuMK47T9RpxiMv0TC_FnYLA6LWI/getUpdates "HTTP/1.1 200 OK"
2025-01-28 02:39:36,648 - httpx - INFO - HTTP Request: POST https://api.telegram.org/bot8077274379:AAFawJIixuMK47T9RpxiMv0TC_FnYLA6LWI/getUpdates "HTTP/1.1 200 OK"
2025-01-28 02:42:27,424 - __main__ - INFO - 
STARTING THE BOT

2025-01-28 02:42:28,883 - httpx - INFO - HTTP Request: POST https://api.telegram.org/bot8077274379:AAFawJIixuMK47T9RpxiMv0TC_FnYLA6LWI/setMyCommands "HTTP/1.1 200 OK"
2025-01-28 02:42:28,885 - __main__ - INFO - 
BOT HAS STARTED

2025-01-28 02:42:28,886 - __main__ - INFO - 
BOT IS RUNNING

2025-01-28 02:42:28,887 - __main__ - INFO - 
WAITING FOR USER INTERACTIONS...

2025-01-28 02:42:29,396 - httpx - INFO - HTTP Request: POST https://api.telegram.org/bot8077274379:AAFawJIixuMK47T9RpxiMv0TC_FnYLA6LWI/getMe "HTTP/1.1 200 OK"
2025-01-28 02:42:29,583 - httpx - INFO - HTTP Request: POST https://api.telegram.org/bot8077274379:AAFawJIixuMK47T9RpxiMv0TC_FnYLA6LWI/deleteWebhook "HTTP/1.1 200 OK"
2025-01-28 02:42:29,585 - telegram.ext.Application - INFO - Application started
2025-01-28 02:42:40,156 - httpx - INFO - HTTP Request: POST https://api.telegram.org/bot8077274379:AAFawJIixuMK47T9RpxiMv0TC_FnYLA6LWI/getUpdates "HTTP/1.1 200 OK"
2025-01-28 02:42:45,780 - httpx - INFO - HTTP Request: POST https://api.telegram.org/bot8077274379:AAFawJIixuMK47T9RpxiMv0TC_FnYLA6LWI/getUpdates "HTTP/1.1 200 OK"
2025-01-28 02:42:45,782 - __main__ - INFO - INFO - User ERROR (ID: 2142334821) started the bot.
2025-01-28 02:42:46,616 - httpx - INFO - HTTP Request: POST https://api.telegram.org/bot8077274379:AAFawJIixuMK47T9RpxiMv0TC_FnYLA6LWI/sendMessage "HTTP/1.1 200 OK"
2025-01-28 02:42:53,461 - httpx - INFO - HTTP Request: POST https://api.telegram.org/bot8077274379:AAFawJIixuMK47T9RpxiMv0TC_FnYLA6LWI/getUpdates "HTTP/1.1 200 OK"
2025-01-28 02:42:54,377 - httpx - INFO - HTTP Request: POST https://api.telegram.org/bot8077274379:AAFawJIixuMK47T9RpxiMv0TC_FnYLA6LWI/sendMessage "HTTP/1.1 200 OK"
2025-01-28 02:42:58,486 - httpx - INFO - HTTP Request: POST https://api.telegram.org/bot8077274379:AAFawJIixuMK47T9RpxiMv0TC_FnYLA6LWI/getUpdates "HTTP/1.1 200 OK"
2025-01-28 02:42:58,894 - httpx - INFO - HTTP Request: POST https://api.telegram.org/bot8077274379:AAFawJIixuMK47T9RpxiMv0TC_FnYLA6LWI/sendMessage "HTTP/1.1 200 OK"
2025-01-28 02:43:03,615 - __main__ - INFO - File size: 79.69 MB
2025-01-28 02:43:03,954 - httpx - INFO - HTTP Request: POST https://api.telegram.org/bot8077274379:AAFawJIixuMK47T9RpxiMv0TC_FnYLA6LWI/sendMessage "HTTP/1.1 200 OK"
2025-01-28 02:43:04,270 - httpx - INFO - HTTP Request: POST https://api.telegram.org/bot8077274379:AAFawJIixuMK47T9RpxiMv0TC_FnYLA6LWI/sendMessage "HTTP/1.1 200 OK"
2025-01-28 02:43:08,720 - httpx - INFO - HTTP Request: POST https://api.telegram.org/bot8077274379:AAFawJIixuMK47T9RpxiMv0TC_FnYLA6LWI/getUpdates "HTTP/1.1 200 OK"
2025-01-28 02:43:18,956 - httpx - INFO - HTTP Request: POST https://api.telegram.org/bot8077274379:AAFawJIixuMK47T9RpxiMv0TC_FnYLA6LWI/getUpdates "HTTP/1.1 200 OK"
2025-01-28 02:43:19,586 - httpx - INFO - HTTP Request: POST https://api.telegram.org/bot8077274379:AAFawJIixuMK47T9RpxiMv0TC_FnYLA6LWI/getUpdates "HTTP/1.1 200 OK"
2025-01-28 02:43:20,392 - httpx - INFO - HTTP Request: POST https://api.telegram.org/bot8077274379:AAFawJIixuMK47T9RpxiMv0TC_FnYLA6LWI/sendMessage "HTTP/1.1 200 OK"
2025-01-28 02:43:29,817 - httpx - INFO - HTTP Request: POST https://api.telegram.org/bot8077274379:AAFawJIixuMK47T9RpxiMv0TC_FnYLA6LWI/getUpdates "HTTP/1.1 200 OK"
2025-01-28 02:43:39,974 - httpx - INFO - HTTP Request: POST https://api.telegram.org/bot8077274379:AAFawJIixuMK47T9RpxiMv0TC_FnYLA6LWI/getUpdates "HTTP/1.1 200 OK"
2025-01-28 02:43:46,705 - httpx - INFO - HTTP Request: POST https://api.telegram.org/bot8077274379:AAFawJIixuMK47T9RpxiMv0TC_FnYLA6LWI/getUpdates "HTTP/1.1 200 OK"
2025-01-28 02:43:46,708 - __main__ - INFO - INFO - User ERROR invoked the /help command.
2025-01-28 02:43:47,594 - httpx - INFO - HTTP Request: POST https://api.telegram.org/bot8077274379:AAFawJIixuMK47T9RpxiMv0TC_FnYLA6LWI/sendMessage "HTTP/1.1 200 OK"
2025-01-28 02:43:56,947 - httpx - INFO - HTTP Request: POST https://api.telegram.org/bot8077274379:AAFawJIixuMK47T9RpxiMv0TC_FnYLA6LWI/getUpdates "HTTP/1.1 200 OK"
2025-01-28 02:44:07,182 - httpx - INFO - HTTP Request: POST https://api.telegram.org/bot8077274379:AAFawJIixuMK47T9RpxiMv0TC_FnYLA6LWI/getUpdates "HTTP/1.1 200 OK"
2025-01-28 02:44:17,432 - httpx - INFO - HTTP Request: POST https://api.telegram.org/bot8077274379:AAFawJIixuMK47T9RpxiMv0TC_FnYLA6LWI/getUpdates "HTTP/1.1 200 OK"
2025-01-28 02:44:27,624 - httpx - INFO - HTTP Request: POST https://api.telegram.org/bot8077274379:AAFawJIixuMK47T9RpxiMv0TC_FnYLA6LWI/getUpdates "HTTP/1.1 200 OK"
2025-01-28 02:44:37,810 - httpx - INFO - HTTP Request: POST https://api.telegram.org/bot8077274379:AAFawJIixuMK47T9RpxiMv0TC_FnYLA6LWI/getUpdates "HTTP/1.1 200 OK"
2025-01-28 02:44:48,050 - httpx - INFO - HTTP Request: POST https://api.telegram.org/bot8077274379:AAFawJIixuMK47T9RpxiMv0TC_FnYLA6LWI/getUpdates "HTTP/1.1 200 OK"
2025-01-28 02:44:55,064 - httpx - INFO - HTTP Request: POST https://api.telegram.org/bot8077274379:AAFawJIixuMK47T9RpxiMv0TC_FnYLA6LWI/getUpdates "HTTP/1.1 200 OK"
2025-01-28 02:44:55,932 - httpx - INFO - HTTP Request: POST https://api.telegram.org/bot8077274379:AAFawJIixuMK47T9RpxiMv0TC_FnYLA6LWI/sendMessage "HTTP/1.1 200 OK"
2025-01-28 02:45:05,048 - httpx - INFO - HTTP Request: POST https://api.telegram.org/bot8077274379:AAFawJIixuMK47T9RpxiMv0TC_FnYLA6LWI/getUpdates "HTTP/1.1 200 OK"
2025-01-28 02:45:05,862 - httpx - INFO - HTTP Request: POST https://api.telegram.org/bot8077274379:AAFawJIixuMK47T9RpxiMv0TC_FnYLA6LWI/getUpdates "HTTP/1.1 200 OK"
2025-01-28 02:45:10,257 - telegram.ext.Application - ERROR - No error handlers are registered, logging exception.
Traceback (most recent call last):
  File "C:\Users\atikm\AppData\Local\Programs\Python\Python313\Lib\site-packages\httpx\_transports\default.py", line 101, in map_httpcore_exceptions
    yield
  File "C:\Users\atikm\AppData\Local\Programs\Python\Python313\Lib\site-packages\httpx\_transports\default.py", line 394, in handle_async_request
    resp = await self._pool.handle_async_request(req)
           ^^^^^^^^^^^^^^^^^^^^^^^^^^^^^^^^^^^^^^^^^^
  File "C:\Users\atikm\AppData\Local\Programs\Python\Python313\Lib\site-packages\httpcore\_async\connection_pool.py", line 256, in handle_async_request
    raise exc from None
  File "C:\Users\atikm\AppData\Local\Programs\Python\Python313\Lib\site-packages\httpcore\_async\connection_pool.py", line 236, in handle_async_request
    response = await connection.handle_async_request(
               ^^^^^^^^^^^^^^^^^^^^^^^^^^^^^^^^^^^^^^
        pool_request.request
        ^^^^^^^^^^^^^^^^^^^^
    )
    ^
  File "C:\Users\atikm\AppData\Local\Programs\Python\Python313\Lib\site-packages\httpcore\_async\connection.py", line 101, in handle_async_request
    raise exc
  File "C:\Users\atikm\AppData\Local\Programs\Python\Python313\Lib\site-packages\httpcore\_async\connection.py", line 78, in handle_async_request
    stream = await self._connect(request)
             ^^^^^^^^^^^^^^^^^^^^^^^^^^^^
  File "C:\Users\atikm\AppData\Local\Programs\Python\Python313\Lib\site-packages\httpcore\_async\connection.py", line 156, in _connect
    stream = await stream.start_tls(**kwargs)
             ^^^^^^^^^^^^^^^^^^^^^^^^^^^^^^^^
  File "C:\Users\atikm\AppData\Local\Programs\Python\Python313\Lib\site-packages\httpcore\_backends\anyio.py", line 67, in start_tls
    with map_exceptions(exc_map):
         ~~~~~~~~~~~~~~^^^^^^^^^
  File "C:\Users\atikm\AppData\Local\Programs\Python\Python313\Lib\contextlib.py", line 162, in __exit__
    self.gen.throw(value)
    ~~~~~~~~~~~~~~^^^^^^^
  File "C:\Users\atikm\AppData\Local\Programs\Python\Python313\Lib\site-packages\httpcore\_exceptions.py", line 14, in map_exceptions
    raise to_exc(exc) from exc
httpcore.ConnectTimeout

The above exception was the direct cause of the following exception:

Traceback (most recent call last):
  File "C:\Users\atikm\AppData\Local\Programs\Python\Python313\Lib\site-packages\telegram\request\_httpxrequest.py", line 293, in do_request
    res = await self._client.request(
          ^^^^^^^^^^^^^^^^^^^^^^^^^^^
    ...<6 lines>...
    )
    ^
  File "C:\Users\atikm\AppData\Local\Programs\Python\Python313\Lib\site-packages\httpx\_client.py", line 1540, in request
    return await self.send(request, auth=auth, follow_redirects=follow_redirects)
           ^^^^^^^^^^^^^^^^^^^^^^^^^^^^^^^^^^^^^^^^^^^^^^^^^^^^^^^^^^^^^^^^^^^^^^
  File "C:\Users\atikm\AppData\Local\Programs\Python\Python313\Lib\site-packages\httpx\_client.py", line 1629, in send
    response = await self._send_handling_auth(
               ^^^^^^^^^^^^^^^^^^^^^^^^^^^^^^^
    ...<4 lines>...
    )
    ^
  File "C:\Users\atikm\AppData\Local\Programs\Python\Python313\Lib\site-packages\httpx\_client.py", line 1657, in _send_handling_auth
    response = await self._send_handling_redirects(
               ^^^^^^^^^^^^^^^^^^^^^^^^^^^^^^^^^^^^
    ...<3 lines>...
    )
    ^
  File "C:\Users\atikm\AppData\Local\Programs\Python\Python313\Lib\site-packages\httpx\_client.py", line 1694, in _send_handling_redirects
    response = await self._send_single_request(request)
               ^^^^^^^^^^^^^^^^^^^^^^^^^^^^^^^^^^^^^^^^
  File "C:\Users\atikm\AppData\Local\Programs\Python\Python313\Lib\site-packages\httpx\_client.py", line 1730, in _send_single_request
    response = await transport.handle_async_request(request)
               ^^^^^^^^^^^^^^^^^^^^^^^^^^^^^^^^^^^^^^^^^^^^^
  File "C:\Users\atikm\AppData\Local\Programs\Python\Python313\Lib\site-packages\httpx\_transports\default.py", line 393, in handle_async_request
    with map_httpcore_exceptions():
         ~~~~~~~~~~~~~~~~~~~~~~~^^
  File "C:\Users\atikm\AppData\Local\Programs\Python\Python313\Lib\contextlib.py", line 162, in __exit__
    self.gen.throw(value)
    ~~~~~~~~~~~~~~^^^^^^^
  File "C:\Users\atikm\AppData\Local\Programs\Python\Python313\Lib\site-packages\httpx\_transports\default.py", line 118, in map_httpcore_exceptions
    raise mapped_exc(message) from exc
httpx.ConnectTimeout

The above exception was the direct cause of the following exception:

Traceback (most recent call last):
  File "C:\Users\atikm\AppData\Local\Programs\Python\Python313\Lib\site-packages\telegram\ext\_application.py", line 1325, in process_update
    await coroutine
  File "C:\Users\atikm\AppData\Local\Programs\Python\Python313\Lib\site-packages\telegram\ext\_handlers\basehandler.py", line 158, in handle_update
    return await self.callback(update, context)
           ^^^^^^^^^^^^^^^^^^^^^^^^^^^^^^^^^^^^
  File "c:\Users\atikm\Desktop\PROJECT\YTDOWNLOADER\main.py", line 77, in history
    await update.message.reply_text("You don't have any download history yet.")
  File "C:\Users\atikm\AppData\Local\Programs\Python\Python313\Lib\site-packages\telegram\_message.py", line 1771, in reply_text
    return await self.get_bot().send_message(
           ^^^^^^^^^^^^^^^^^^^^^^^^^^^^^^^^^^
    ...<20 lines>...
    )
    ^
  File "C:\Users\atikm\AppData\Local\Programs\Python\Python313\Lib\site-packages\telegram\ext\_extbot.py", line 2965, in send_message
    return await super().send_message(
           ^^^^^^^^^^^^^^^^^^^^^^^^^^^
    ...<21 lines>...
    )
    ^
  File "C:\Users\atikm\AppData\Local\Programs\Python\Python313\Lib\site-packages\telegram\_bot.py", line 1019, in send_message
    return await self._send_message(
           ^^^^^^^^^^^^^^^^^^^^^^^^^
    ...<19 lines>...
    )
    ^
  File "C:\Users\atikm\AppData\Local\Programs\Python\Python313\Lib\site-packages\telegram\ext\_extbot.py", line 610, in _send_message
    result = await super()._send_message(
             ^^^^^^^^^^^^^^^^^^^^^^^^^^^^
    ...<21 lines>...
    )
    ^
  File "C:\Users\atikm\AppData\Local\Programs\Python\Python313\Lib\site-packages\telegram\_bot.py", line 731, in _send_message
    result = await self._post(
             ^^^^^^^^^^^^^^^^^
    ...<7 lines>...
    )
    ^
  File "C:\Users\atikm\AppData\Local\Programs\Python\Python313\Lib\site-packages\telegram\_bot.py", line 619, in _post
    return await self._do_post(
           ^^^^^^^^^^^^^^^^^^^^
    ...<6 lines>...
    )
    ^
  File "C:\Users\atikm\AppData\Local\Programs\Python\Python313\Lib\site-packages\telegram\ext\_extbot.py", line 354, in _do_post
    return await super()._do_post(
           ^^^^^^^^^^^^^^^^^^^^^^^
    ...<6 lines>...
    )
    ^
  File "C:\Users\atikm\AppData\Local\Programs\Python\Python313\Lib\site-packages\telegram\_bot.py", line 648, in _do_post
    result = await request.post(
             ^^^^^^^^^^^^^^^^^^^
    ...<6 lines>...
    )
    ^
  File "C:\Users\atikm\AppData\Local\Programs\Python\Python313\Lib\site-packages\telegram\request\_baserequest.py", line 202, in post
    result = await self._request_wrapper(
             ^^^^^^^^^^^^^^^^^^^^^^^^^^^^
    ...<7 lines>...
    )
    ^
  File "C:\Users\atikm\AppData\Local\Programs\Python\Python313\Lib\site-packages\telegram\request\_baserequest.py", line 334, in _request_wrapper
    code, payload = await self.do_request(
                    ^^^^^^^^^^^^^^^^^^^^^^
    ...<7 lines>...
    )
    ^
  File "C:\Users\atikm\AppData\Local\Programs\Python\Python313\Lib\site-packages\telegram\request\_httpxrequest.py", line 310, in do_request
    raise TimedOut from err
telegram.error.TimedOut: Timed out
2025-01-28 02:45:15,556 - telegram.ext.Application - ERROR - No error handlers are registered, logging exception.
Traceback (most recent call last):
  File "C:\Users\atikm\AppData\Local\Programs\Python\Python313\Lib\site-packages\httpx\_transports\default.py", line 101, in map_httpcore_exceptions
    yield
  File "C:\Users\atikm\AppData\Local\Programs\Python\Python313\Lib\site-packages\httpx\_transports\default.py", line 394, in handle_async_request
    resp = await self._pool.handle_async_request(req)
           ^^^^^^^^^^^^^^^^^^^^^^^^^^^^^^^^^^^^^^^^^^
  File "C:\Users\atikm\AppData\Local\Programs\Python\Python313\Lib\site-packages\httpcore\_async\connection_pool.py", line 256, in handle_async_request
    raise exc from None
  File "C:\Users\atikm\AppData\Local\Programs\Python\Python313\Lib\site-packages\httpcore\_async\connection_pool.py", line 236, in handle_async_request
    response = await connection.handle_async_request(
               ^^^^^^^^^^^^^^^^^^^^^^^^^^^^^^^^^^^^^^
        pool_request.request
        ^^^^^^^^^^^^^^^^^^^^
    )
    ^
  File "C:\Users\atikm\AppData\Local\Programs\Python\Python313\Lib\site-packages\httpcore\_async\connection.py", line 101, in handle_async_request
    raise exc
  File "C:\Users\atikm\AppData\Local\Programs\Python\Python313\Lib\site-packages\httpcore\_async\connection.py", line 78, in handle_async_request
    stream = await self._connect(request)
             ^^^^^^^^^^^^^^^^^^^^^^^^^^^^
  File "C:\Users\atikm\AppData\Local\Programs\Python\Python313\Lib\site-packages\httpcore\_async\connection.py", line 124, in _connect
    stream = await self._network_backend.connect_tcp(**kwargs)
             ^^^^^^^^^^^^^^^^^^^^^^^^^^^^^^^^^^^^^^^^^^^^^^^^^
  File "C:\Users\atikm\AppData\Local\Programs\Python\Python313\Lib\site-packages\httpcore\_backends\auto.py", line 31, in connect_tcp
    return await self._backend.connect_tcp(
           ^^^^^^^^^^^^^^^^^^^^^^^^^^^^^^^^
    ...<5 lines>...
    )
    ^
  File "C:\Users\atikm\AppData\Local\Programs\Python\Python313\Lib\site-packages\httpcore\_backends\anyio.py", line 113, in connect_tcp
    with map_exceptions(exc_map):
         ~~~~~~~~~~~~~~^^^^^^^^^
  File "C:\Users\atikm\AppData\Local\Programs\Python\Python313\Lib\contextlib.py", line 162, in __exit__
    self.gen.throw(value)
    ~~~~~~~~~~~~~~^^^^^^^
  File "C:\Users\atikm\AppData\Local\Programs\Python\Python313\Lib\site-packages\httpcore\_exceptions.py", line 14, in map_exceptions
    raise to_exc(exc) from exc
httpcore.ConnectTimeout

The above exception was the direct cause of the following exception:

Traceback (most recent call last):
  File "C:\Users\atikm\AppData\Local\Programs\Python\Python313\Lib\site-packages\telegram\request\_httpxrequest.py", line 293, in do_request
    res = await self._client.request(
          ^^^^^^^^^^^^^^^^^^^^^^^^^^^
    ...<6 lines>...
    )
    ^
  File "C:\Users\atikm\AppData\Local\Programs\Python\Python313\Lib\site-packages\httpx\_client.py", line 1540, in request
    return await self.send(request, auth=auth, follow_redirects=follow_redirects)
           ^^^^^^^^^^^^^^^^^^^^^^^^^^^^^^^^^^^^^^^^^^^^^^^^^^^^^^^^^^^^^^^^^^^^^^
  File "C:\Users\atikm\AppData\Local\Programs\Python\Python313\Lib\site-packages\httpx\_client.py", line 1629, in send
    response = await self._send_handling_auth(
               ^^^^^^^^^^^^^^^^^^^^^^^^^^^^^^^
    ...<4 lines>...
    )
    ^
  File "C:\Users\atikm\AppData\Local\Programs\Python\Python313\Lib\site-packages\httpx\_client.py", line 1657, in _send_handling_auth
    response = await self._send_handling_redirects(
               ^^^^^^^^^^^^^^^^^^^^^^^^^^^^^^^^^^^^
    ...<3 lines>...
    )
    ^
  File "C:\Users\atikm\AppData\Local\Programs\Python\Python313\Lib\site-packages\httpx\_client.py", line 1694, in _send_handling_redirects
    response = await self._send_single_request(request)
               ^^^^^^^^^^^^^^^^^^^^^^^^^^^^^^^^^^^^^^^^
  File "C:\Users\atikm\AppData\Local\Programs\Python\Python313\Lib\site-packages\httpx\_client.py", line 1730, in _send_single_request
    response = await transport.handle_async_request(request)
               ^^^^^^^^^^^^^^^^^^^^^^^^^^^^^^^^^^^^^^^^^^^^^
  File "C:\Users\atikm\AppData\Local\Programs\Python\Python313\Lib\site-packages\httpx\_transports\default.py", line 393, in handle_async_request
    with map_httpcore_exceptions():
         ~~~~~~~~~~~~~~~~~~~~~~~^^
  File "C:\Users\atikm\AppData\Local\Programs\Python\Python313\Lib\contextlib.py", line 162, in __exit__
    self.gen.throw(value)
    ~~~~~~~~~~~~~~^^^^^^^
  File "C:\Users\atikm\AppData\Local\Programs\Python\Python313\Lib\site-packages\httpx\_transports\default.py", line 118, in map_httpcore_exceptions
    raise mapped_exc(message) from exc
httpx.ConnectTimeout

The above exception was the direct cause of the following exception:

Traceback (most recent call last):
  File "C:\Users\atikm\AppData\Local\Programs\Python\Python313\Lib\site-packages\telegram\ext\_application.py", line 1325, in process_update
    await coroutine
  File "C:\Users\atikm\AppData\Local\Programs\Python\Python313\Lib\site-packages\telegram\ext\_handlers\basehandler.py", line 158, in handle_update
    return await self.callback(update, context)
           ^^^^^^^^^^^^^^^^^^^^^^^^^^^^^^^^^^^^
  File "c:\Users\atikm\Desktop\PROJECT\YTDOWNLOADER\main.py", line 77, in history
    await update.message.reply_text("You don't have any download history yet.")
  File "C:\Users\atikm\AppData\Local\Programs\Python\Python313\Lib\site-packages\telegram\_message.py", line 1771, in reply_text
    return await self.get_bot().send_message(
           ^^^^^^^^^^^^^^^^^^^^^^^^^^^^^^^^^^
    ...<20 lines>...
    )
    ^
  File "C:\Users\atikm\AppData\Local\Programs\Python\Python313\Lib\site-packages\telegram\ext\_extbot.py", line 2965, in send_message
    return await super().send_message(
           ^^^^^^^^^^^^^^^^^^^^^^^^^^^
    ...<21 lines>...
    )
    ^
  File "C:\Users\atikm\AppData\Local\Programs\Python\Python313\Lib\site-packages\telegram\_bot.py", line 1019, in send_message
    return await self._send_message(
           ^^^^^^^^^^^^^^^^^^^^^^^^^
    ...<19 lines>...
    )
    ^
  File "C:\Users\atikm\AppData\Local\Programs\Python\Python313\Lib\site-packages\telegram\ext\_extbot.py", line 610, in _send_message
    result = await super()._send_message(
             ^^^^^^^^^^^^^^^^^^^^^^^^^^^^
    ...<21 lines>...
    )
    ^
  File "C:\Users\atikm\AppData\Local\Programs\Python\Python313\Lib\site-packages\telegram\_bot.py", line 731, in _send_message
    result = await self._post(
             ^^^^^^^^^^^^^^^^^
    ...<7 lines>...
    )
    ^
  File "C:\Users\atikm\AppData\Local\Programs\Python\Python313\Lib\site-packages\telegram\_bot.py", line 619, in _post
    return await self._do_post(
           ^^^^^^^^^^^^^^^^^^^^
    ...<6 lines>...
    )
    ^
  File "C:\Users\atikm\AppData\Local\Programs\Python\Python313\Lib\site-packages\telegram\ext\_extbot.py", line 354, in _do_post
    return await super()._do_post(
           ^^^^^^^^^^^^^^^^^^^^^^^
    ...<6 lines>...
    )
    ^
  File "C:\Users\atikm\AppData\Local\Programs\Python\Python313\Lib\site-packages\telegram\_bot.py", line 648, in _do_post
    result = await request.post(
             ^^^^^^^^^^^^^^^^^^^
    ...<6 lines>...
    )
    ^
  File "C:\Users\atikm\AppData\Local\Programs\Python\Python313\Lib\site-packages\telegram\request\_baserequest.py", line 202, in post
    result = await self._request_wrapper(
             ^^^^^^^^^^^^^^^^^^^^^^^^^^^^
    ...<7 lines>...
    )
    ^
  File "C:\Users\atikm\AppData\Local\Programs\Python\Python313\Lib\site-packages\telegram\request\_baserequest.py", line 334, in _request_wrapper
    code, payload = await self.do_request(
                    ^^^^^^^^^^^^^^^^^^^^^^
    ...<7 lines>...
    )
    ^
  File "C:\Users\atikm\AppData\Local\Programs\Python\Python313\Lib\site-packages\telegram\request\_httpxrequest.py", line 310, in do_request
    raise TimedOut from err
telegram.error.TimedOut: Timed out
2025-01-28 02:45:19,584 - httpx - INFO - HTTP Request: POST https://api.telegram.org/bot8077274379:AAFawJIixuMK47T9RpxiMv0TC_FnYLA6LWI/getUpdates "HTTP/1.1 200 OK"
2025-01-28 02:45:29,824 - httpx - INFO - HTTP Request: POST https://api.telegram.org/bot8077274379:AAFawJIixuMK47T9RpxiMv0TC_FnYLA6LWI/getUpdates "HTTP/1.1 200 OK"
2025-01-28 02:45:30,822 - httpx - INFO - HTTP Request: POST https://api.telegram.org/bot8077274379:AAFawJIixuMK47T9RpxiMv0TC_FnYLA6LWI/getUpdates "HTTP/1.1 200 OK"
2025-01-28 02:45:30,825 - __main__ - INFO - INFO - User ERROR (ID: 2142334821) started the bot.
2025-01-28 02:45:31,574 - httpx - INFO - HTTP Request: POST https://api.telegram.org/bot8077274379:AAFawJIixuMK47T9RpxiMv0TC_FnYLA6LWI/sendMessage "HTTP/1.1 200 OK"
2025-01-28 02:45:34,230 - httpx - INFO - HTTP Request: POST https://api.telegram.org/bot8077274379:AAFawJIixuMK47T9RpxiMv0TC_FnYLA6LWI/getUpdates "HTTP/1.1 200 OK"
2025-01-28 02:45:34,644 - httpx - INFO - HTTP Request: POST https://api.telegram.org/bot8077274379:AAFawJIixuMK47T9RpxiMv0TC_FnYLA6LWI/sendMessage "HTTP/1.1 200 OK"
2025-01-28 02:45:36,882 - httpx - INFO - HTTP Request: POST https://api.telegram.org/bot8077274379:AAFawJIixuMK47T9RpxiMv0TC_FnYLA6LWI/getUpdates "HTTP/1.1 200 OK"
2025-01-28 02:45:37,307 - httpx - INFO - HTTP Request: POST https://api.telegram.org/bot8077274379:AAFawJIixuMK47T9RpxiMv0TC_FnYLA6LWI/sendMessage "HTTP/1.1 200 OK"
2025-01-28 02:45:47,129 - httpx - INFO - HTTP Request: POST https://api.telegram.org/bot8077274379:AAFawJIixuMK47T9RpxiMv0TC_FnYLA6LWI/getUpdates "HTTP/1.1 200 OK"
2025-01-28 02:45:57,280 - httpx - INFO - HTTP Request: POST https://api.telegram.org/bot8077274379:AAFawJIixuMK47T9RpxiMv0TC_FnYLA6LWI/getUpdates "HTTP/1.1 200 OK"
2025-01-28 02:46:07,507 - httpx - INFO - HTTP Request: POST https://api.telegram.org/bot8077274379:AAFawJIixuMK47T9RpxiMv0TC_FnYLA6LWI/getUpdates "HTTP/1.1 200 OK"
2025-01-28 02:46:17,663 - httpx - INFO - HTTP Request: POST https://api.telegram.org/bot8077274379:AAFawJIixuMK47T9RpxiMv0TC_FnYLA6LWI/getUpdates "HTTP/1.1 200 OK"
2025-01-28 02:46:19,387 - httpx - INFO - HTTP Request: POST https://api.telegram.org/bot8077274379:AAFawJIixuMK47T9RpxiMv0TC_FnYLA6LWI/getUpdates "HTTP/1.1 200 OK"
2025-01-28 02:46:20,237 - httpx - INFO - HTTP Request: POST https://api.telegram.org/bot8077274379:AAFawJIixuMK47T9RpxiMv0TC_FnYLA6LWI/sendMessage "HTTP/1.1 200 OK"
2025-01-28 02:46:29,527 - httpx - INFO - HTTP Request: POST https://api.telegram.org/bot8077274379:AAFawJIixuMK47T9RpxiMv0TC_FnYLA6LWI/getUpdates "HTTP/1.1 200 OK"
2025-01-28 02:46:36,292 - httpx - INFO - HTTP Request: POST https://api.telegram.org/bot8077274379:AAFawJIixuMK47T9RpxiMv0TC_FnYLA6LWI/getUpdates "HTTP/1.1 200 OK"
2025-01-28 02:46:37,108 - httpx - INFO - HTTP Request: POST https://api.telegram.org/bot8077274379:AAFawJIixuMK47T9RpxiMv0TC_FnYLA6LWI/sendMessage "HTTP/1.1 200 OK"
2025-01-28 02:46:46,520 - httpx - INFO - HTTP Request: POST https://api.telegram.org/bot8077274379:AAFawJIixuMK47T9RpxiMv0TC_FnYLA6LWI/getUpdates "HTTP/1.1 200 OK"
2025-01-28 02:46:47,136 - httpx - INFO - HTTP Request: POST https://api.telegram.org/bot8077274379:AAFawJIixuMK47T9RpxiMv0TC_FnYLA6LWI/getUpdates "HTTP/1.1 200 OK"
2025-01-28 02:46:47,960 - httpx - INFO - HTTP Request: POST https://api.telegram.org/bot8077274379:AAFawJIixuMK47T9RpxiMv0TC_FnYLA6LWI/sendMessage "HTTP/1.1 200 OK"
2025-01-28 02:46:56,565 - httpx - INFO - HTTP Request: POST https://api.telegram.org/bot8077274379:AAFawJIixuMK47T9RpxiMv0TC_FnYLA6LWI/getUpdates "HTTP/1.1 200 OK"
2025-01-28 02:46:56,567 - __main__ - INFO - INFO - User ERROR (ID: 2142334821) started the bot.
2025-01-28 02:46:57,379 - httpx - INFO - HTTP Request: POST https://api.telegram.org/bot8077274379:AAFawJIixuMK47T9RpxiMv0TC_FnYLA6LWI/sendMessage "HTTP/1.1 200 OK"
2025-01-28 02:46:58,730 - httpx - INFO - HTTP Request: POST https://api.telegram.org/bot8077274379:AAFawJIixuMK47T9RpxiMv0TC_FnYLA6LWI/getUpdates "HTTP/1.1 200 OK"
2025-01-28 02:46:59,117 - httpx - INFO - HTTP Request: POST https://api.telegram.org/bot8077274379:AAFawJIixuMK47T9RpxiMv0TC_FnYLA6LWI/sendMessage "HTTP/1.1 200 OK"
2025-01-28 02:47:09,005 - httpx - INFO - HTTP Request: POST https://api.telegram.org/bot8077274379:AAFawJIixuMK47T9RpxiMv0TC_FnYLA6LWI/getUpdates "HTTP/1.1 200 OK"
2025-01-28 02:47:19,196 - httpx - INFO - HTTP Request: POST https://api.telegram.org/bot8077274379:AAFawJIixuMK47T9RpxiMv0TC_FnYLA6LWI/getUpdates "HTTP/1.1 200 OK"
2025-01-28 02:47:29,428 - httpx - INFO - HTTP Request: POST https://api.telegram.org/bot8077274379:AAFawJIixuMK47T9RpxiMv0TC_FnYLA6LWI/getUpdates "HTTP/1.1 200 OK"
2025-01-28 02:47:39,667 - httpx - INFO - HTTP Request: POST https://api.telegram.org/bot8077274379:AAFawJIixuMK47T9RpxiMv0TC_FnYLA6LWI/getUpdates "HTTP/1.1 200 OK"
2025-01-28 02:47:49,912 - httpx - INFO - HTTP Request: POST https://api.telegram.org/bot8077274379:AAFawJIixuMK47T9RpxiMv0TC_FnYLA6LWI/getUpdates "HTTP/1.1 200 OK"
2025-01-28 02:48:00,050 - httpx - INFO - HTTP Request: POST https://api.telegram.org/bot8077274379:AAFawJIixuMK47T9RpxiMv0TC_FnYLA6LWI/getUpdates "HTTP/1.1 200 OK"
2025-01-28 02:48:10,210 - httpx - INFO - HTTP Request: POST https://api.telegram.org/bot8077274379:AAFawJIixuMK47T9RpxiMv0TC_FnYLA6LWI/getUpdates "HTTP/1.1 200 OK"
2025-01-28 02:48:20,426 - httpx - INFO - HTTP Request: POST https://api.telegram.org/bot8077274379:AAFawJIixuMK47T9RpxiMv0TC_FnYLA6LWI/getUpdates "HTTP/1.1 200 OK"
2025-01-28 02:48:30,765 - httpx - INFO - HTTP Request: POST https://api.telegram.org/bot8077274379:AAFawJIixuMK47T9RpxiMv0TC_FnYLA6LWI/getUpdates "HTTP/1.1 200 OK"
2025-01-28 02:48:40,923 - httpx - INFO - HTTP Request: POST https://api.telegram.org/bot8077274379:AAFawJIixuMK47T9RpxiMv0TC_FnYLA6LWI/getUpdates "HTTP/1.1 200 OK"
2025-01-28 02:48:54,691 - __main__ - INFO - 
STARTING THE BOT

2025-01-28 02:48:56,368 - httpx - INFO - HTTP Request: POST https://api.telegram.org/bot8077274379:AAFawJIixuMK47T9RpxiMv0TC_FnYLA6LWI/setMyCommands "HTTP/1.1 200 OK"
2025-01-28 02:48:56,369 - __main__ - INFO - 
BOT HAS STARTED

2025-01-28 02:48:56,369 - __main__ - INFO - 
BOT IS RUNNING

2025-01-28 02:48:56,369 - __main__ - INFO - 
WAITING FOR USER INTERACTIONS...

2025-01-28 02:48:57,610 - httpx - INFO - HTTP Request: POST https://api.telegram.org/bot8077274379:AAFawJIixuMK47T9RpxiMv0TC_FnYLA6LWI/getMe "HTTP/1.1 200 OK"
2025-01-28 02:48:57,807 - httpx - INFO - HTTP Request: POST https://api.telegram.org/bot8077274379:AAFawJIixuMK47T9RpxiMv0TC_FnYLA6LWI/deleteWebhook "HTTP/1.1 200 OK"
2025-01-28 02:48:57,810 - telegram.ext.Application - INFO - Application started
2025-01-28 02:49:05,996 - httpx - INFO - HTTP Request: POST https://api.telegram.org/bot8077274379:AAFawJIixuMK47T9RpxiMv0TC_FnYLA6LWI/getUpdates "HTTP/1.1 200 OK"
2025-01-28 02:49:05,998 - __main__ - INFO - INFO - User ERROR (ID: 2142334821) started the bot.
2025-01-28 02:49:06,916 - httpx - INFO - HTTP Request: POST https://api.telegram.org/bot8077274379:AAFawJIixuMK47T9RpxiMv0TC_FnYLA6LWI/sendMessage "HTTP/1.1 200 OK"
2025-01-28 02:49:09,372 - httpx - INFO - HTTP Request: POST https://api.telegram.org/bot8077274379:AAFawJIixuMK47T9RpxiMv0TC_FnYLA6LWI/getUpdates "HTTP/1.1 200 OK"
2025-01-28 02:49:09,778 - httpx - INFO - HTTP Request: POST https://api.telegram.org/bot8077274379:AAFawJIixuMK47T9RpxiMv0TC_FnYLA6LWI/sendMessage "HTTP/1.1 200 OK"
2025-01-28 02:49:14,358 - httpx - INFO - HTTP Request: POST https://api.telegram.org/bot8077274379:AAFawJIixuMK47T9RpxiMv0TC_FnYLA6LWI/getUpdates "HTTP/1.1 200 OK"
2025-01-28 02:49:14,803 - httpx - INFO - HTTP Request: POST https://api.telegram.org/bot8077274379:AAFawJIixuMK47T9RpxiMv0TC_FnYLA6LWI/sendMessage "HTTP/1.1 200 OK"
2025-01-28 02:49:17,260 - httpx - INFO - HTTP Request: POST https://api.telegram.org/bot8077274379:AAFawJIixuMK47T9RpxiMv0TC_FnYLA6LWI/getUpdates "HTTP/1.1 200 OK"
2025-01-28 02:49:17,262 - __main__ - INFO - INFO - User ERROR invoked the /help command.
2025-01-28 02:49:17,759 - httpx - INFO - HTTP Request: POST https://api.telegram.org/bot8077274379:AAFawJIixuMK47T9RpxiMv0TC_FnYLA6LWI/sendMessage "HTTP/1.1 200 OK"
2025-01-28 02:49:27,411 - httpx - INFO - HTTP Request: POST https://api.telegram.org/bot8077274379:AAFawJIixuMK47T9RpxiMv0TC_FnYLA6LWI/getUpdates "HTTP/1.1 200 OK"
2025-01-28 02:49:31,082 - httpx - INFO - HTTP Request: POST https://api.telegram.org/bot8077274379:AAFawJIixuMK47T9RpxiMv0TC_FnYLA6LWI/getUpdates "HTTP/1.1 200 OK"
2025-01-28 02:49:31,084 - __main__ - INFO - INFO - User ERROR invoked the /help command.
2025-01-28 02:49:31,919 - httpx - INFO - HTTP Request: POST https://api.telegram.org/bot8077274379:AAFawJIixuMK47T9RpxiMv0TC_FnYLA6LWI/sendMessage "HTTP/1.1 200 OK"
2025-01-28 02:49:41,332 - httpx - INFO - HTTP Request: POST https://api.telegram.org/bot8077274379:AAFawJIixuMK47T9RpxiMv0TC_FnYLA6LWI/getUpdates "HTTP/1.1 200 OK"
2025-01-28 02:49:51,565 - httpx - INFO - HTTP Request: POST https://api.telegram.org/bot8077274379:AAFawJIixuMK47T9RpxiMv0TC_FnYLA6LWI/getUpdates "HTTP/1.1 200 OK"
2025-01-28 02:50:01,706 - httpx - INFO - HTTP Request: POST https://api.telegram.org/bot8077274379:AAFawJIixuMK47T9RpxiMv0TC_FnYLA6LWI/getUpdates "HTTP/1.1 200 OK"
2025-01-28 02:50:12,046 - httpx - INFO - HTTP Request: POST https://api.telegram.org/bot8077274379:AAFawJIixuMK47T9RpxiMv0TC_FnYLA6LWI/getUpdates "HTTP/1.1 200 OK"
2025-01-28 02:50:22,287 - httpx - INFO - HTTP Request: POST https://api.telegram.org/bot8077274379:AAFawJIixuMK47T9RpxiMv0TC_FnYLA6LWI/getUpdates "HTTP/1.1 200 OK"
2025-01-28 03:01:49,993 - __main__ - INFO - 
STARTING THE BOT

2025-01-28 03:01:51,638 - httpx - INFO - HTTP Request: POST https://api.telegram.org/bot8077274379:AAFawJIixuMK47T9RpxiMv0TC_FnYLA6LWI/setMyCommands "HTTP/1.1 200 OK"
2025-01-28 03:01:51,641 - __main__ - INFO - 
BOT HAS STARTED

2025-01-28 03:01:51,641 - __main__ - INFO - 
BOT IS RUNNING

2025-01-28 03:01:51,642 - __main__ - INFO - 
WAITING FOR USER INTERACTIONS...

2025-01-28 03:01:52,165 - httpx - INFO - HTTP Request: POST https://api.telegram.org/bot8077274379:AAFawJIixuMK47T9RpxiMv0TC_FnYLA6LWI/getMe "HTTP/1.1 200 OK"
2025-01-28 03:01:52,457 - httpx - INFO - HTTP Request: POST https://api.telegram.org/bot8077274379:AAFawJIixuMK47T9RpxiMv0TC_FnYLA6LWI/deleteWebhook "HTTP/1.1 200 OK"
2025-01-28 03:01:52,459 - telegram.ext.Application - INFO - Application started
2025-01-28 03:01:57,283 - httpx - INFO - HTTP Request: POST https://api.telegram.org/bot8077274379:AAFawJIixuMK47T9RpxiMv0TC_FnYLA6LWI/getUpdates "HTTP/1.1 409 Conflict"
2025-01-28 03:01:57,285 - telegram.ext.Application - ERROR - No error handlers are registered, logging exception.
Traceback (most recent call last):
  File "C:\Users\atikm\AppData\Local\Programs\Python\Python313\Lib\site-packages\telegram\ext\_updater.py", line 750, in _network_loop_retry
    if not await do_action():
           ^^^^^^^^^^^^^^^^^
  File "C:\Users\atikm\AppData\Local\Programs\Python\Python313\Lib\site-packages\telegram\ext\_updater.py", line 744, in do_action
    return action_cb_task.result()
           ~~~~~~~~~~~~~~~~~~~~~^^
  File "C:\Users\atikm\AppData\Local\Programs\Python\Python313\Lib\asyncio\futures.py", line 199, in result
    raise self._exception.with_traceback(self._exception_tb)
  File "C:\Users\atikm\AppData\Local\Programs\Python\Python313\Lib\asyncio\tasks.py", line 304, in __step_run_and_handle_result
    result = coro.send(None)
  File "C:\Users\atikm\AppData\Local\Programs\Python\Python313\Lib\site-packages\telegram\ext\_updater.py", line 371, in polling_action_cb
    updates = await self.bot.get_updates(
              ^^^^^^^^^^^^^^^^^^^^^^^^^^^
    ...<7 lines>...
    )
    ^
  File "C:\Users\atikm\AppData\Local\Programs\Python\Python313\Lib\site-packages\telegram\ext\_extbot.py", line 650, in get_updates
    updates = await super().get_updates(
              ^^^^^^^^^^^^^^^^^^^^^^^^^^
    ...<9 lines>...
    )
    ^
  File "C:\Users\atikm\AppData\Local\Programs\Python\Python313\Lib\site-packages\telegram\_bot.py", line 4480, in get_updates
    await self._post(
    ^^^^^^^^^^^^^^^^^
    ...<7 lines>...
    ),
    ^
  File "C:\Users\atikm\AppData\Local\Programs\Python\Python313\Lib\site-packages\telegram\_bot.py", line 619, in _post
    return await self._do_post(
           ^^^^^^^^^^^^^^^^^^^^
    ...<6 lines>...
    )
    ^
  File "C:\Users\atikm\AppData\Local\Programs\Python\Python313\Lib\site-packages\telegram\ext\_extbot.py", line 354, in _do_post
    return await super()._do_post(
           ^^^^^^^^^^^^^^^^^^^^^^^
    ...<6 lines>...
    )
    ^
  File "C:\Users\atikm\AppData\Local\Programs\Python\Python313\Lib\site-packages\telegram\_bot.py", line 648, in _do_post
    result = await request.post(
             ^^^^^^^^^^^^^^^^^^^
    ...<6 lines>...
    )
    ^
  File "C:\Users\atikm\AppData\Local\Programs\Python\Python313\Lib\site-packages\telegram\request\_baserequest.py", line 202, in post
    result = await self._request_wrapper(
             ^^^^^^^^^^^^^^^^^^^^^^^^^^^^
    ...<7 lines>...
    )
    ^
  File "C:\Users\atikm\AppData\Local\Programs\Python\Python313\Lib\site-packages\telegram\request\_baserequest.py", line 385, in _request_wrapper
    raise Conflict(message)
telegram.error.Conflict: Conflict: terminated by other getUpdates request; make sure that only one bot instance is running
