2025-01-26 23:48:32,745 - __main__ - INFO - 
STARTING THE BOT

2025-01-26 23:48:33,456 - __main__ - INFO - 
BOT HAS STARTED

2025-01-26 23:48:33,457 - __main__ - INFO - 
BOT IS RUNNING

2025-01-26 23:48:33,457 - __main__ - INFO - 
WAITING FOR USER INTERACTIONS...

2025-01-26 23:48:34,463 - httpx - INFO - HTTP Request: POST https://api.telegram.org/bot8077274379:AAFawJIixuMK47T9RpxiMv0TC_FnYLA6LWI/getMe "HTTP/1.1 200 OK"
2025-01-26 23:48:34,696 - httpx - INFO - HTTP Request: POST https://api.telegram.org/bot8077274379:AAFawJIixuMK47T9RpxiMv0TC_FnYLA6LWI/deleteWebhook "HTTP/1.1 200 OK"
2025-01-26 23:48:34,699 - telegram.ext.Application - INFO - Application started
2025-01-26 23:48:46,455 - httpx - INFO - HTTP Request: POST https://api.telegram.org/bot8077274379:AAFawJIixuMK47T9RpxiMv0TC_FnYLA6LWI/getUpdates "HTTP/1.1 200 OK"
2025-01-26 23:48:48,311 - httpx - INFO - HTTP Request: POST https://api.telegram.org/bot8077274379:AAFawJIixuMK47T9RpxiMv0TC_FnYLA6LWI/getUpdates "HTTP/1.1 200 OK"
2025-01-26 23:48:48,314 - __main__ - INFO - INFO - User Sakir (ID: 5721819840) started the bot.
2025-01-26 23:48:49,216 - httpx - INFO - HTTP Request: POST https://api.telegram.org/bot8077274379:AAFawJIixuMK47T9RpxiMv0TC_FnYLA6LWI/sendMessage "HTTP/1.1 200 OK"
2025-01-26 23:48:54,849 - httpx - INFO - HTTP Request: POST https://api.telegram.org/bot8077274379:AAFawJIixuMK47T9RpxiMv0TC_FnYLA6LWI/getUpdates "HTTP/1.1 200 OK"
2025-01-26 23:48:55,830 - httpx - INFO - HTTP Request: POST https://api.telegram.org/bot8077274379:AAFawJIixuMK47T9RpxiMv0TC_FnYLA6LWI/answerCallbackQuery "HTTP/1.1 200 OK"
2025-01-26 23:48:56,274 - httpx - INFO - HTTP Request: POST https://api.telegram.org/bot8077274379:AAFawJIixuMK47T9RpxiMv0TC_FnYLA6LWI/editMessageText "HTTP/1.1 200 OK"
2025-01-26 23:49:04,991 - httpx - INFO - HTTP Request: POST https://api.telegram.org/bot8077274379:AAFawJIixuMK47T9RpxiMv0TC_FnYLA6LWI/getUpdates "HTTP/1.1 200 OK"
2025-01-26 23:49:15,233 - httpx - INFO - HTTP Request: POST https://api.telegram.org/bot8077274379:AAFawJIixuMK47T9RpxiMv0TC_FnYLA6LWI/getUpdates "HTTP/1.1 200 OK"
2025-01-26 23:49:25,476 - httpx - INFO - HTTP Request: POST https://api.telegram.org/bot8077274379:AAFawJIixuMK47T9RpxiMv0TC_FnYLA6LWI/getUpdates "HTTP/1.1 200 OK"
2025-01-26 23:49:35,725 - httpx - INFO - HTTP Request: POST https://api.telegram.org/bot8077274379:AAFawJIixuMK47T9RpxiMv0TC_FnYLA6LWI/getUpdates "HTTP/1.1 200 OK"
2025-01-26 23:49:45,874 - httpx - INFO - HTTP Request: POST https://api.telegram.org/bot8077274379:AAFawJIixuMK47T9RpxiMv0TC_FnYLA6LWI/getUpdates "HTTP/1.1 200 OK"
2025-01-26 23:49:54,676 - httpx - INFO - HTTP Request: POST https://api.telegram.org/bot8077274379:AAFawJIixuMK47T9RpxiMv0TC_FnYLA6LWI/getUpdates "HTTP/1.1 200 OK"
2025-01-26 23:49:55,975 - httpx - INFO - HTTP Request: POST https://api.telegram.org/bot8077274379:AAFawJIixuMK47T9RpxiMv0TC_FnYLA6LWI/sendMessage "HTTP/1.1 200 OK"
2025-01-26 23:50:06,059 - httpx - INFO - HTTP Request: POST https://api.telegram.org/bot8077274379:AAFawJIixuMK47T9RpxiMv0TC_FnYLA6LWI/getUpdates "HTTP/1.1 200 OK"
2025-01-26 23:50:10,155 - httpx - INFO - HTTP Request: POST https://api.telegram.org/bot8077274379:AAFawJIixuMK47T9RpxiMv0TC_FnYLA6LWI/sendDocument "HTTP/1.1 200 OK"
2025-01-26 23:50:10,633 - httpx - INFO - HTTP Request: POST https://api.telegram.org/bot8077274379:AAFawJIixuMK47T9RpxiMv0TC_FnYLA6LWI/sendMessage "HTTP/1.1 200 OK"
2025-01-26 23:50:16,302 - httpx - INFO - HTTP Request: POST https://api.telegram.org/bot8077274379:AAFawJIixuMK47T9RpxiMv0TC_FnYLA6LWI/getUpdates "HTTP/1.1 200 OK"
2025-01-26 23:50:26,450 - httpx - INFO - HTTP Request: POST https://api.telegram.org/bot8077274379:AAFawJIixuMK47T9RpxiMv0TC_FnYLA6LWI/getUpdates "HTTP/1.1 200 OK"
2025-01-26 23:50:36,848 - httpx - INFO - HTTP Request: POST https://api.telegram.org/bot8077274379:AAFawJIixuMK47T9RpxiMv0TC_FnYLA6LWI/getUpdates "HTTP/1.1 200 OK"
2025-01-26 23:50:47,157 - httpx - INFO - HTTP Request: POST https://api.telegram.org/bot8077274379:AAFawJIixuMK47T9RpxiMv0TC_FnYLA6LWI/getUpdates "HTTP/1.1 200 OK"
2025-01-26 23:50:57,834 - httpx - INFO - HTTP Request: POST https://api.telegram.org/bot8077274379:AAFawJIixuMK47T9RpxiMv0TC_FnYLA6LWI/getUpdates "HTTP/1.1 200 OK"
2025-01-26 23:51:08,107 - httpx - INFO - HTTP Request: POST https://api.telegram.org/bot8077274379:AAFawJIixuMK47T9RpxiMv0TC_FnYLA6LWI/getUpdates "HTTP/1.1 200 OK"
2025-01-26 23:51:18,523 - httpx - INFO - HTTP Request: POST https://api.telegram.org/bot8077274379:AAFawJIixuMK47T9RpxiMv0TC_FnYLA6LWI/getUpdates "HTTP/1.1 200 OK"
2025-01-26 23:51:28,867 - httpx - INFO - HTTP Request: POST https://api.telegram.org/bot8077274379:AAFawJIixuMK47T9RpxiMv0TC_FnYLA6LWI/getUpdates "HTTP/1.1 200 OK"
2025-01-26 23:51:39,720 - httpx - INFO - HTTP Request: POST https://api.telegram.org/bot8077274379:AAFawJIixuMK47T9RpxiMv0TC_FnYLA6LWI/getUpdates "HTTP/1.1 200 OK"
2025-01-26 23:51:49,872 - httpx - INFO - HTTP Request: POST https://api.telegram.org/bot8077274379:AAFawJIixuMK47T9RpxiMv0TC_FnYLA6LWI/getUpdates "HTTP/1.1 200 OK"
2025-01-26 23:52:00,123 - httpx - INFO - HTTP Request: POST https://api.telegram.org/bot8077274379:AAFawJIixuMK47T9RpxiMv0TC_FnYLA6LWI/getUpdates "HTTP/1.1 200 OK"
2025-01-26 23:52:10,332 - httpx - INFO - HTTP Request: POST https://api.telegram.org/bot8077274379:AAFawJIixuMK47T9RpxiMv0TC_FnYLA6LWI/getUpdates "HTTP/1.1 200 OK"
2025-01-26 23:52:20,479 - httpx - INFO - HTTP Request: POST https://api.telegram.org/bot8077274379:AAFawJIixuMK47T9RpxiMv0TC_FnYLA6LWI/getUpdates "HTTP/1.1 200 OK"
2025-01-26 23:52:30,932 - httpx - INFO - HTTP Request: POST https://api.telegram.org/bot8077274379:AAFawJIixuMK47T9RpxiMv0TC_FnYLA6LWI/getUpdates "HTTP/1.1 200 OK"
2025-01-26 23:52:41,154 - httpx - INFO - HTTP Request: POST https://api.telegram.org/bot8077274379:AAFawJIixuMK47T9RpxiMv0TC_FnYLA6LWI/getUpdates "HTTP/1.1 200 OK"
2025-01-26 23:52:51,559 - httpx - INFO - HTTP Request: POST https://api.telegram.org/bot8077274379:AAFawJIixuMK47T9RpxiMv0TC_FnYLA6LWI/getUpdates "HTTP/1.1 200 OK"
2025-01-26 23:53:02,387 - httpx - INFO - HTTP Request: POST https://api.telegram.org/bot8077274379:AAFawJIixuMK47T9RpxiMv0TC_FnYLA6LWI/getUpdates "HTTP/1.1 200 OK"
2025-01-27 00:00:26,275 - __main__ - INFO - 
STARTING THE BOT

2025-01-27 00:00:26,967 - __main__ - INFO - 
BOT HAS STARTED

2025-01-27 00:00:26,967 - __main__ - INFO - 
BOT IS RUNNING

2025-01-27 00:00:26,968 - __main__ - INFO - 
WAITING FOR USER INTERACTIONS...

2025-01-27 00:00:28,107 - httpx - INFO - HTTP Request: POST https://api.telegram.org/bot8077274379:AAFawJIixuMK47T9RpxiMv0TC_FnYLA6LWI/getMe "HTTP/1.1 200 OK"
2025-01-27 00:00:28,305 - httpx - INFO - HTTP Request: POST https://api.telegram.org/bot8077274379:AAFawJIixuMK47T9RpxiMv0TC_FnYLA6LWI/deleteWebhook "HTTP/1.1 200 OK"
2025-01-27 00:00:28,307 - telegram.ext.Application - INFO - Application started
2025-01-27 00:00:31,460 - httpx - INFO - HTTP Request: POST https://api.telegram.org/bot8077274379:AAFawJIixuMK47T9RpxiMv0TC_FnYLA6LWI/getUpdates "HTTP/1.1 200 OK"
2025-01-27 00:00:31,461 - __main__ - INFO - INFO - User Sakir (ID: 5721819840) started the bot.
2025-01-27 00:00:31,947 - httpx - INFO - HTTP Request: POST https://api.telegram.org/bot8077274379:AAFawJIixuMK47T9RpxiMv0TC_FnYLA6LWI/sendMessage "HTTP/1.1 200 OK"
2025-01-27 00:00:34,240 - httpx - INFO - HTTP Request: POST https://api.telegram.org/bot8077274379:AAFawJIixuMK47T9RpxiMv0TC_FnYLA6LWI/getUpdates "HTTP/1.1 200 OK"
2025-01-27 00:00:34,807 - httpx - INFO - HTTP Request: POST https://api.telegram.org/bot8077274379:AAFawJIixuMK47T9RpxiMv0TC_FnYLA6LWI/answerCallbackQuery "HTTP/1.1 200 OK"
2025-01-27 00:00:35,238 - httpx - INFO - HTTP Request: POST https://api.telegram.org/bot8077274379:AAFawJIixuMK47T9RpxiMv0TC_FnYLA6LWI/editMessageText "HTTP/1.1 200 OK"
2025-01-27 00:00:44,485 - httpx - INFO - HTTP Request: POST https://api.telegram.org/bot8077274379:AAFawJIixuMK47T9RpxiMv0TC_FnYLA6LWI/getUpdates "HTTP/1.1 200 OK"
2025-01-27 00:00:54,713 - httpx - INFO - HTTP Request: POST https://api.telegram.org/bot8077274379:AAFawJIixuMK47T9RpxiMv0TC_FnYLA6LWI/getUpdates "HTTP/1.1 200 OK"
2025-01-27 00:01:04,982 - httpx - INFO - HTTP Request: POST https://api.telegram.org/bot8077274379:AAFawJIixuMK47T9RpxiMv0TC_FnYLA6LWI/getUpdates "HTTP/1.1 200 OK"
2025-01-27 00:01:15,208 - httpx - INFO - HTTP Request: POST https://api.telegram.org/bot8077274379:AAFawJIixuMK47T9RpxiMv0TC_FnYLA6LWI/getUpdates "HTTP/1.1 200 OK"
2025-01-27 00:01:25,451 - httpx - INFO - HTTP Request: POST https://api.telegram.org/bot8077274379:AAFawJIixuMK47T9RpxiMv0TC_FnYLA6LWI/getUpdates "HTTP/1.1 200 OK"
2025-01-27 00:01:30,867 - httpx - INFO - HTTP Request: POST https://api.telegram.org/bot8077274379:AAFawJIixuMK47T9RpxiMv0TC_FnYLA6LWI/getUpdates "HTTP/1.1 200 OK"
2025-01-27 00:01:31,793 - httpx - INFO - HTTP Request: POST https://api.telegram.org/bot8077274379:AAFawJIixuMK47T9RpxiMv0TC_FnYLA6LWI/sendMessage "HTTP/1.1 200 OK"
2025-01-27 00:01:40,087 - httpx - INFO - HTTP Request: POST https://api.telegram.org/bot8077274379:AAFawJIixuMK47T9RpxiMv0TC_FnYLA6LWI/sendDocument "HTTP/1.1 200 OK"
2025-01-27 00:01:40,612 - httpx - INFO - HTTP Request: POST https://api.telegram.org/bot8077274379:AAFawJIixuMK47T9RpxiMv0TC_FnYLA6LWI/sendMessage "HTTP/1.1 200 OK"
2025-01-27 00:01:41,101 - httpx - INFO - HTTP Request: POST https://api.telegram.org/bot8077274379:AAFawJIixuMK47T9RpxiMv0TC_FnYLA6LWI/getUpdates "HTTP/1.1 200 OK"
2025-01-27 00:01:51,355 - httpx - INFO - HTTP Request: POST https://api.telegram.org/bot8077274379:AAFawJIixuMK47T9RpxiMv0TC_FnYLA6LWI/getUpdates "HTTP/1.1 200 OK"
2025-01-27 00:02:01,598 - httpx - INFO - HTTP Request: POST https://api.telegram.org/bot8077274379:AAFawJIixuMK47T9RpxiMv0TC_FnYLA6LWI/getUpdates "HTTP/1.1 200 OK"
2025-01-27 00:02:11,831 - httpx - INFO - HTTP Request: POST https://api.telegram.org/bot8077274379:AAFawJIixuMK47T9RpxiMv0TC_FnYLA6LWI/getUpdates "HTTP/1.1 200 OK"
2025-01-27 00:02:22,069 - httpx - INFO - HTTP Request: POST https://api.telegram.org/bot8077274379:AAFawJIixuMK47T9RpxiMv0TC_FnYLA6LWI/getUpdates "HTTP/1.1 200 OK"
2025-01-27 00:02:32,311 - httpx - INFO - HTTP Request: POST https://api.telegram.org/bot8077274379:AAFawJIixuMK47T9RpxiMv0TC_FnYLA6LWI/getUpdates "HTTP/1.1 200 OK"
2025-01-27 00:02:42,543 - httpx - INFO - HTTP Request: POST https://api.telegram.org/bot8077274379:AAFawJIixuMK47T9RpxiMv0TC_FnYLA6LWI/getUpdates "HTTP/1.1 200 OK"
2025-01-27 00:02:52,842 - httpx - INFO - HTTP Request: POST https://api.telegram.org/bot8077274379:AAFawJIixuMK47T9RpxiMv0TC_FnYLA6LWI/getUpdates "HTTP/1.1 200 OK"
2025-01-27 00:03:03,140 - httpx - INFO - HTTP Request: POST https://api.telegram.org/bot8077274379:AAFawJIixuMK47T9RpxiMv0TC_FnYLA6LWI/getUpdates "HTTP/1.1 200 OK"
2025-01-27 00:03:15,018 - __main__ - INFO - 
STARTING THE BOT

2025-01-27 00:03:15,706 - __main__ - INFO - 
BOT HAS STARTED

2025-01-27 00:03:15,706 - __main__ - INFO - 
BOT IS RUNNING

2025-01-27 00:03:15,707 - __main__ - INFO - 
WAITING FOR USER INTERACTIONS...

2025-01-27 00:03:17,878 - httpx - INFO - HTTP Request: POST https://api.telegram.org/bot8077274379:AAFawJIixuMK47T9RpxiMv0TC_FnYLA6LWI/getMe "HTTP/1.1 200 OK"
2025-01-27 00:03:18,128 - httpx - INFO - HTTP Request: POST https://api.telegram.org/bot8077274379:AAFawJIixuMK47T9RpxiMv0TC_FnYLA6LWI/deleteWebhook "HTTP/1.1 200 OK"
2025-01-27 00:03:18,130 - telegram.ext.Application - INFO - Application started
2025-01-27 00:03:19,197 - httpx - INFO - HTTP Request: POST https://api.telegram.org/bot8077274379:AAFawJIixuMK47T9RpxiMv0TC_FnYLA6LWI/getUpdates "HTTP/1.1 200 OK"
2025-01-27 00:03:19,200 - __main__ - INFO - INFO - User Sakir (ID: 5721819840) started the bot.
2025-01-27 00:03:19,717 - httpx - INFO - HTTP Request: POST https://api.telegram.org/bot8077274379:AAFawJIixuMK47T9RpxiMv0TC_FnYLA6LWI/sendMessage "HTTP/1.1 200 OK"
2025-01-27 00:03:21,197 - httpx - INFO - HTTP Request: POST https://api.telegram.org/bot8077274379:AAFawJIixuMK47T9RpxiMv0TC_FnYLA6LWI/getUpdates "HTTP/1.1 200 OK"
2025-01-27 00:03:21,661 - httpx - INFO - HTTP Request: POST https://api.telegram.org/bot8077274379:AAFawJIixuMK47T9RpxiMv0TC_FnYLA6LWI/answerCallbackQuery "HTTP/1.1 200 OK"
2025-01-27 00:03:22,278 - httpx - INFO - HTTP Request: POST https://api.telegram.org/bot8077274379:AAFawJIixuMK47T9RpxiMv0TC_FnYLA6LWI/editMessageText "HTTP/1.1 200 OK"
2025-01-27 00:03:31,672 - httpx - INFO - HTTP Request: POST https://api.telegram.org/bot8077274379:AAFawJIixuMK47T9RpxiMv0TC_FnYLA6LWI/getUpdates "HTTP/1.1 200 OK"
2025-01-27 00:03:41,934 - httpx - INFO - HTTP Request: POST https://api.telegram.org/bot8077274379:AAFawJIixuMK47T9RpxiMv0TC_FnYLA6LWI/getUpdates "HTTP/1.1 200 OK"
2025-01-27 00:03:52,181 - httpx - INFO - HTTP Request: POST https://api.telegram.org/bot8077274379:AAFawJIixuMK47T9RpxiMv0TC_FnYLA6LWI/getUpdates "HTTP/1.1 200 OK"
2025-01-27 00:04:02,526 - httpx - INFO - HTTP Request: POST https://api.telegram.org/bot8077274379:AAFawJIixuMK47T9RpxiMv0TC_FnYLA6LWI/getUpdates "HTTP/1.1 200 OK"
2025-01-27 00:04:12,755 - httpx - INFO - HTTP Request: POST https://api.telegram.org/bot8077274379:AAFawJIixuMK47T9RpxiMv0TC_FnYLA6LWI/getUpdates "HTTP/1.1 200 OK"
2025-01-27 00:04:23,065 - httpx - INFO - HTTP Request: POST https://api.telegram.org/bot8077274379:AAFawJIixuMK47T9RpxiMv0TC_FnYLA6LWI/getUpdates "HTTP/1.1 200 OK"
2025-01-27 00:04:34,186 - httpx - INFO - HTTP Request: POST https://api.telegram.org/bot8077274379:AAFawJIixuMK47T9RpxiMv0TC_FnYLA6LWI/getUpdates "HTTP/1.1 200 OK"
2025-01-27 00:04:44,398 - httpx - INFO - HTTP Request: POST https://api.telegram.org/bot8077274379:AAFawJIixuMK47T9RpxiMv0TC_FnYLA6LWI/getUpdates "HTTP/1.1 200 OK"
2025-01-27 00:04:54,645 - httpx - INFO - HTTP Request: POST https://api.telegram.org/bot8077274379:AAFawJIixuMK47T9RpxiMv0TC_FnYLA6LWI/getUpdates "HTTP/1.1 200 OK"
2025-01-27 00:05:04,890 - httpx - INFO - HTTP Request: POST https://api.telegram.org/bot8077274379:AAFawJIixuMK47T9RpxiMv0TC_FnYLA6LWI/getUpdates "HTTP/1.1 200 OK"
2025-01-27 00:05:15,124 - httpx - INFO - HTTP Request: POST https://api.telegram.org/bot8077274379:AAFawJIixuMK47T9RpxiMv0TC_FnYLA6LWI/getUpdates "HTTP/1.1 200 OK"
2025-01-27 00:05:25,365 - httpx - INFO - HTTP Request: POST https://api.telegram.org/bot8077274379:AAFawJIixuMK47T9RpxiMv0TC_FnYLA6LWI/getUpdates "HTTP/1.1 200 OK"
2025-01-27 00:05:35,627 - httpx - INFO - HTTP Request: POST https://api.telegram.org/bot8077274379:AAFawJIixuMK47T9RpxiMv0TC_FnYLA6LWI/getUpdates "HTTP/1.1 200 OK"
2025-01-27 00:05:45,852 - httpx - INFO - HTTP Request: POST https://api.telegram.org/bot8077274379:AAFawJIixuMK47T9RpxiMv0TC_FnYLA6LWI/getUpdates "HTTP/1.1 200 OK"
2025-01-27 00:05:56,495 - httpx - INFO - HTTP Request: POST https://api.telegram.org/bot8077274379:AAFawJIixuMK47T9RpxiMv0TC_FnYLA6LWI/getUpdates "HTTP/1.1 200 OK"
2025-01-27 00:06:06,649 - httpx - INFO - HTTP Request: POST https://api.telegram.org/bot8077274379:AAFawJIixuMK47T9RpxiMv0TC_FnYLA6LWI/getUpdates "HTTP/1.1 200 OK"
2025-01-27 00:06:16,869 - httpx - INFO - HTTP Request: POST https://api.telegram.org/bot8077274379:AAFawJIixuMK47T9RpxiMv0TC_FnYLA6LWI/getUpdates "HTTP/1.1 200 OK"
2025-01-27 00:06:27,114 - httpx - INFO - HTTP Request: POST https://api.telegram.org/bot8077274379:AAFawJIixuMK47T9RpxiMv0TC_FnYLA6LWI/getUpdates "HTTP/1.1 200 OK"
2025-01-27 00:06:37,358 - httpx - INFO - HTTP Request: POST https://api.telegram.org/bot8077274379:AAFawJIixuMK47T9RpxiMv0TC_FnYLA6LWI/getUpdates "HTTP/1.1 200 OK"
2025-01-27 00:06:47,586 - httpx - INFO - HTTP Request: POST https://api.telegram.org/bot8077274379:AAFawJIixuMK47T9RpxiMv0TC_FnYLA6LWI/getUpdates "HTTP/1.1 200 OK"
2025-01-27 00:06:57,845 - httpx - INFO - HTTP Request: POST https://api.telegram.org/bot8077274379:AAFawJIixuMK47T9RpxiMv0TC_FnYLA6LWI/getUpdates "HTTP/1.1 200 OK"
2025-01-27 00:07:08,160 - httpx - INFO - HTTP Request: POST https://api.telegram.org/bot8077274379:AAFawJIixuMK47T9RpxiMv0TC_FnYLA6LWI/getUpdates "HTTP/1.1 200 OK"
2025-01-27 00:07:18,418 - httpx - INFO - HTTP Request: POST https://api.telegram.org/bot8077274379:AAFawJIixuMK47T9RpxiMv0TC_FnYLA6LWI/getUpdates "HTTP/1.1 200 OK"
2025-01-27 00:07:28,648 - httpx - INFO - HTTP Request: POST https://api.telegram.org/bot8077274379:AAFawJIixuMK47T9RpxiMv0TC_FnYLA6LWI/getUpdates "HTTP/1.1 200 OK"
2025-01-27 00:07:38,862 - httpx - INFO - HTTP Request: POST https://api.telegram.org/bot8077274379:AAFawJIixuMK47T9RpxiMv0TC_FnYLA6LWI/getUpdates "HTTP/1.1 200 OK"
2025-01-27 00:07:49,165 - httpx - INFO - HTTP Request: POST https://api.telegram.org/bot8077274379:AAFawJIixuMK47T9RpxiMv0TC_FnYLA6LWI/getUpdates "HTTP/1.1 200 OK"
2025-01-27 00:07:59,374 - httpx - INFO - HTTP Request: POST https://api.telegram.org/bot8077274379:AAFawJIixuMK47T9RpxiMv0TC_FnYLA6LWI/getUpdates "HTTP/1.1 200 OK"
2025-01-27 00:08:09,619 - httpx - INFO - HTTP Request: POST https://api.telegram.org/bot8077274379:AAFawJIixuMK47T9RpxiMv0TC_FnYLA6LWI/getUpdates "HTTP/1.1 200 OK"
2025-01-27 00:08:19,909 - httpx - INFO - HTTP Request: POST https://api.telegram.org/bot8077274379:AAFawJIixuMK47T9RpxiMv0TC_FnYLA6LWI/getUpdates "HTTP/1.1 200 OK"
2025-01-27 00:08:30,092 - httpx - INFO - HTTP Request: POST https://api.telegram.org/bot8077274379:AAFawJIixuMK47T9RpxiMv0TC_FnYLA6LWI/getUpdates "HTTP/1.1 200 OK"
2025-01-27 00:08:40,336 - httpx - INFO - HTTP Request: POST https://api.telegram.org/bot8077274379:AAFawJIixuMK47T9RpxiMv0TC_FnYLA6LWI/getUpdates "HTTP/1.1 200 OK"
2025-01-27 00:08:50,577 - httpx - INFO - HTTP Request: POST https://api.telegram.org/bot8077274379:AAFawJIixuMK47T9RpxiMv0TC_FnYLA6LWI/getUpdates "HTTP/1.1 200 OK"
2025-01-27 00:09:00,809 - httpx - INFO - HTTP Request: POST https://api.telegram.org/bot8077274379:AAFawJIixuMK47T9RpxiMv0TC_FnYLA6LWI/getUpdates "HTTP/1.1 200 OK"
2025-01-27 00:09:11,054 - httpx - INFO - HTTP Request: POST https://api.telegram.org/bot8077274379:AAFawJIixuMK47T9RpxiMv0TC_FnYLA6LWI/getUpdates "HTTP/1.1 200 OK"
2025-01-27 00:09:21,304 - httpx - INFO - HTTP Request: POST https://api.telegram.org/bot8077274379:AAFawJIixuMK47T9RpxiMv0TC_FnYLA6LWI/getUpdates "HTTP/1.1 200 OK"
2025-01-27 00:09:31,629 - httpx - INFO - HTTP Request: POST https://api.telegram.org/bot8077274379:AAFawJIixuMK47T9RpxiMv0TC_FnYLA6LWI/getUpdates "HTTP/1.1 200 OK"
2025-01-27 00:09:41,914 - httpx - INFO - HTTP Request: POST https://api.telegram.org/bot8077274379:AAFawJIixuMK47T9RpxiMv0TC_FnYLA6LWI/getUpdates "HTTP/1.1 200 OK"
2025-01-27 00:09:52,566 - httpx - INFO - HTTP Request: POST https://api.telegram.org/bot8077274379:AAFawJIixuMK47T9RpxiMv0TC_FnYLA6LWI/getUpdates "HTTP/1.1 200 OK"
2025-01-27 00:10:03,166 - httpx - INFO - HTTP Request: POST https://api.telegram.org/bot8077274379:AAFawJIixuMK47T9RpxiMv0TC_FnYLA6LWI/getUpdates "HTTP/1.1 200 OK"
2025-01-27 00:10:13,413 - httpx - INFO - HTTP Request: POST https://api.telegram.org/bot8077274379:AAFawJIixuMK47T9RpxiMv0TC_FnYLA6LWI/getUpdates "HTTP/1.1 200 OK"
2025-01-27 00:10:23,673 - httpx - INFO - HTTP Request: POST https://api.telegram.org/bot8077274379:AAFawJIixuMK47T9RpxiMv0TC_FnYLA6LWI/getUpdates "HTTP/1.1 200 OK"
2025-01-27 00:10:34,265 - httpx - INFO - HTTP Request: POST https://api.telegram.org/bot8077274379:AAFawJIixuMK47T9RpxiMv0TC_FnYLA6LWI/getUpdates "HTTP/1.1 200 OK"
2025-01-27 00:10:44,675 - httpx - INFO - HTTP Request: POST https://api.telegram.org/bot8077274379:AAFawJIixuMK47T9RpxiMv0TC_FnYLA6LWI/getUpdates "HTTP/1.1 200 OK"
2025-01-27 00:10:54,988 - httpx - INFO - HTTP Request: POST https://api.telegram.org/bot8077274379:AAFawJIixuMK47T9RpxiMv0TC_FnYLA6LWI/getUpdates "HTTP/1.1 200 OK"
2025-01-27 00:11:05,244 - httpx - INFO - HTTP Request: POST https://api.telegram.org/bot8077274379:AAFawJIixuMK47T9RpxiMv0TC_FnYLA6LWI/getUpdates "HTTP/1.1 200 OK"
2025-01-27 00:11:15,679 - httpx - INFO - HTTP Request: POST https://api.telegram.org/bot8077274379:AAFawJIixuMK47T9RpxiMv0TC_FnYLA6LWI/getUpdates "HTTP/1.1 200 OK"
2025-01-27 00:11:26,215 - httpx - INFO - HTTP Request: POST https://api.telegram.org/bot8077274379:AAFawJIixuMK47T9RpxiMv0TC_FnYLA6LWI/getUpdates "HTTP/1.1 200 OK"
2025-01-27 00:11:36,771 - httpx - INFO - HTTP Request: POST https://api.telegram.org/bot8077274379:AAFawJIixuMK47T9RpxiMv0TC_FnYLA6LWI/getUpdates "HTTP/1.1 200 OK"
2025-01-27 00:11:47,380 - httpx - INFO - HTTP Request: POST https://api.telegram.org/bot8077274379:AAFawJIixuMK47T9RpxiMv0TC_FnYLA6LWI/getUpdates "HTTP/1.1 200 OK"
2025-01-27 00:11:57,892 - httpx - INFO - HTTP Request: POST https://api.telegram.org/bot8077274379:AAFawJIixuMK47T9RpxiMv0TC_FnYLA6LWI/getUpdates "HTTP/1.1 200 OK"
2025-01-27 00:12:08,453 - httpx - INFO - HTTP Request: POST https://api.telegram.org/bot8077274379:AAFawJIixuMK47T9RpxiMv0TC_FnYLA6LWI/getUpdates "HTTP/1.1 200 OK"
2025-01-27 00:12:18,672 - httpx - INFO - HTTP Request: POST https://api.telegram.org/bot8077274379:AAFawJIixuMK47T9RpxiMv0TC_FnYLA6LWI/getUpdates "HTTP/1.1 200 OK"
2025-01-27 00:12:28,901 - httpx - INFO - HTTP Request: POST https://api.telegram.org/bot8077274379:AAFawJIixuMK47T9RpxiMv0TC_FnYLA6LWI/getUpdates "HTTP/1.1 200 OK"
2025-01-27 00:12:39,133 - httpx - INFO - HTTP Request: POST https://api.telegram.org/bot8077274379:AAFawJIixuMK47T9RpxiMv0TC_FnYLA6LWI/getUpdates "HTTP/1.1 200 OK"
2025-01-27 00:12:49,889 - httpx - INFO - HTTP Request: POST https://api.telegram.org/bot8077274379:AAFawJIixuMK47T9RpxiMv0TC_FnYLA6LWI/getUpdates "HTTP/1.1 200 OK"
2025-01-27 00:13:00,338 - httpx - INFO - HTTP Request: POST https://api.telegram.org/bot8077274379:AAFawJIixuMK47T9RpxiMv0TC_FnYLA6LWI/getUpdates "HTTP/1.1 200 OK"
2025-01-27 00:13:10,486 - httpx - INFO - HTTP Request: POST https://api.telegram.org/bot8077274379:AAFawJIixuMK47T9RpxiMv0TC_FnYLA6LWI/getUpdates "HTTP/1.1 200 OK"
2025-01-27 00:13:20,801 - httpx - INFO - HTTP Request: POST https://api.telegram.org/bot8077274379:AAFawJIixuMK47T9RpxiMv0TC_FnYLA6LWI/getUpdates "HTTP/1.1 200 OK"
2025-01-27 00:13:31,056 - httpx - INFO - HTTP Request: POST https://api.telegram.org/bot8077274379:AAFawJIixuMK47T9RpxiMv0TC_FnYLA6LWI/getUpdates "HTTP/1.1 200 OK"
2025-01-27 00:31:41,244 - telegram.ext.Application - ERROR - No error handlers are registered, logging exception.
Traceback (most recent call last):
  File "C:\Users\atikm\AppData\Local\Programs\Python\Python313\Lib\site-packages\httpx\_transports\default.py", line 101, in map_httpcore_exceptions
    yield
  File "C:\Users\atikm\AppData\Local\Programs\Python\Python313\Lib\site-packages\httpx\_transports\default.py", line 394, in handle_async_request
    resp = await self._pool.handle_async_request(req)
           ^^^^^^^^^^^^^^^^^^^^^^^^^^^^^^^^^^^^^^^^^^
  File "C:\Users\atikm\AppData\Local\Programs\Python\Python313\Lib\site-packages\httpcore\_async\connection_pool.py", line 256, in handle_async_request
    raise exc from None
  File "C:\Users\atikm\AppData\Local\Programs\Python\Python313\Lib\site-packages\httpcore\_async\connection_pool.py", line 236, in handle_async_request
    response = await connection.handle_async_request(
               ^^^^^^^^^^^^^^^^^^^^^^^^^^^^^^^^^^^^^^
        pool_request.request
        ^^^^^^^^^^^^^^^^^^^^
    )
    ^
  File "C:\Users\atikm\AppData\Local\Programs\Python\Python313\Lib\site-packages\httpcore\_async\connection.py", line 101, in handle_async_request
    raise exc
  File "C:\Users\atikm\AppData\Local\Programs\Python\Python313\Lib\site-packages\httpcore\_async\connection.py", line 78, in handle_async_request
    stream = await self._connect(request)
             ^^^^^^^^^^^^^^^^^^^^^^^^^^^^
  File "C:\Users\atikm\AppData\Local\Programs\Python\Python313\Lib\site-packages\httpcore\_async\connection.py", line 124, in _connect
    stream = await self._network_backend.connect_tcp(**kwargs)
             ^^^^^^^^^^^^^^^^^^^^^^^^^^^^^^^^^^^^^^^^^^^^^^^^^
  File "C:\Users\atikm\AppData\Local\Programs\Python\Python313\Lib\site-packages\httpcore\_backends\auto.py", line 31, in connect_tcp
    return await self._backend.connect_tcp(
           ^^^^^^^^^^^^^^^^^^^^^^^^^^^^^^^^
    ...<5 lines>...
    )
    ^
  File "C:\Users\atikm\AppData\Local\Programs\Python\Python313\Lib\site-packages\httpcore\_backends\anyio.py", line 113, in connect_tcp
    with map_exceptions(exc_map):
         ~~~~~~~~~~~~~~^^^^^^^^^
  File "C:\Users\atikm\AppData\Local\Programs\Python\Python313\Lib\contextlib.py", line 162, in __exit__
    self.gen.throw(value)
    ~~~~~~~~~~~~~~^^^^^^^
  File "C:\Users\atikm\AppData\Local\Programs\Python\Python313\Lib\site-packages\httpcore\_exceptions.py", line 14, in map_exceptions
    raise to_exc(exc) from exc
httpcore.ConnectError: [Errno 11001] getaddrinfo failed

The above exception was the direct cause of the following exception:

Traceback (most recent call last):
  File "C:\Users\atikm\AppData\Local\Programs\Python\Python313\Lib\site-packages\telegram\request\_httpxrequest.py", line 293, in do_request
    res = await self._client.request(
          ^^^^^^^^^^^^^^^^^^^^^^^^^^^
    ...<6 lines>...
    )
    ^
  File "C:\Users\atikm\AppData\Local\Programs\Python\Python313\Lib\site-packages\httpx\_client.py", line 1540, in request
    return await self.send(request, auth=auth, follow_redirects=follow_redirects)
           ^^^^^^^^^^^^^^^^^^^^^^^^^^^^^^^^^^^^^^^^^^^^^^^^^^^^^^^^^^^^^^^^^^^^^^
  File "C:\Users\atikm\AppData\Local\Programs\Python\Python313\Lib\site-packages\httpx\_client.py", line 1629, in send
    response = await self._send_handling_auth(
               ^^^^^^^^^^^^^^^^^^^^^^^^^^^^^^^
    ...<4 lines>...
    )
    ^
  File "C:\Users\atikm\AppData\Local\Programs\Python\Python313\Lib\site-packages\httpx\_client.py", line 1657, in _send_handling_auth
    response = await self._send_handling_redirects(
               ^^^^^^^^^^^^^^^^^^^^^^^^^^^^^^^^^^^^
    ...<3 lines>...
    )
    ^
  File "C:\Users\atikm\AppData\Local\Programs\Python\Python313\Lib\site-packages\httpx\_client.py", line 1694, in _send_handling_redirects
    response = await self._send_single_request(request)
               ^^^^^^^^^^^^^^^^^^^^^^^^^^^^^^^^^^^^^^^^
  File "C:\Users\atikm\AppData\Local\Programs\Python\Python313\Lib\site-packages\httpx\_client.py", line 1730, in _send_single_request
    response = await transport.handle_async_request(request)
               ^^^^^^^^^^^^^^^^^^^^^^^^^^^^^^^^^^^^^^^^^^^^^
  File "C:\Users\atikm\AppData\Local\Programs\Python\Python313\Lib\site-packages\httpx\_transports\default.py", line 393, in handle_async_request
    with map_httpcore_exceptions():
         ~~~~~~~~~~~~~~~~~~~~~~~^^
  File "C:\Users\atikm\AppData\Local\Programs\Python\Python313\Lib\contextlib.py", line 162, in __exit__
    self.gen.throw(value)
    ~~~~~~~~~~~~~~^^^^^^^
  File "C:\Users\atikm\AppData\Local\Programs\Python\Python313\Lib\site-packages\httpx\_transports\default.py", line 118, in map_httpcore_exceptions
    raise mapped_exc(message) from exc
httpx.ConnectError: [Errno 11001] getaddrinfo failed

The above exception was the direct cause of the following exception:

Traceback (most recent call last):
  File "C:\Users\atikm\AppData\Local\Programs\Python\Python313\Lib\site-packages\telegram\ext\_updater.py", line 750, in _network_loop_retry
    if not await do_action():
           ^^^^^^^^^^^^^^^^^
  File "C:\Users\atikm\AppData\Local\Programs\Python\Python313\Lib\site-packages\telegram\ext\_updater.py", line 744, in do_action
    return action_cb_task.result()
           ~~~~~~~~~~~~~~~~~~~~~^^
  File "C:\Users\atikm\AppData\Local\Programs\Python\Python313\Lib\asyncio\futures.py", line 199, in result
    raise self._exception.with_traceback(self._exception_tb)
  File "C:\Users\atikm\AppData\Local\Programs\Python\Python313\Lib\asyncio\tasks.py", line 306, in __step_run_and_handle_result
    result = coro.throw(exc)
  File "C:\Users\atikm\AppData\Local\Programs\Python\Python313\Lib\site-packages\telegram\ext\_updater.py", line 371, in polling_action_cb
    updates = await self.bot.get_updates(
              ^^^^^^^^^^^^^^^^^^^^^^^^^^^
    ...<7 lines>...
    )
    ^
  File "C:\Users\atikm\AppData\Local\Programs\Python\Python313\Lib\site-packages\telegram\ext\_extbot.py", line 650, in get_updates
    updates = await super().get_updates(
              ^^^^^^^^^^^^^^^^^^^^^^^^^^
    ...<9 lines>...
    )
    ^
  File "C:\Users\atikm\AppData\Local\Programs\Python\Python313\Lib\site-packages\telegram\_bot.py", line 4480, in get_updates
    await self._post(
    ^^^^^^^^^^^^^^^^^
    ...<7 lines>...
    ),
    ^
  File "C:\Users\atikm\AppData\Local\Programs\Python\Python313\Lib\site-packages\telegram\_bot.py", line 619, in _post
    return await self._do_post(
           ^^^^^^^^^^^^^^^^^^^^
    ...<6 lines>...
    )
    ^
  File "C:\Users\atikm\AppData\Local\Programs\Python\Python313\Lib\site-packages\telegram\ext\_extbot.py", line 354, in _do_post
    return await super()._do_post(
           ^^^^^^^^^^^^^^^^^^^^^^^
    ...<6 lines>...
    )
    ^
  File "C:\Users\atikm\AppData\Local\Programs\Python\Python313\Lib\site-packages\telegram\_bot.py", line 648, in _do_post
    result = await request.post(
             ^^^^^^^^^^^^^^^^^^^
    ...<6 lines>...
    )
    ^
  File "C:\Users\atikm\AppData\Local\Programs\Python\Python313\Lib\site-packages\telegram\request\_baserequest.py", line 202, in post
    result = await self._request_wrapper(
             ^^^^^^^^^^^^^^^^^^^^^^^^^^^^
    ...<7 lines>...
    )
    ^
  File "C:\Users\atikm\AppData\Local\Programs\Python\Python313\Lib\site-packages\telegram\request\_baserequest.py", line 334, in _request_wrapper
    code, payload = await self.do_request(
                    ^^^^^^^^^^^^^^^^^^^^^^
    ...<7 lines>...
    )
    ^
  File "C:\Users\atikm\AppData\Local\Programs\Python\Python313\Lib\site-packages\telegram\request\_httpxrequest.py", line 317, in do_request
    raise NetworkError(f"httpx.{err.__class__.__name__}: {err}") from err
telegram.error.NetworkError: httpx.ConnectError: [Errno 11001] getaddrinfo failed
2025-01-27 00:31:42,253 - telegram.ext.Application - ERROR - No error handlers are registered, logging exception.
Traceback (most recent call last):
  File "C:\Users\atikm\AppData\Local\Programs\Python\Python313\Lib\site-packages\httpx\_transports\default.py", line 101, in map_httpcore_exceptions
    yield
  File "C:\Users\atikm\AppData\Local\Programs\Python\Python313\Lib\site-packages\httpx\_transports\default.py", line 394, in handle_async_request
    resp = await self._pool.handle_async_request(req)
           ^^^^^^^^^^^^^^^^^^^^^^^^^^^^^^^^^^^^^^^^^^
  File "C:\Users\atikm\AppData\Local\Programs\Python\Python313\Lib\site-packages\httpcore\_async\connection_pool.py", line 256, in handle_async_request
    raise exc from None
  File "C:\Users\atikm\AppData\Local\Programs\Python\Python313\Lib\site-packages\httpcore\_async\connection_pool.py", line 236, in handle_async_request
    response = await connection.handle_async_request(
               ^^^^^^^^^^^^^^^^^^^^^^^^^^^^^^^^^^^^^^
        pool_request.request
        ^^^^^^^^^^^^^^^^^^^^
    )
    ^
  File "C:\Users\atikm\AppData\Local\Programs\Python\Python313\Lib\site-packages\httpcore\_async\connection.py", line 101, in handle_async_request
    raise exc
  File "C:\Users\atikm\AppData\Local\Programs\Python\Python313\Lib\site-packages\httpcore\_async\connection.py", line 78, in handle_async_request
    stream = await self._connect(request)
             ^^^^^^^^^^^^^^^^^^^^^^^^^^^^
  File "C:\Users\atikm\AppData\Local\Programs\Python\Python313\Lib\site-packages\httpcore\_async\connection.py", line 124, in _connect
    stream = await self._network_backend.connect_tcp(**kwargs)
             ^^^^^^^^^^^^^^^^^^^^^^^^^^^^^^^^^^^^^^^^^^^^^^^^^
  File "C:\Users\atikm\AppData\Local\Programs\Python\Python313\Lib\site-packages\httpcore\_backends\auto.py", line 31, in connect_tcp
    return await self._backend.connect_tcp(
           ^^^^^^^^^^^^^^^^^^^^^^^^^^^^^^^^
    ...<5 lines>...
    )
    ^
  File "C:\Users\atikm\AppData\Local\Programs\Python\Python313\Lib\site-packages\httpcore\_backends\anyio.py", line 113, in connect_tcp
    with map_exceptions(exc_map):
         ~~~~~~~~~~~~~~^^^^^^^^^
  File "C:\Users\atikm\AppData\Local\Programs\Python\Python313\Lib\contextlib.py", line 162, in __exit__
    self.gen.throw(value)
    ~~~~~~~~~~~~~~^^^^^^^
  File "C:\Users\atikm\AppData\Local\Programs\Python\Python313\Lib\site-packages\httpcore\_exceptions.py", line 14, in map_exceptions
    raise to_exc(exc) from exc
httpcore.ConnectError: [Errno 11001] getaddrinfo failed

The above exception was the direct cause of the following exception:

Traceback (most recent call last):
  File "C:\Users\atikm\AppData\Local\Programs\Python\Python313\Lib\site-packages\telegram\request\_httpxrequest.py", line 293, in do_request
    res = await self._client.request(
          ^^^^^^^^^^^^^^^^^^^^^^^^^^^
    ...<6 lines>...
    )
    ^
  File "C:\Users\atikm\AppData\Local\Programs\Python\Python313\Lib\site-packages\httpx\_client.py", line 1540, in request
    return await self.send(request, auth=auth, follow_redirects=follow_redirects)
           ^^^^^^^^^^^^^^^^^^^^^^^^^^^^^^^^^^^^^^^^^^^^^^^^^^^^^^^^^^^^^^^^^^^^^^
  File "C:\Users\atikm\AppData\Local\Programs\Python\Python313\Lib\site-packages\httpx\_client.py", line 1629, in send
    response = await self._send_handling_auth(
               ^^^^^^^^^^^^^^^^^^^^^^^^^^^^^^^
    ...<4 lines>...
    )
    ^
  File "C:\Users\atikm\AppData\Local\Programs\Python\Python313\Lib\site-packages\httpx\_client.py", line 1657, in _send_handling_auth
    response = await self._send_handling_redirects(
               ^^^^^^^^^^^^^^^^^^^^^^^^^^^^^^^^^^^^
    ...<3 lines>...
    )
    ^
  File "C:\Users\atikm\AppData\Local\Programs\Python\Python313\Lib\site-packages\httpx\_client.py", line 1694, in _send_handling_redirects
    response = await self._send_single_request(request)
               ^^^^^^^^^^^^^^^^^^^^^^^^^^^^^^^^^^^^^^^^
  File "C:\Users\atikm\AppData\Local\Programs\Python\Python313\Lib\site-packages\httpx\_client.py", line 1730, in _send_single_request
    response = await transport.handle_async_request(request)
               ^^^^^^^^^^^^^^^^^^^^^^^^^^^^^^^^^^^^^^^^^^^^^
  File "C:\Users\atikm\AppData\Local\Programs\Python\Python313\Lib\site-packages\httpx\_transports\default.py", line 393, in handle_async_request
    with map_httpcore_exceptions():
         ~~~~~~~~~~~~~~~~~~~~~~~^^
  File "C:\Users\atikm\AppData\Local\Programs\Python\Python313\Lib\contextlib.py", line 162, in __exit__
    self.gen.throw(value)
    ~~~~~~~~~~~~~~^^^^^^^
  File "C:\Users\atikm\AppData\Local\Programs\Python\Python313\Lib\site-packages\httpx\_transports\default.py", line 118, in map_httpcore_exceptions
    raise mapped_exc(message) from exc
httpx.ConnectError: [Errno 11001] getaddrinfo failed

The above exception was the direct cause of the following exception:

Traceback (most recent call last):
  File "C:\Users\atikm\AppData\Local\Programs\Python\Python313\Lib\site-packages\telegram\ext\_updater.py", line 750, in _network_loop_retry
    if not await do_action():
           ^^^^^^^^^^^^^^^^^
  File "C:\Users\atikm\AppData\Local\Programs\Python\Python313\Lib\site-packages\telegram\ext\_updater.py", line 744, in do_action
    return action_cb_task.result()
           ~~~~~~~~~~~~~~~~~~~~~^^
  File "C:\Users\atikm\AppData\Local\Programs\Python\Python313\Lib\asyncio\futures.py", line 199, in result
    raise self._exception.with_traceback(self._exception_tb)
  File "C:\Users\atikm\AppData\Local\Programs\Python\Python313\Lib\asyncio\tasks.py", line 306, in __step_run_and_handle_result
    result = coro.throw(exc)
  File "C:\Users\atikm\AppData\Local\Programs\Python\Python313\Lib\site-packages\telegram\ext\_updater.py", line 371, in polling_action_cb
    updates = await self.bot.get_updates(
              ^^^^^^^^^^^^^^^^^^^^^^^^^^^
    ...<7 lines>...
    )
    ^
  File "C:\Users\atikm\AppData\Local\Programs\Python\Python313\Lib\site-packages\telegram\ext\_extbot.py", line 650, in get_updates
    updates = await super().get_updates(
              ^^^^^^^^^^^^^^^^^^^^^^^^^^
    ...<9 lines>...
    )
    ^
  File "C:\Users\atikm\AppData\Local\Programs\Python\Python313\Lib\site-packages\telegram\_bot.py", line 4480, in get_updates
    await self._post(
    ^^^^^^^^^^^^^^^^^
    ...<7 lines>...
    ),
    ^
  File "C:\Users\atikm\AppData\Local\Programs\Python\Python313\Lib\site-packages\telegram\_bot.py", line 619, in _post
    return await self._do_post(
           ^^^^^^^^^^^^^^^^^^^^
    ...<6 lines>...
    )
    ^
  File "C:\Users\atikm\AppData\Local\Programs\Python\Python313\Lib\site-packages\telegram\ext\_extbot.py", line 354, in _do_post
    return await super()._do_post(
           ^^^^^^^^^^^^^^^^^^^^^^^
    ...<6 lines>...
    )
    ^
  File "C:\Users\atikm\AppData\Local\Programs\Python\Python313\Lib\site-packages\telegram\_bot.py", line 648, in _do_post
    result = await request.post(
             ^^^^^^^^^^^^^^^^^^^
    ...<6 lines>...
    )
    ^
  File "C:\Users\atikm\AppData\Local\Programs\Python\Python313\Lib\site-packages\telegram\request\_baserequest.py", line 202, in post
    result = await self._request_wrapper(
             ^^^^^^^^^^^^^^^^^^^^^^^^^^^^
    ...<7 lines>...
    )
    ^
  File "C:\Users\atikm\AppData\Local\Programs\Python\Python313\Lib\site-packages\telegram\request\_baserequest.py", line 334, in _request_wrapper
    code, payload = await self.do_request(
                    ^^^^^^^^^^^^^^^^^^^^^^
    ...<7 lines>...
    )
    ^
  File "C:\Users\atikm\AppData\Local\Programs\Python\Python313\Lib\site-packages\telegram\request\_httpxrequest.py", line 317, in do_request
    raise NetworkError(f"httpx.{err.__class__.__name__}: {err}") from err
telegram.error.NetworkError: httpx.ConnectError: [Errno 11001] getaddrinfo failed
2025-01-27 00:31:43,764 - telegram.ext.Application - ERROR - No error handlers are registered, logging exception.
Traceback (most recent call last):
  File "C:\Users\atikm\AppData\Local\Programs\Python\Python313\Lib\site-packages\httpx\_transports\default.py", line 101, in map_httpcore_exceptions
    yield
  File "C:\Users\atikm\AppData\Local\Programs\Python\Python313\Lib\site-packages\httpx\_transports\default.py", line 394, in handle_async_request
    resp = await self._pool.handle_async_request(req)
           ^^^^^^^^^^^^^^^^^^^^^^^^^^^^^^^^^^^^^^^^^^
  File "C:\Users\atikm\AppData\Local\Programs\Python\Python313\Lib\site-packages\httpcore\_async\connection_pool.py", line 256, in handle_async_request
    raise exc from None
  File "C:\Users\atikm\AppData\Local\Programs\Python\Python313\Lib\site-packages\httpcore\_async\connection_pool.py", line 236, in handle_async_request
    response = await connection.handle_async_request(
               ^^^^^^^^^^^^^^^^^^^^^^^^^^^^^^^^^^^^^^
        pool_request.request
        ^^^^^^^^^^^^^^^^^^^^
    )
    ^
  File "C:\Users\atikm\AppData\Local\Programs\Python\Python313\Lib\site-packages\httpcore\_async\connection.py", line 101, in handle_async_request
    raise exc
  File "C:\Users\atikm\AppData\Local\Programs\Python\Python313\Lib\site-packages\httpcore\_async\connection.py", line 78, in handle_async_request
    stream = await self._connect(request)
             ^^^^^^^^^^^^^^^^^^^^^^^^^^^^
  File "C:\Users\atikm\AppData\Local\Programs\Python\Python313\Lib\site-packages\httpcore\_async\connection.py", line 124, in _connect
    stream = await self._network_backend.connect_tcp(**kwargs)
             ^^^^^^^^^^^^^^^^^^^^^^^^^^^^^^^^^^^^^^^^^^^^^^^^^
  File "C:\Users\atikm\AppData\Local\Programs\Python\Python313\Lib\site-packages\httpcore\_backends\auto.py", line 31, in connect_tcp
    return await self._backend.connect_tcp(
           ^^^^^^^^^^^^^^^^^^^^^^^^^^^^^^^^
    ...<5 lines>...
    )
    ^
  File "C:\Users\atikm\AppData\Local\Programs\Python\Python313\Lib\site-packages\httpcore\_backends\anyio.py", line 113, in connect_tcp
    with map_exceptions(exc_map):
         ~~~~~~~~~~~~~~^^^^^^^^^
  File "C:\Users\atikm\AppData\Local\Programs\Python\Python313\Lib\contextlib.py", line 162, in __exit__
    self.gen.throw(value)
    ~~~~~~~~~~~~~~^^^^^^^
  File "C:\Users\atikm\AppData\Local\Programs\Python\Python313\Lib\site-packages\httpcore\_exceptions.py", line 14, in map_exceptions
    raise to_exc(exc) from exc
httpcore.ConnectError: [Errno 11001] getaddrinfo failed

The above exception was the direct cause of the following exception:

Traceback (most recent call last):
  File "C:\Users\atikm\AppData\Local\Programs\Python\Python313\Lib\site-packages\telegram\request\_httpxrequest.py", line 293, in do_request
    res = await self._client.request(
          ^^^^^^^^^^^^^^^^^^^^^^^^^^^
    ...<6 lines>...
    )
    ^
  File "C:\Users\atikm\AppData\Local\Programs\Python\Python313\Lib\site-packages\httpx\_client.py", line 1540, in request
    return await self.send(request, auth=auth, follow_redirects=follow_redirects)
           ^^^^^^^^^^^^^^^^^^^^^^^^^^^^^^^^^^^^^^^^^^^^^^^^^^^^^^^^^^^^^^^^^^^^^^
  File "C:\Users\atikm\AppData\Local\Programs\Python\Python313\Lib\site-packages\httpx\_client.py", line 1629, in send
    response = await self._send_handling_auth(
               ^^^^^^^^^^^^^^^^^^^^^^^^^^^^^^^
    ...<4 lines>...
    )
    ^
  File "C:\Users\atikm\AppData\Local\Programs\Python\Python313\Lib\site-packages\httpx\_client.py", line 1657, in _send_handling_auth
    response = await self._send_handling_redirects(
               ^^^^^^^^^^^^^^^^^^^^^^^^^^^^^^^^^^^^
    ...<3 lines>...
    )
    ^
  File "C:\Users\atikm\AppData\Local\Programs\Python\Python313\Lib\site-packages\httpx\_client.py", line 1694, in _send_handling_redirects
    response = await self._send_single_request(request)
               ^^^^^^^^^^^^^^^^^^^^^^^^^^^^^^^^^^^^^^^^
  File "C:\Users\atikm\AppData\Local\Programs\Python\Python313\Lib\site-packages\httpx\_client.py", line 1730, in _send_single_request
    response = await transport.handle_async_request(request)
               ^^^^^^^^^^^^^^^^^^^^^^^^^^^^^^^^^^^^^^^^^^^^^
  File "C:\Users\atikm\AppData\Local\Programs\Python\Python313\Lib\site-packages\httpx\_transports\default.py", line 393, in handle_async_request
    with map_httpcore_exceptions():
         ~~~~~~~~~~~~~~~~~~~~~~~^^
  File "C:\Users\atikm\AppData\Local\Programs\Python\Python313\Lib\contextlib.py", line 162, in __exit__
    self.gen.throw(value)
    ~~~~~~~~~~~~~~^^^^^^^
  File "C:\Users\atikm\AppData\Local\Programs\Python\Python313\Lib\site-packages\httpx\_transports\default.py", line 118, in map_httpcore_exceptions
    raise mapped_exc(message) from exc
httpx.ConnectError: [Errno 11001] getaddrinfo failed

The above exception was the direct cause of the following exception:

Traceback (most recent call last):
  File "C:\Users\atikm\AppData\Local\Programs\Python\Python313\Lib\site-packages\telegram\ext\_updater.py", line 750, in _network_loop_retry
    if not await do_action():
           ^^^^^^^^^^^^^^^^^
  File "C:\Users\atikm\AppData\Local\Programs\Python\Python313\Lib\site-packages\telegram\ext\_updater.py", line 744, in do_action
    return action_cb_task.result()
           ~~~~~~~~~~~~~~~~~~~~~^^
  File "C:\Users\atikm\AppData\Local\Programs\Python\Python313\Lib\asyncio\futures.py", line 199, in result
    raise self._exception.with_traceback(self._exception_tb)
  File "C:\Users\atikm\AppData\Local\Programs\Python\Python313\Lib\asyncio\tasks.py", line 306, in __step_run_and_handle_result
    result = coro.throw(exc)
  File "C:\Users\atikm\AppData\Local\Programs\Python\Python313\Lib\site-packages\telegram\ext\_updater.py", line 371, in polling_action_cb
    updates = await self.bot.get_updates(
              ^^^^^^^^^^^^^^^^^^^^^^^^^^^
    ...<7 lines>...
    )
    ^
  File "C:\Users\atikm\AppData\Local\Programs\Python\Python313\Lib\site-packages\telegram\ext\_extbot.py", line 650, in get_updates
    updates = await super().get_updates(
              ^^^^^^^^^^^^^^^^^^^^^^^^^^
    ...<9 lines>...
    )
    ^
  File "C:\Users\atikm\AppData\Local\Programs\Python\Python313\Lib\site-packages\telegram\_bot.py", line 4480, in get_updates
    await self._post(
    ^^^^^^^^^^^^^^^^^
    ...<7 lines>...
    ),
    ^
  File "C:\Users\atikm\AppData\Local\Programs\Python\Python313\Lib\site-packages\telegram\_bot.py", line 619, in _post
    return await self._do_post(
           ^^^^^^^^^^^^^^^^^^^^
    ...<6 lines>...
    )
    ^
  File "C:\Users\atikm\AppData\Local\Programs\Python\Python313\Lib\site-packages\telegram\ext\_extbot.py", line 354, in _do_post
    return await super()._do_post(
           ^^^^^^^^^^^^^^^^^^^^^^^
    ...<6 lines>...
    )
    ^
  File "C:\Users\atikm\AppData\Local\Programs\Python\Python313\Lib\site-packages\telegram\_bot.py", line 648, in _do_post
    result = await request.post(
             ^^^^^^^^^^^^^^^^^^^
    ...<6 lines>...
    )
    ^
  File "C:\Users\atikm\AppData\Local\Programs\Python\Python313\Lib\site-packages\telegram\request\_baserequest.py", line 202, in post
    result = await self._request_wrapper(
             ^^^^^^^^^^^^^^^^^^^^^^^^^^^^
    ...<7 lines>...
    )
    ^
  File "C:\Users\atikm\AppData\Local\Programs\Python\Python313\Lib\site-packages\telegram\request\_baserequest.py", line 334, in _request_wrapper
    code, payload = await self.do_request(
                    ^^^^^^^^^^^^^^^^^^^^^^
    ...<7 lines>...
    )
    ^
  File "C:\Users\atikm\AppData\Local\Programs\Python\Python313\Lib\site-packages\telegram\request\_httpxrequest.py", line 317, in do_request
    raise NetworkError(f"httpx.{err.__class__.__name__}: {err}") from err
telegram.error.NetworkError: httpx.ConnectError: [Errno 11001] getaddrinfo failed
2025-01-27 00:31:46,021 - telegram.ext.Application - ERROR - No error handlers are registered, logging exception.
Traceback (most recent call last):
  File "C:\Users\atikm\AppData\Local\Programs\Python\Python313\Lib\site-packages\httpx\_transports\default.py", line 101, in map_httpcore_exceptions
    yield
  File "C:\Users\atikm\AppData\Local\Programs\Python\Python313\Lib\site-packages\httpx\_transports\default.py", line 394, in handle_async_request
    resp = await self._pool.handle_async_request(req)
           ^^^^^^^^^^^^^^^^^^^^^^^^^^^^^^^^^^^^^^^^^^
  File "C:\Users\atikm\AppData\Local\Programs\Python\Python313\Lib\site-packages\httpcore\_async\connection_pool.py", line 256, in handle_async_request
    raise exc from None
  File "C:\Users\atikm\AppData\Local\Programs\Python\Python313\Lib\site-packages\httpcore\_async\connection_pool.py", line 236, in handle_async_request
    response = await connection.handle_async_request(
               ^^^^^^^^^^^^^^^^^^^^^^^^^^^^^^^^^^^^^^
        pool_request.request
        ^^^^^^^^^^^^^^^^^^^^
    )
    ^
  File "C:\Users\atikm\AppData\Local\Programs\Python\Python313\Lib\site-packages\httpcore\_async\connection.py", line 101, in handle_async_request
    raise exc
  File "C:\Users\atikm\AppData\Local\Programs\Python\Python313\Lib\site-packages\httpcore\_async\connection.py", line 78, in handle_async_request
    stream = await self._connect(request)
             ^^^^^^^^^^^^^^^^^^^^^^^^^^^^
  File "C:\Users\atikm\AppData\Local\Programs\Python\Python313\Lib\site-packages\httpcore\_async\connection.py", line 124, in _connect
    stream = await self._network_backend.connect_tcp(**kwargs)
             ^^^^^^^^^^^^^^^^^^^^^^^^^^^^^^^^^^^^^^^^^^^^^^^^^
  File "C:\Users\atikm\AppData\Local\Programs\Python\Python313\Lib\site-packages\httpcore\_backends\auto.py", line 31, in connect_tcp
    return await self._backend.connect_tcp(
           ^^^^^^^^^^^^^^^^^^^^^^^^^^^^^^^^
    ...<5 lines>...
    )
    ^
  File "C:\Users\atikm\AppData\Local\Programs\Python\Python313\Lib\site-packages\httpcore\_backends\anyio.py", line 113, in connect_tcp
    with map_exceptions(exc_map):
         ~~~~~~~~~~~~~~^^^^^^^^^
  File "C:\Users\atikm\AppData\Local\Programs\Python\Python313\Lib\contextlib.py", line 162, in __exit__
    self.gen.throw(value)
    ~~~~~~~~~~~~~~^^^^^^^
  File "C:\Users\atikm\AppData\Local\Programs\Python\Python313\Lib\site-packages\httpcore\_exceptions.py", line 14, in map_exceptions
    raise to_exc(exc) from exc
httpcore.ConnectError: [Errno 11001] getaddrinfo failed

The above exception was the direct cause of the following exception:

Traceback (most recent call last):
  File "C:\Users\atikm\AppData\Local\Programs\Python\Python313\Lib\site-packages\telegram\request\_httpxrequest.py", line 293, in do_request
    res = await self._client.request(
          ^^^^^^^^^^^^^^^^^^^^^^^^^^^
    ...<6 lines>...
    )
    ^
  File "C:\Users\atikm\AppData\Local\Programs\Python\Python313\Lib\site-packages\httpx\_client.py", line 1540, in request
    return await self.send(request, auth=auth, follow_redirects=follow_redirects)
           ^^^^^^^^^^^^^^^^^^^^^^^^^^^^^^^^^^^^^^^^^^^^^^^^^^^^^^^^^^^^^^^^^^^^^^
  File "C:\Users\atikm\AppData\Local\Programs\Python\Python313\Lib\site-packages\httpx\_client.py", line 1629, in send
    response = await self._send_handling_auth(
               ^^^^^^^^^^^^^^^^^^^^^^^^^^^^^^^
    ...<4 lines>...
    )
    ^
  File "C:\Users\atikm\AppData\Local\Programs\Python\Python313\Lib\site-packages\httpx\_client.py", line 1657, in _send_handling_auth
    response = await self._send_handling_redirects(
               ^^^^^^^^^^^^^^^^^^^^^^^^^^^^^^^^^^^^
    ...<3 lines>...
    )
    ^
  File "C:\Users\atikm\AppData\Local\Programs\Python\Python313\Lib\site-packages\httpx\_client.py", line 1694, in _send_handling_redirects
    response = await self._send_single_request(request)
               ^^^^^^^^^^^^^^^^^^^^^^^^^^^^^^^^^^^^^^^^
  File "C:\Users\atikm\AppData\Local\Programs\Python\Python313\Lib\site-packages\httpx\_client.py", line 1730, in _send_single_request
    response = await transport.handle_async_request(request)
               ^^^^^^^^^^^^^^^^^^^^^^^^^^^^^^^^^^^^^^^^^^^^^
  File "C:\Users\atikm\AppData\Local\Programs\Python\Python313\Lib\site-packages\httpx\_transports\default.py", line 393, in handle_async_request
    with map_httpcore_exceptions():
         ~~~~~~~~~~~~~~~~~~~~~~~^^
  File "C:\Users\atikm\AppData\Local\Programs\Python\Python313\Lib\contextlib.py", line 162, in __exit__
    self.gen.throw(value)
    ~~~~~~~~~~~~~~^^^^^^^
  File "C:\Users\atikm\AppData\Local\Programs\Python\Python313\Lib\site-packages\httpx\_transports\default.py", line 118, in map_httpcore_exceptions
    raise mapped_exc(message) from exc
httpx.ConnectError: [Errno 11001] getaddrinfo failed

The above exception was the direct cause of the following exception:

Traceback (most recent call last):
  File "C:\Users\atikm\AppData\Local\Programs\Python\Python313\Lib\site-packages\telegram\ext\_updater.py", line 750, in _network_loop_retry
    if not await do_action():
           ^^^^^^^^^^^^^^^^^
  File "C:\Users\atikm\AppData\Local\Programs\Python\Python313\Lib\site-packages\telegram\ext\_updater.py", line 744, in do_action
    return action_cb_task.result()
           ~~~~~~~~~~~~~~~~~~~~~^^
  File "C:\Users\atikm\AppData\Local\Programs\Python\Python313\Lib\asyncio\futures.py", line 199, in result
    raise self._exception.with_traceback(self._exception_tb)
  File "C:\Users\atikm\AppData\Local\Programs\Python\Python313\Lib\asyncio\tasks.py", line 306, in __step_run_and_handle_result
    result = coro.throw(exc)
  File "C:\Users\atikm\AppData\Local\Programs\Python\Python313\Lib\site-packages\telegram\ext\_updater.py", line 371, in polling_action_cb
    updates = await self.bot.get_updates(
              ^^^^^^^^^^^^^^^^^^^^^^^^^^^
    ...<7 lines>...
    )
    ^
  File "C:\Users\atikm\AppData\Local\Programs\Python\Python313\Lib\site-packages\telegram\ext\_extbot.py", line 650, in get_updates
    updates = await super().get_updates(
              ^^^^^^^^^^^^^^^^^^^^^^^^^^
    ...<9 lines>...
    )
    ^
  File "C:\Users\atikm\AppData\Local\Programs\Python\Python313\Lib\site-packages\telegram\_bot.py", line 4480, in get_updates
    await self._post(
    ^^^^^^^^^^^^^^^^^
    ...<7 lines>...
    ),
    ^
  File "C:\Users\atikm\AppData\Local\Programs\Python\Python313\Lib\site-packages\telegram\_bot.py", line 619, in _post
    return await self._do_post(
           ^^^^^^^^^^^^^^^^^^^^
    ...<6 lines>...
    )
    ^
  File "C:\Users\atikm\AppData\Local\Programs\Python\Python313\Lib\site-packages\telegram\ext\_extbot.py", line 354, in _do_post
    return await super()._do_post(
           ^^^^^^^^^^^^^^^^^^^^^^^
    ...<6 lines>...
    )
    ^
  File "C:\Users\atikm\AppData\Local\Programs\Python\Python313\Lib\site-packages\telegram\_bot.py", line 648, in _do_post
    result = await request.post(
             ^^^^^^^^^^^^^^^^^^^
    ...<6 lines>...
    )
    ^
  File "C:\Users\atikm\AppData\Local\Programs\Python\Python313\Lib\site-packages\telegram\request\_baserequest.py", line 202, in post
    result = await self._request_wrapper(
             ^^^^^^^^^^^^^^^^^^^^^^^^^^^^
    ...<7 lines>...
    )
    ^
  File "C:\Users\atikm\AppData\Local\Programs\Python\Python313\Lib\site-packages\telegram\request\_baserequest.py", line 334, in _request_wrapper
    code, payload = await self.do_request(
                    ^^^^^^^^^^^^^^^^^^^^^^
    ...<7 lines>...
    )
    ^
  File "C:\Users\atikm\AppData\Local\Programs\Python\Python313\Lib\site-packages\telegram\request\_httpxrequest.py", line 317, in do_request
    raise NetworkError(f"httpx.{err.__class__.__name__}: {err}") from err
telegram.error.NetworkError: httpx.ConnectError: [Errno 11001] getaddrinfo failed
2025-01-27 00:31:49,410 - telegram.ext.Application - ERROR - No error handlers are registered, logging exception.
Traceback (most recent call last):
  File "C:\Users\atikm\AppData\Local\Programs\Python\Python313\Lib\site-packages\httpx\_transports\default.py", line 101, in map_httpcore_exceptions
    yield
  File "C:\Users\atikm\AppData\Local\Programs\Python\Python313\Lib\site-packages\httpx\_transports\default.py", line 394, in handle_async_request
    resp = await self._pool.handle_async_request(req)
           ^^^^^^^^^^^^^^^^^^^^^^^^^^^^^^^^^^^^^^^^^^
  File "C:\Users\atikm\AppData\Local\Programs\Python\Python313\Lib\site-packages\httpcore\_async\connection_pool.py", line 256, in handle_async_request
    raise exc from None
  File "C:\Users\atikm\AppData\Local\Programs\Python\Python313\Lib\site-packages\httpcore\_async\connection_pool.py", line 236, in handle_async_request
    response = await connection.handle_async_request(
               ^^^^^^^^^^^^^^^^^^^^^^^^^^^^^^^^^^^^^^
        pool_request.request
        ^^^^^^^^^^^^^^^^^^^^
    )
    ^
  File "C:\Users\atikm\AppData\Local\Programs\Python\Python313\Lib\site-packages\httpcore\_async\connection.py", line 101, in handle_async_request
    raise exc
  File "C:\Users\atikm\AppData\Local\Programs\Python\Python313\Lib\site-packages\httpcore\_async\connection.py", line 78, in handle_async_request
    stream = await self._connect(request)
             ^^^^^^^^^^^^^^^^^^^^^^^^^^^^
  File "C:\Users\atikm\AppData\Local\Programs\Python\Python313\Lib\site-packages\httpcore\_async\connection.py", line 124, in _connect
    stream = await self._network_backend.connect_tcp(**kwargs)
             ^^^^^^^^^^^^^^^^^^^^^^^^^^^^^^^^^^^^^^^^^^^^^^^^^
  File "C:\Users\atikm\AppData\Local\Programs\Python\Python313\Lib\site-packages\httpcore\_backends\auto.py", line 31, in connect_tcp
    return await self._backend.connect_tcp(
           ^^^^^^^^^^^^^^^^^^^^^^^^^^^^^^^^
    ...<5 lines>...
    )
    ^
  File "C:\Users\atikm\AppData\Local\Programs\Python\Python313\Lib\site-packages\httpcore\_backends\anyio.py", line 113, in connect_tcp
    with map_exceptions(exc_map):
         ~~~~~~~~~~~~~~^^^^^^^^^
  File "C:\Users\atikm\AppData\Local\Programs\Python\Python313\Lib\contextlib.py", line 162, in __exit__
    self.gen.throw(value)
    ~~~~~~~~~~~~~~^^^^^^^
  File "C:\Users\atikm\AppData\Local\Programs\Python\Python313\Lib\site-packages\httpcore\_exceptions.py", line 14, in map_exceptions
    raise to_exc(exc) from exc
httpcore.ConnectError: [Errno 11001] getaddrinfo failed

The above exception was the direct cause of the following exception:

Traceback (most recent call last):
  File "C:\Users\atikm\AppData\Local\Programs\Python\Python313\Lib\site-packages\telegram\request\_httpxrequest.py", line 293, in do_request
    res = await self._client.request(
          ^^^^^^^^^^^^^^^^^^^^^^^^^^^
    ...<6 lines>...
    )
    ^
  File "C:\Users\atikm\AppData\Local\Programs\Python\Python313\Lib\site-packages\httpx\_client.py", line 1540, in request
    return await self.send(request, auth=auth, follow_redirects=follow_redirects)
           ^^^^^^^^^^^^^^^^^^^^^^^^^^^^^^^^^^^^^^^^^^^^^^^^^^^^^^^^^^^^^^^^^^^^^^
  File "C:\Users\atikm\AppData\Local\Programs\Python\Python313\Lib\site-packages\httpx\_client.py", line 1629, in send
    response = await self._send_handling_auth(
               ^^^^^^^^^^^^^^^^^^^^^^^^^^^^^^^
    ...<4 lines>...
    )
    ^
  File "C:\Users\atikm\AppData\Local\Programs\Python\Python313\Lib\site-packages\httpx\_client.py", line 1657, in _send_handling_auth
    response = await self._send_handling_redirects(
               ^^^^^^^^^^^^^^^^^^^^^^^^^^^^^^^^^^^^
    ...<3 lines>...
    )
    ^
  File "C:\Users\atikm\AppData\Local\Programs\Python\Python313\Lib\site-packages\httpx\_client.py", line 1694, in _send_handling_redirects
    response = await self._send_single_request(request)
               ^^^^^^^^^^^^^^^^^^^^^^^^^^^^^^^^^^^^^^^^
  File "C:\Users\atikm\AppData\Local\Programs\Python\Python313\Lib\site-packages\httpx\_client.py", line 1730, in _send_single_request
    response = await transport.handle_async_request(request)
               ^^^^^^^^^^^^^^^^^^^^^^^^^^^^^^^^^^^^^^^^^^^^^
  File "C:\Users\atikm\AppData\Local\Programs\Python\Python313\Lib\site-packages\httpx\_transports\default.py", line 393, in handle_async_request
    with map_httpcore_exceptions():
         ~~~~~~~~~~~~~~~~~~~~~~~^^
  File "C:\Users\atikm\AppData\Local\Programs\Python\Python313\Lib\contextlib.py", line 162, in __exit__
    self.gen.throw(value)
    ~~~~~~~~~~~~~~^^^^^^^
  File "C:\Users\atikm\AppData\Local\Programs\Python\Python313\Lib\site-packages\httpx\_transports\default.py", line 118, in map_httpcore_exceptions
    raise mapped_exc(message) from exc
httpx.ConnectError: [Errno 11001] getaddrinfo failed

The above exception was the direct cause of the following exception:

Traceback (most recent call last):
  File "C:\Users\atikm\AppData\Local\Programs\Python\Python313\Lib\site-packages\telegram\ext\_updater.py", line 750, in _network_loop_retry
    if not await do_action():
           ^^^^^^^^^^^^^^^^^
  File "C:\Users\atikm\AppData\Local\Programs\Python\Python313\Lib\site-packages\telegram\ext\_updater.py", line 744, in do_action
    return action_cb_task.result()
           ~~~~~~~~~~~~~~~~~~~~~^^
  File "C:\Users\atikm\AppData\Local\Programs\Python\Python313\Lib\asyncio\futures.py", line 199, in result
    raise self._exception.with_traceback(self._exception_tb)
  File "C:\Users\atikm\AppData\Local\Programs\Python\Python313\Lib\asyncio\tasks.py", line 306, in __step_run_and_handle_result
    result = coro.throw(exc)
  File "C:\Users\atikm\AppData\Local\Programs\Python\Python313\Lib\site-packages\telegram\ext\_updater.py", line 371, in polling_action_cb
    updates = await self.bot.get_updates(
              ^^^^^^^^^^^^^^^^^^^^^^^^^^^
    ...<7 lines>...
    )
    ^
  File "C:\Users\atikm\AppData\Local\Programs\Python\Python313\Lib\site-packages\telegram\ext\_extbot.py", line 650, in get_updates
    updates = await super().get_updates(
              ^^^^^^^^^^^^^^^^^^^^^^^^^^
    ...<9 lines>...
    )
    ^
  File "C:\Users\atikm\AppData\Local\Programs\Python\Python313\Lib\site-packages\telegram\_bot.py", line 4480, in get_updates
    await self._post(
    ^^^^^^^^^^^^^^^^^
    ...<7 lines>...
    ),
    ^
  File "C:\Users\atikm\AppData\Local\Programs\Python\Python313\Lib\site-packages\telegram\_bot.py", line 619, in _post
    return await self._do_post(
           ^^^^^^^^^^^^^^^^^^^^
    ...<6 lines>...
    )
    ^
  File "C:\Users\atikm\AppData\Local\Programs\Python\Python313\Lib\site-packages\telegram\ext\_extbot.py", line 354, in _do_post
    return await super()._do_post(
           ^^^^^^^^^^^^^^^^^^^^^^^
    ...<6 lines>...
    )
    ^
  File "C:\Users\atikm\AppData\Local\Programs\Python\Python313\Lib\site-packages\telegram\_bot.py", line 648, in _do_post
    result = await request.post(
             ^^^^^^^^^^^^^^^^^^^
    ...<6 lines>...
    )
    ^
  File "C:\Users\atikm\AppData\Local\Programs\Python\Python313\Lib\site-packages\telegram\request\_baserequest.py", line 202, in post
    result = await self._request_wrapper(
             ^^^^^^^^^^^^^^^^^^^^^^^^^^^^
    ...<7 lines>...
    )
    ^
  File "C:\Users\atikm\AppData\Local\Programs\Python\Python313\Lib\site-packages\telegram\request\_baserequest.py", line 334, in _request_wrapper
    code, payload = await self.do_request(
                    ^^^^^^^^^^^^^^^^^^^^^^
    ...<7 lines>...
    )
    ^
  File "C:\Users\atikm\AppData\Local\Programs\Python\Python313\Lib\site-packages\telegram\request\_httpxrequest.py", line 317, in do_request
    raise NetworkError(f"httpx.{err.__class__.__name__}: {err}") from err
telegram.error.NetworkError: httpx.ConnectError: [Errno 11001] getaddrinfo failed
2025-01-27 00:31:54,479 - telegram.ext.Application - ERROR - No error handlers are registered, logging exception.
Traceback (most recent call last):
  File "C:\Users\atikm\AppData\Local\Programs\Python\Python313\Lib\site-packages\httpx\_transports\default.py", line 101, in map_httpcore_exceptions
    yield
  File "C:\Users\atikm\AppData\Local\Programs\Python\Python313\Lib\site-packages\httpx\_transports\default.py", line 394, in handle_async_request
    resp = await self._pool.handle_async_request(req)
           ^^^^^^^^^^^^^^^^^^^^^^^^^^^^^^^^^^^^^^^^^^
  File "C:\Users\atikm\AppData\Local\Programs\Python\Python313\Lib\site-packages\httpcore\_async\connection_pool.py", line 256, in handle_async_request
    raise exc from None
  File "C:\Users\atikm\AppData\Local\Programs\Python\Python313\Lib\site-packages\httpcore\_async\connection_pool.py", line 236, in handle_async_request
    response = await connection.handle_async_request(
               ^^^^^^^^^^^^^^^^^^^^^^^^^^^^^^^^^^^^^^
        pool_request.request
        ^^^^^^^^^^^^^^^^^^^^
    )
    ^
  File "C:\Users\atikm\AppData\Local\Programs\Python\Python313\Lib\site-packages\httpcore\_async\connection.py", line 101, in handle_async_request
    raise exc
  File "C:\Users\atikm\AppData\Local\Programs\Python\Python313\Lib\site-packages\httpcore\_async\connection.py", line 78, in handle_async_request
    stream = await self._connect(request)
             ^^^^^^^^^^^^^^^^^^^^^^^^^^^^
  File "C:\Users\atikm\AppData\Local\Programs\Python\Python313\Lib\site-packages\httpcore\_async\connection.py", line 124, in _connect
    stream = await self._network_backend.connect_tcp(**kwargs)
             ^^^^^^^^^^^^^^^^^^^^^^^^^^^^^^^^^^^^^^^^^^^^^^^^^
  File "C:\Users\atikm\AppData\Local\Programs\Python\Python313\Lib\site-packages\httpcore\_backends\auto.py", line 31, in connect_tcp
    return await self._backend.connect_tcp(
           ^^^^^^^^^^^^^^^^^^^^^^^^^^^^^^^^
    ...<5 lines>...
    )
    ^
  File "C:\Users\atikm\AppData\Local\Programs\Python\Python313\Lib\site-packages\httpcore\_backends\anyio.py", line 113, in connect_tcp
    with map_exceptions(exc_map):
         ~~~~~~~~~~~~~~^^^^^^^^^
  File "C:\Users\atikm\AppData\Local\Programs\Python\Python313\Lib\contextlib.py", line 162, in __exit__
    self.gen.throw(value)
    ~~~~~~~~~~~~~~^^^^^^^
  File "C:\Users\atikm\AppData\Local\Programs\Python\Python313\Lib\site-packages\httpcore\_exceptions.py", line 14, in map_exceptions
    raise to_exc(exc) from exc
httpcore.ConnectError: [Errno 11001] getaddrinfo failed

The above exception was the direct cause of the following exception:

Traceback (most recent call last):
  File "C:\Users\atikm\AppData\Local\Programs\Python\Python313\Lib\site-packages\telegram\request\_httpxrequest.py", line 293, in do_request
    res = await self._client.request(
          ^^^^^^^^^^^^^^^^^^^^^^^^^^^
    ...<6 lines>...
    )
    ^
  File "C:\Users\atikm\AppData\Local\Programs\Python\Python313\Lib\site-packages\httpx\_client.py", line 1540, in request
    return await self.send(request, auth=auth, follow_redirects=follow_redirects)
           ^^^^^^^^^^^^^^^^^^^^^^^^^^^^^^^^^^^^^^^^^^^^^^^^^^^^^^^^^^^^^^^^^^^^^^
  File "C:\Users\atikm\AppData\Local\Programs\Python\Python313\Lib\site-packages\httpx\_client.py", line 1629, in send
    response = await self._send_handling_auth(
               ^^^^^^^^^^^^^^^^^^^^^^^^^^^^^^^
    ...<4 lines>...
    )
    ^
  File "C:\Users\atikm\AppData\Local\Programs\Python\Python313\Lib\site-packages\httpx\_client.py", line 1657, in _send_handling_auth
    response = await self._send_handling_redirects(
               ^^^^^^^^^^^^^^^^^^^^^^^^^^^^^^^^^^^^
    ...<3 lines>...
    )
    ^
  File "C:\Users\atikm\AppData\Local\Programs\Python\Python313\Lib\site-packages\httpx\_client.py", line 1694, in _send_handling_redirects
    response = await self._send_single_request(request)
               ^^^^^^^^^^^^^^^^^^^^^^^^^^^^^^^^^^^^^^^^
  File "C:\Users\atikm\AppData\Local\Programs\Python\Python313\Lib\site-packages\httpx\_client.py", line 1730, in _send_single_request
    response = await transport.handle_async_request(request)
               ^^^^^^^^^^^^^^^^^^^^^^^^^^^^^^^^^^^^^^^^^^^^^
  File "C:\Users\atikm\AppData\Local\Programs\Python\Python313\Lib\site-packages\httpx\_transports\default.py", line 393, in handle_async_request
    with map_httpcore_exceptions():
         ~~~~~~~~~~~~~~~~~~~~~~~^^
  File "C:\Users\atikm\AppData\Local\Programs\Python\Python313\Lib\contextlib.py", line 162, in __exit__
    self.gen.throw(value)
    ~~~~~~~~~~~~~~^^^^^^^
  File "C:\Users\atikm\AppData\Local\Programs\Python\Python313\Lib\site-packages\httpx\_transports\default.py", line 118, in map_httpcore_exceptions
    raise mapped_exc(message) from exc
httpx.ConnectError: [Errno 11001] getaddrinfo failed

The above exception was the direct cause of the following exception:

Traceback (most recent call last):
  File "C:\Users\atikm\AppData\Local\Programs\Python\Python313\Lib\site-packages\telegram\ext\_updater.py", line 750, in _network_loop_retry
    if not await do_action():
           ^^^^^^^^^^^^^^^^^
  File "C:\Users\atikm\AppData\Local\Programs\Python\Python313\Lib\site-packages\telegram\ext\_updater.py", line 744, in do_action
    return action_cb_task.result()
           ~~~~~~~~~~~~~~~~~~~~~^^
  File "C:\Users\atikm\AppData\Local\Programs\Python\Python313\Lib\asyncio\futures.py", line 199, in result
    raise self._exception.with_traceback(self._exception_tb)
  File "C:\Users\atikm\AppData\Local\Programs\Python\Python313\Lib\asyncio\tasks.py", line 306, in __step_run_and_handle_result
    result = coro.throw(exc)
  File "C:\Users\atikm\AppData\Local\Programs\Python\Python313\Lib\site-packages\telegram\ext\_updater.py", line 371, in polling_action_cb
    updates = await self.bot.get_updates(
              ^^^^^^^^^^^^^^^^^^^^^^^^^^^
    ...<7 lines>...
    )
    ^
  File "C:\Users\atikm\AppData\Local\Programs\Python\Python313\Lib\site-packages\telegram\ext\_extbot.py", line 650, in get_updates
    updates = await super().get_updates(
              ^^^^^^^^^^^^^^^^^^^^^^^^^^
    ...<9 lines>...
    )
    ^
  File "C:\Users\atikm\AppData\Local\Programs\Python\Python313\Lib\site-packages\telegram\_bot.py", line 4480, in get_updates
    await self._post(
    ^^^^^^^^^^^^^^^^^
    ...<7 lines>...
    ),
    ^
  File "C:\Users\atikm\AppData\Local\Programs\Python\Python313\Lib\site-packages\telegram\_bot.py", line 619, in _post
    return await self._do_post(
           ^^^^^^^^^^^^^^^^^^^^
    ...<6 lines>...
    )
    ^
  File "C:\Users\atikm\AppData\Local\Programs\Python\Python313\Lib\site-packages\telegram\ext\_extbot.py", line 354, in _do_post
    return await super()._do_post(
           ^^^^^^^^^^^^^^^^^^^^^^^
    ...<6 lines>...
    )
    ^
  File "C:\Users\atikm\AppData\Local\Programs\Python\Python313\Lib\site-packages\telegram\_bot.py", line 648, in _do_post
    result = await request.post(
             ^^^^^^^^^^^^^^^^^^^
    ...<6 lines>...
    )
    ^
  File "C:\Users\atikm\AppData\Local\Programs\Python\Python313\Lib\site-packages\telegram\request\_baserequest.py", line 202, in post
    result = await self._request_wrapper(
             ^^^^^^^^^^^^^^^^^^^^^^^^^^^^
    ...<7 lines>...
    )
    ^
  File "C:\Users\atikm\AppData\Local\Programs\Python\Python313\Lib\site-packages\telegram\request\_baserequest.py", line 334, in _request_wrapper
    code, payload = await self.do_request(
                    ^^^^^^^^^^^^^^^^^^^^^^
    ...<7 lines>...
    )
    ^
  File "C:\Users\atikm\AppData\Local\Programs\Python\Python313\Lib\site-packages\telegram\request\_httpxrequest.py", line 317, in do_request
    raise NetworkError(f"httpx.{err.__class__.__name__}: {err}") from err
telegram.error.NetworkError: httpx.ConnectError: [Errno 11001] getaddrinfo failed
2025-01-27 00:32:02,082 - telegram.ext.Application - ERROR - No error handlers are registered, logging exception.
Traceback (most recent call last):
  File "C:\Users\atikm\AppData\Local\Programs\Python\Python313\Lib\site-packages\httpx\_transports\default.py", line 101, in map_httpcore_exceptions
    yield
  File "C:\Users\atikm\AppData\Local\Programs\Python\Python313\Lib\site-packages\httpx\_transports\default.py", line 394, in handle_async_request
    resp = await self._pool.handle_async_request(req)
           ^^^^^^^^^^^^^^^^^^^^^^^^^^^^^^^^^^^^^^^^^^
  File "C:\Users\atikm\AppData\Local\Programs\Python\Python313\Lib\site-packages\httpcore\_async\connection_pool.py", line 256, in handle_async_request
    raise exc from None
  File "C:\Users\atikm\AppData\Local\Programs\Python\Python313\Lib\site-packages\httpcore\_async\connection_pool.py", line 236, in handle_async_request
    response = await connection.handle_async_request(
               ^^^^^^^^^^^^^^^^^^^^^^^^^^^^^^^^^^^^^^
        pool_request.request
        ^^^^^^^^^^^^^^^^^^^^
    )
    ^
  File "C:\Users\atikm\AppData\Local\Programs\Python\Python313\Lib\site-packages\httpcore\_async\connection.py", line 101, in handle_async_request
    raise exc
  File "C:\Users\atikm\AppData\Local\Programs\Python\Python313\Lib\site-packages\httpcore\_async\connection.py", line 78, in handle_async_request
    stream = await self._connect(request)
             ^^^^^^^^^^^^^^^^^^^^^^^^^^^^
  File "C:\Users\atikm\AppData\Local\Programs\Python\Python313\Lib\site-packages\httpcore\_async\connection.py", line 124, in _connect
    stream = await self._network_backend.connect_tcp(**kwargs)
             ^^^^^^^^^^^^^^^^^^^^^^^^^^^^^^^^^^^^^^^^^^^^^^^^^
  File "C:\Users\atikm\AppData\Local\Programs\Python\Python313\Lib\site-packages\httpcore\_backends\auto.py", line 31, in connect_tcp
    return await self._backend.connect_tcp(
           ^^^^^^^^^^^^^^^^^^^^^^^^^^^^^^^^
    ...<5 lines>...
    )
    ^
  File "C:\Users\atikm\AppData\Local\Programs\Python\Python313\Lib\site-packages\httpcore\_backends\anyio.py", line 113, in connect_tcp
    with map_exceptions(exc_map):
         ~~~~~~~~~~~~~~^^^^^^^^^
  File "C:\Users\atikm\AppData\Local\Programs\Python\Python313\Lib\contextlib.py", line 162, in __exit__
    self.gen.throw(value)
    ~~~~~~~~~~~~~~^^^^^^^
  File "C:\Users\atikm\AppData\Local\Programs\Python\Python313\Lib\site-packages\httpcore\_exceptions.py", line 14, in map_exceptions
    raise to_exc(exc) from exc
httpcore.ConnectError: [Errno 11001] getaddrinfo failed

The above exception was the direct cause of the following exception:

Traceback (most recent call last):
  File "C:\Users\atikm\AppData\Local\Programs\Python\Python313\Lib\site-packages\telegram\request\_httpxrequest.py", line 293, in do_request
    res = await self._client.request(
          ^^^^^^^^^^^^^^^^^^^^^^^^^^^
    ...<6 lines>...
    )
    ^
  File "C:\Users\atikm\AppData\Local\Programs\Python\Python313\Lib\site-packages\httpx\_client.py", line 1540, in request
    return await self.send(request, auth=auth, follow_redirects=follow_redirects)
           ^^^^^^^^^^^^^^^^^^^^^^^^^^^^^^^^^^^^^^^^^^^^^^^^^^^^^^^^^^^^^^^^^^^^^^
  File "C:\Users\atikm\AppData\Local\Programs\Python\Python313\Lib\site-packages\httpx\_client.py", line 1629, in send
    response = await self._send_handling_auth(
               ^^^^^^^^^^^^^^^^^^^^^^^^^^^^^^^
    ...<4 lines>...
    )
    ^
  File "C:\Users\atikm\AppData\Local\Programs\Python\Python313\Lib\site-packages\httpx\_client.py", line 1657, in _send_handling_auth
    response = await self._send_handling_redirects(
               ^^^^^^^^^^^^^^^^^^^^^^^^^^^^^^^^^^^^
    ...<3 lines>...
    )
    ^
  File "C:\Users\atikm\AppData\Local\Programs\Python\Python313\Lib\site-packages\httpx\_client.py", line 1694, in _send_handling_redirects
    response = await self._send_single_request(request)
               ^^^^^^^^^^^^^^^^^^^^^^^^^^^^^^^^^^^^^^^^
  File "C:\Users\atikm\AppData\Local\Programs\Python\Python313\Lib\site-packages\httpx\_client.py", line 1730, in _send_single_request
    response = await transport.handle_async_request(request)
               ^^^^^^^^^^^^^^^^^^^^^^^^^^^^^^^^^^^^^^^^^^^^^
  File "C:\Users\atikm\AppData\Local\Programs\Python\Python313\Lib\site-packages\httpx\_transports\default.py", line 393, in handle_async_request
    with map_httpcore_exceptions():
         ~~~~~~~~~~~~~~~~~~~~~~~^^
  File "C:\Users\atikm\AppData\Local\Programs\Python\Python313\Lib\contextlib.py", line 162, in __exit__
    self.gen.throw(value)
    ~~~~~~~~~~~~~~^^^^^^^
  File "C:\Users\atikm\AppData\Local\Programs\Python\Python313\Lib\site-packages\httpx\_transports\default.py", line 118, in map_httpcore_exceptions
    raise mapped_exc(message) from exc
httpx.ConnectError: [Errno 11001] getaddrinfo failed

The above exception was the direct cause of the following exception:

Traceback (most recent call last):
  File "C:\Users\atikm\AppData\Local\Programs\Python\Python313\Lib\site-packages\telegram\ext\_updater.py", line 750, in _network_loop_retry
    if not await do_action():
           ^^^^^^^^^^^^^^^^^
  File "C:\Users\atikm\AppData\Local\Programs\Python\Python313\Lib\site-packages\telegram\ext\_updater.py", line 744, in do_action
    return action_cb_task.result()
           ~~~~~~~~~~~~~~~~~~~~~^^
  File "C:\Users\atikm\AppData\Local\Programs\Python\Python313\Lib\asyncio\futures.py", line 199, in result
    raise self._exception.with_traceback(self._exception_tb)
  File "C:\Users\atikm\AppData\Local\Programs\Python\Python313\Lib\asyncio\tasks.py", line 306, in __step_run_and_handle_result
    result = coro.throw(exc)
  File "C:\Users\atikm\AppData\Local\Programs\Python\Python313\Lib\site-packages\telegram\ext\_updater.py", line 371, in polling_action_cb
    updates = await self.bot.get_updates(
              ^^^^^^^^^^^^^^^^^^^^^^^^^^^
    ...<7 lines>...
    )
    ^
  File "C:\Users\atikm\AppData\Local\Programs\Python\Python313\Lib\site-packages\telegram\ext\_extbot.py", line 650, in get_updates
    updates = await super().get_updates(
              ^^^^^^^^^^^^^^^^^^^^^^^^^^
    ...<9 lines>...
    )
    ^
  File "C:\Users\atikm\AppData\Local\Programs\Python\Python313\Lib\site-packages\telegram\_bot.py", line 4480, in get_updates
    await self._post(
    ^^^^^^^^^^^^^^^^^
    ...<7 lines>...
    ),
    ^
  File "C:\Users\atikm\AppData\Local\Programs\Python\Python313\Lib\site-packages\telegram\_bot.py", line 619, in _post
    return await self._do_post(
           ^^^^^^^^^^^^^^^^^^^^
    ...<6 lines>...
    )
    ^
  File "C:\Users\atikm\AppData\Local\Programs\Python\Python313\Lib\site-packages\telegram\ext\_extbot.py", line 354, in _do_post
    return await super()._do_post(
           ^^^^^^^^^^^^^^^^^^^^^^^
    ...<6 lines>...
    )
    ^
  File "C:\Users\atikm\AppData\Local\Programs\Python\Python313\Lib\site-packages\telegram\_bot.py", line 648, in _do_post
    result = await request.post(
             ^^^^^^^^^^^^^^^^^^^
    ...<6 lines>...
    )
    ^
  File "C:\Users\atikm\AppData\Local\Programs\Python\Python313\Lib\site-packages\telegram\request\_baserequest.py", line 202, in post
    result = await self._request_wrapper(
             ^^^^^^^^^^^^^^^^^^^^^^^^^^^^
    ...<7 lines>...
    )
    ^
  File "C:\Users\atikm\AppData\Local\Programs\Python\Python313\Lib\site-packages\telegram\request\_baserequest.py", line 334, in _request_wrapper
    code, payload = await self.do_request(
                    ^^^^^^^^^^^^^^^^^^^^^^
    ...<7 lines>...
    )
    ^
  File "C:\Users\atikm\AppData\Local\Programs\Python\Python313\Lib\site-packages\telegram\request\_httpxrequest.py", line 317, in do_request
    raise NetworkError(f"httpx.{err.__class__.__name__}: {err}") from err
telegram.error.NetworkError: httpx.ConnectError: [Errno 11001] getaddrinfo failed
2025-01-27 00:32:13,480 - telegram.ext.Application - ERROR - No error handlers are registered, logging exception.
Traceback (most recent call last):
  File "C:\Users\atikm\AppData\Local\Programs\Python\Python313\Lib\site-packages\httpx\_transports\default.py", line 101, in map_httpcore_exceptions
    yield
  File "C:\Users\atikm\AppData\Local\Programs\Python\Python313\Lib\site-packages\httpx\_transports\default.py", line 394, in handle_async_request
    resp = await self._pool.handle_async_request(req)
           ^^^^^^^^^^^^^^^^^^^^^^^^^^^^^^^^^^^^^^^^^^
  File "C:\Users\atikm\AppData\Local\Programs\Python\Python313\Lib\site-packages\httpcore\_async\connection_pool.py", line 256, in handle_async_request
    raise exc from None
  File "C:\Users\atikm\AppData\Local\Programs\Python\Python313\Lib\site-packages\httpcore\_async\connection_pool.py", line 236, in handle_async_request
    response = await connection.handle_async_request(
               ^^^^^^^^^^^^^^^^^^^^^^^^^^^^^^^^^^^^^^
        pool_request.request
        ^^^^^^^^^^^^^^^^^^^^
    )
    ^
  File "C:\Users\atikm\AppData\Local\Programs\Python\Python313\Lib\site-packages\httpcore\_async\connection.py", line 101, in handle_async_request
    raise exc
  File "C:\Users\atikm\AppData\Local\Programs\Python\Python313\Lib\site-packages\httpcore\_async\connection.py", line 78, in handle_async_request
    stream = await self._connect(request)
             ^^^^^^^^^^^^^^^^^^^^^^^^^^^^
  File "C:\Users\atikm\AppData\Local\Programs\Python\Python313\Lib\site-packages\httpcore\_async\connection.py", line 124, in _connect
    stream = await self._network_backend.connect_tcp(**kwargs)
             ^^^^^^^^^^^^^^^^^^^^^^^^^^^^^^^^^^^^^^^^^^^^^^^^^
  File "C:\Users\atikm\AppData\Local\Programs\Python\Python313\Lib\site-packages\httpcore\_backends\auto.py", line 31, in connect_tcp
    return await self._backend.connect_tcp(
           ^^^^^^^^^^^^^^^^^^^^^^^^^^^^^^^^
    ...<5 lines>...
    )
    ^
  File "C:\Users\atikm\AppData\Local\Programs\Python\Python313\Lib\site-packages\httpcore\_backends\anyio.py", line 113, in connect_tcp
    with map_exceptions(exc_map):
         ~~~~~~~~~~~~~~^^^^^^^^^
  File "C:\Users\atikm\AppData\Local\Programs\Python\Python313\Lib\contextlib.py", line 162, in __exit__
    self.gen.throw(value)
    ~~~~~~~~~~~~~~^^^^^^^
  File "C:\Users\atikm\AppData\Local\Programs\Python\Python313\Lib\site-packages\httpcore\_exceptions.py", line 14, in map_exceptions
    raise to_exc(exc) from exc
httpcore.ConnectError: [Errno 11001] getaddrinfo failed

The above exception was the direct cause of the following exception:

Traceback (most recent call last):
  File "C:\Users\atikm\AppData\Local\Programs\Python\Python313\Lib\site-packages\telegram\request\_httpxrequest.py", line 293, in do_request
    res = await self._client.request(
          ^^^^^^^^^^^^^^^^^^^^^^^^^^^
    ...<6 lines>...
    )
    ^
  File "C:\Users\atikm\AppData\Local\Programs\Python\Python313\Lib\site-packages\httpx\_client.py", line 1540, in request
    return await self.send(request, auth=auth, follow_redirects=follow_redirects)
           ^^^^^^^^^^^^^^^^^^^^^^^^^^^^^^^^^^^^^^^^^^^^^^^^^^^^^^^^^^^^^^^^^^^^^^
  File "C:\Users\atikm\AppData\Local\Programs\Python\Python313\Lib\site-packages\httpx\_client.py", line 1629, in send
    response = await self._send_handling_auth(
               ^^^^^^^^^^^^^^^^^^^^^^^^^^^^^^^
    ...<4 lines>...
    )
    ^
  File "C:\Users\atikm\AppData\Local\Programs\Python\Python313\Lib\site-packages\httpx\_client.py", line 1657, in _send_handling_auth
    response = await self._send_handling_redirects(
               ^^^^^^^^^^^^^^^^^^^^^^^^^^^^^^^^^^^^
    ...<3 lines>...
    )
    ^
  File "C:\Users\atikm\AppData\Local\Programs\Python\Python313\Lib\site-packages\httpx\_client.py", line 1694, in _send_handling_redirects
    response = await self._send_single_request(request)
               ^^^^^^^^^^^^^^^^^^^^^^^^^^^^^^^^^^^^^^^^
  File "C:\Users\atikm\AppData\Local\Programs\Python\Python313\Lib\site-packages\httpx\_client.py", line 1730, in _send_single_request
    response = await transport.handle_async_request(request)
               ^^^^^^^^^^^^^^^^^^^^^^^^^^^^^^^^^^^^^^^^^^^^^
  File "C:\Users\atikm\AppData\Local\Programs\Python\Python313\Lib\site-packages\httpx\_transports\default.py", line 393, in handle_async_request
    with map_httpcore_exceptions():
         ~~~~~~~~~~~~~~~~~~~~~~~^^
  File "C:\Users\atikm\AppData\Local\Programs\Python\Python313\Lib\contextlib.py", line 162, in __exit__
    self.gen.throw(value)
    ~~~~~~~~~~~~~~^^^^^^^
  File "C:\Users\atikm\AppData\Local\Programs\Python\Python313\Lib\site-packages\httpx\_transports\default.py", line 118, in map_httpcore_exceptions
    raise mapped_exc(message) from exc
httpx.ConnectError: [Errno 11001] getaddrinfo failed

The above exception was the direct cause of the following exception:

Traceback (most recent call last):
  File "C:\Users\atikm\AppData\Local\Programs\Python\Python313\Lib\site-packages\telegram\ext\_updater.py", line 750, in _network_loop_retry
    if not await do_action():
           ^^^^^^^^^^^^^^^^^
  File "C:\Users\atikm\AppData\Local\Programs\Python\Python313\Lib\site-packages\telegram\ext\_updater.py", line 744, in do_action
    return action_cb_task.result()
           ~~~~~~~~~~~~~~~~~~~~~^^
  File "C:\Users\atikm\AppData\Local\Programs\Python\Python313\Lib\asyncio\futures.py", line 199, in result
    raise self._exception.with_traceback(self._exception_tb)
  File "C:\Users\atikm\AppData\Local\Programs\Python\Python313\Lib\asyncio\tasks.py", line 306, in __step_run_and_handle_result
    result = coro.throw(exc)
  File "C:\Users\atikm\AppData\Local\Programs\Python\Python313\Lib\site-packages\telegram\ext\_updater.py", line 371, in polling_action_cb
    updates = await self.bot.get_updates(
              ^^^^^^^^^^^^^^^^^^^^^^^^^^^
    ...<7 lines>...
    )
    ^
  File "C:\Users\atikm\AppData\Local\Programs\Python\Python313\Lib\site-packages\telegram\ext\_extbot.py", line 650, in get_updates
    updates = await super().get_updates(
              ^^^^^^^^^^^^^^^^^^^^^^^^^^
    ...<9 lines>...
    )
    ^
  File "C:\Users\atikm\AppData\Local\Programs\Python\Python313\Lib\site-packages\telegram\_bot.py", line 4480, in get_updates
    await self._post(
    ^^^^^^^^^^^^^^^^^
    ...<7 lines>...
    ),
    ^
  File "C:\Users\atikm\AppData\Local\Programs\Python\Python313\Lib\site-packages\telegram\_bot.py", line 619, in _post
    return await self._do_post(
           ^^^^^^^^^^^^^^^^^^^^
    ...<6 lines>...
    )
    ^
  File "C:\Users\atikm\AppData\Local\Programs\Python\Python313\Lib\site-packages\telegram\ext\_extbot.py", line 354, in _do_post
    return await super()._do_post(
           ^^^^^^^^^^^^^^^^^^^^^^^
    ...<6 lines>...
    )
    ^
  File "C:\Users\atikm\AppData\Local\Programs\Python\Python313\Lib\site-packages\telegram\_bot.py", line 648, in _do_post
    result = await request.post(
             ^^^^^^^^^^^^^^^^^^^
    ...<6 lines>...
    )
    ^
  File "C:\Users\atikm\AppData\Local\Programs\Python\Python313\Lib\site-packages\telegram\request\_baserequest.py", line 202, in post
    result = await self._request_wrapper(
             ^^^^^^^^^^^^^^^^^^^^^^^^^^^^
    ...<7 lines>...
    )
    ^
  File "C:\Users\atikm\AppData\Local\Programs\Python\Python313\Lib\site-packages\telegram\request\_baserequest.py", line 334, in _request_wrapper
    code, payload = await self.do_request(
                    ^^^^^^^^^^^^^^^^^^^^^^
    ...<7 lines>...
    )
    ^
  File "C:\Users\atikm\AppData\Local\Programs\Python\Python313\Lib\site-packages\telegram\request\_httpxrequest.py", line 317, in do_request
    raise NetworkError(f"httpx.{err.__class__.__name__}: {err}") from err
telegram.error.NetworkError: httpx.ConnectError: [Errno 11001] getaddrinfo failed
2025-01-27 00:32:30,586 - telegram.ext.Application - ERROR - No error handlers are registered, logging exception.
Traceback (most recent call last):
  File "C:\Users\atikm\AppData\Local\Programs\Python\Python313\Lib\site-packages\httpx\_transports\default.py", line 101, in map_httpcore_exceptions
    yield
  File "C:\Users\atikm\AppData\Local\Programs\Python\Python313\Lib\site-packages\httpx\_transports\default.py", line 394, in handle_async_request
    resp = await self._pool.handle_async_request(req)
           ^^^^^^^^^^^^^^^^^^^^^^^^^^^^^^^^^^^^^^^^^^
  File "C:\Users\atikm\AppData\Local\Programs\Python\Python313\Lib\site-packages\httpcore\_async\connection_pool.py", line 256, in handle_async_request
    raise exc from None
  File "C:\Users\atikm\AppData\Local\Programs\Python\Python313\Lib\site-packages\httpcore\_async\connection_pool.py", line 236, in handle_async_request
    response = await connection.handle_async_request(
               ^^^^^^^^^^^^^^^^^^^^^^^^^^^^^^^^^^^^^^
        pool_request.request
        ^^^^^^^^^^^^^^^^^^^^
    )
    ^
  File "C:\Users\atikm\AppData\Local\Programs\Python\Python313\Lib\site-packages\httpcore\_async\connection.py", line 101, in handle_async_request
    raise exc
  File "C:\Users\atikm\AppData\Local\Programs\Python\Python313\Lib\site-packages\httpcore\_async\connection.py", line 78, in handle_async_request
    stream = await self._connect(request)
             ^^^^^^^^^^^^^^^^^^^^^^^^^^^^
  File "C:\Users\atikm\AppData\Local\Programs\Python\Python313\Lib\site-packages\httpcore\_async\connection.py", line 124, in _connect
    stream = await self._network_backend.connect_tcp(**kwargs)
             ^^^^^^^^^^^^^^^^^^^^^^^^^^^^^^^^^^^^^^^^^^^^^^^^^
  File "C:\Users\atikm\AppData\Local\Programs\Python\Python313\Lib\site-packages\httpcore\_backends\auto.py", line 31, in connect_tcp
    return await self._backend.connect_tcp(
           ^^^^^^^^^^^^^^^^^^^^^^^^^^^^^^^^
    ...<5 lines>...
    )
    ^
  File "C:\Users\atikm\AppData\Local\Programs\Python\Python313\Lib\site-packages\httpcore\_backends\anyio.py", line 113, in connect_tcp
    with map_exceptions(exc_map):
         ~~~~~~~~~~~~~~^^^^^^^^^
  File "C:\Users\atikm\AppData\Local\Programs\Python\Python313\Lib\contextlib.py", line 162, in __exit__
    self.gen.throw(value)
    ~~~~~~~~~~~~~~^^^^^^^
  File "C:\Users\atikm\AppData\Local\Programs\Python\Python313\Lib\site-packages\httpcore\_exceptions.py", line 14, in map_exceptions
    raise to_exc(exc) from exc
httpcore.ConnectError: [Errno 11001] getaddrinfo failed

The above exception was the direct cause of the following exception:

Traceback (most recent call last):
  File "C:\Users\atikm\AppData\Local\Programs\Python\Python313\Lib\site-packages\telegram\request\_httpxrequest.py", line 293, in do_request
    res = await self._client.request(
          ^^^^^^^^^^^^^^^^^^^^^^^^^^^
    ...<6 lines>...
    )
    ^
  File "C:\Users\atikm\AppData\Local\Programs\Python\Python313\Lib\site-packages\httpx\_client.py", line 1540, in request
    return await self.send(request, auth=auth, follow_redirects=follow_redirects)
           ^^^^^^^^^^^^^^^^^^^^^^^^^^^^^^^^^^^^^^^^^^^^^^^^^^^^^^^^^^^^^^^^^^^^^^
  File "C:\Users\atikm\AppData\Local\Programs\Python\Python313\Lib\site-packages\httpx\_client.py", line 1629, in send
    response = await self._send_handling_auth(
               ^^^^^^^^^^^^^^^^^^^^^^^^^^^^^^^
    ...<4 lines>...
    )
    ^
  File "C:\Users\atikm\AppData\Local\Programs\Python\Python313\Lib\site-packages\httpx\_client.py", line 1657, in _send_handling_auth
    response = await self._send_handling_redirects(
               ^^^^^^^^^^^^^^^^^^^^^^^^^^^^^^^^^^^^
    ...<3 lines>...
    )
    ^
  File "C:\Users\atikm\AppData\Local\Programs\Python\Python313\Lib\site-packages\httpx\_client.py", line 1694, in _send_handling_redirects
    response = await self._send_single_request(request)
               ^^^^^^^^^^^^^^^^^^^^^^^^^^^^^^^^^^^^^^^^
  File "C:\Users\atikm\AppData\Local\Programs\Python\Python313\Lib\site-packages\httpx\_client.py", line 1730, in _send_single_request
    response = await transport.handle_async_request(request)
               ^^^^^^^^^^^^^^^^^^^^^^^^^^^^^^^^^^^^^^^^^^^^^
  File "C:\Users\atikm\AppData\Local\Programs\Python\Python313\Lib\site-packages\httpx\_transports\default.py", line 393, in handle_async_request
    with map_httpcore_exceptions():
         ~~~~~~~~~~~~~~~~~~~~~~~^^
  File "C:\Users\atikm\AppData\Local\Programs\Python\Python313\Lib\contextlib.py", line 162, in __exit__
    self.gen.throw(value)
    ~~~~~~~~~~~~~~^^^^^^^
  File "C:\Users\atikm\AppData\Local\Programs\Python\Python313\Lib\site-packages\httpx\_transports\default.py", line 118, in map_httpcore_exceptions
    raise mapped_exc(message) from exc
httpx.ConnectError: [Errno 11001] getaddrinfo failed

The above exception was the direct cause of the following exception:

Traceback (most recent call last):
  File "C:\Users\atikm\AppData\Local\Programs\Python\Python313\Lib\site-packages\telegram\ext\_updater.py", line 750, in _network_loop_retry
    if not await do_action():
           ^^^^^^^^^^^^^^^^^
  File "C:\Users\atikm\AppData\Local\Programs\Python\Python313\Lib\site-packages\telegram\ext\_updater.py", line 744, in do_action
    return action_cb_task.result()
           ~~~~~~~~~~~~~~~~~~~~~^^
  File "C:\Users\atikm\AppData\Local\Programs\Python\Python313\Lib\asyncio\futures.py", line 199, in result
    raise self._exception.with_traceback(self._exception_tb)
  File "C:\Users\atikm\AppData\Local\Programs\Python\Python313\Lib\asyncio\tasks.py", line 306, in __step_run_and_handle_result
    result = coro.throw(exc)
  File "C:\Users\atikm\AppData\Local\Programs\Python\Python313\Lib\site-packages\telegram\ext\_updater.py", line 371, in polling_action_cb
    updates = await self.bot.get_updates(
              ^^^^^^^^^^^^^^^^^^^^^^^^^^^
    ...<7 lines>...
    )
    ^
  File "C:\Users\atikm\AppData\Local\Programs\Python\Python313\Lib\site-packages\telegram\ext\_extbot.py", line 650, in get_updates
    updates = await super().get_updates(
              ^^^^^^^^^^^^^^^^^^^^^^^^^^
    ...<9 lines>...
    )
    ^
  File "C:\Users\atikm\AppData\Local\Programs\Python\Python313\Lib\site-packages\telegram\_bot.py", line 4480, in get_updates
    await self._post(
    ^^^^^^^^^^^^^^^^^
    ...<7 lines>...
    ),
    ^
  File "C:\Users\atikm\AppData\Local\Programs\Python\Python313\Lib\site-packages\telegram\_bot.py", line 619, in _post
    return await self._do_post(
           ^^^^^^^^^^^^^^^^^^^^
    ...<6 lines>...
    )
    ^
  File "C:\Users\atikm\AppData\Local\Programs\Python\Python313\Lib\site-packages\telegram\ext\_extbot.py", line 354, in _do_post
    return await super()._do_post(
           ^^^^^^^^^^^^^^^^^^^^^^^
    ...<6 lines>...
    )
    ^
  File "C:\Users\atikm\AppData\Local\Programs\Python\Python313\Lib\site-packages\telegram\_bot.py", line 648, in _do_post
    result = await request.post(
             ^^^^^^^^^^^^^^^^^^^
    ...<6 lines>...
    )
    ^
  File "C:\Users\atikm\AppData\Local\Programs\Python\Python313\Lib\site-packages\telegram\request\_baserequest.py", line 202, in post
    result = await self._request_wrapper(
             ^^^^^^^^^^^^^^^^^^^^^^^^^^^^
    ...<7 lines>...
    )
    ^
  File "C:\Users\atikm\AppData\Local\Programs\Python\Python313\Lib\site-packages\telegram\request\_baserequest.py", line 334, in _request_wrapper
    code, payload = await self.do_request(
                    ^^^^^^^^^^^^^^^^^^^^^^
    ...<7 lines>...
    )
    ^
  File "C:\Users\atikm\AppData\Local\Programs\Python\Python313\Lib\site-packages\telegram\request\_httpxrequest.py", line 317, in do_request
    raise NetworkError(f"httpx.{err.__class__.__name__}: {err}") from err
telegram.error.NetworkError: httpx.ConnectError: [Errno 11001] getaddrinfo failed
2025-01-27 00:32:56,222 - telegram.ext.Application - ERROR - No error handlers are registered, logging exception.
Traceback (most recent call last):
  File "C:\Users\atikm\AppData\Local\Programs\Python\Python313\Lib\site-packages\httpx\_transports\default.py", line 101, in map_httpcore_exceptions
    yield
  File "C:\Users\atikm\AppData\Local\Programs\Python\Python313\Lib\site-packages\httpx\_transports\default.py", line 394, in handle_async_request
    resp = await self._pool.handle_async_request(req)
           ^^^^^^^^^^^^^^^^^^^^^^^^^^^^^^^^^^^^^^^^^^
  File "C:\Users\atikm\AppData\Local\Programs\Python\Python313\Lib\site-packages\httpcore\_async\connection_pool.py", line 256, in handle_async_request
    raise exc from None
  File "C:\Users\atikm\AppData\Local\Programs\Python\Python313\Lib\site-packages\httpcore\_async\connection_pool.py", line 236, in handle_async_request
    response = await connection.handle_async_request(
               ^^^^^^^^^^^^^^^^^^^^^^^^^^^^^^^^^^^^^^
        pool_request.request
        ^^^^^^^^^^^^^^^^^^^^
    )
    ^
  File "C:\Users\atikm\AppData\Local\Programs\Python\Python313\Lib\site-packages\httpcore\_async\connection.py", line 101, in handle_async_request
    raise exc
  File "C:\Users\atikm\AppData\Local\Programs\Python\Python313\Lib\site-packages\httpcore\_async\connection.py", line 78, in handle_async_request
    stream = await self._connect(request)
             ^^^^^^^^^^^^^^^^^^^^^^^^^^^^
  File "C:\Users\atikm\AppData\Local\Programs\Python\Python313\Lib\site-packages\httpcore\_async\connection.py", line 124, in _connect
    stream = await self._network_backend.connect_tcp(**kwargs)
             ^^^^^^^^^^^^^^^^^^^^^^^^^^^^^^^^^^^^^^^^^^^^^^^^^
  File "C:\Users\atikm\AppData\Local\Programs\Python\Python313\Lib\site-packages\httpcore\_backends\auto.py", line 31, in connect_tcp
    return await self._backend.connect_tcp(
           ^^^^^^^^^^^^^^^^^^^^^^^^^^^^^^^^
    ...<5 lines>...
    )
    ^
  File "C:\Users\atikm\AppData\Local\Programs\Python\Python313\Lib\site-packages\httpcore\_backends\anyio.py", line 113, in connect_tcp
    with map_exceptions(exc_map):
         ~~~~~~~~~~~~~~^^^^^^^^^
  File "C:\Users\atikm\AppData\Local\Programs\Python\Python313\Lib\contextlib.py", line 162, in __exit__
    self.gen.throw(value)
    ~~~~~~~~~~~~~~^^^^^^^
  File "C:\Users\atikm\AppData\Local\Programs\Python\Python313\Lib\site-packages\httpcore\_exceptions.py", line 14, in map_exceptions
    raise to_exc(exc) from exc
httpcore.ConnectError: [Errno 11001] getaddrinfo failed

The above exception was the direct cause of the following exception:

Traceback (most recent call last):
  File "C:\Users\atikm\AppData\Local\Programs\Python\Python313\Lib\site-packages\telegram\request\_httpxrequest.py", line 293, in do_request
    res = await self._client.request(
          ^^^^^^^^^^^^^^^^^^^^^^^^^^^
    ...<6 lines>...
    )
    ^
  File "C:\Users\atikm\AppData\Local\Programs\Python\Python313\Lib\site-packages\httpx\_client.py", line 1540, in request
    return await self.send(request, auth=auth, follow_redirects=follow_redirects)
           ^^^^^^^^^^^^^^^^^^^^^^^^^^^^^^^^^^^^^^^^^^^^^^^^^^^^^^^^^^^^^^^^^^^^^^
  File "C:\Users\atikm\AppData\Local\Programs\Python\Python313\Lib\site-packages\httpx\_client.py", line 1629, in send
    response = await self._send_handling_auth(
               ^^^^^^^^^^^^^^^^^^^^^^^^^^^^^^^
    ...<4 lines>...
    )
    ^
  File "C:\Users\atikm\AppData\Local\Programs\Python\Python313\Lib\site-packages\httpx\_client.py", line 1657, in _send_handling_auth
    response = await self._send_handling_redirects(
               ^^^^^^^^^^^^^^^^^^^^^^^^^^^^^^^^^^^^
    ...<3 lines>...
    )
    ^
  File "C:\Users\atikm\AppData\Local\Programs\Python\Python313\Lib\site-packages\httpx\_client.py", line 1694, in _send_handling_redirects
    response = await self._send_single_request(request)
               ^^^^^^^^^^^^^^^^^^^^^^^^^^^^^^^^^^^^^^^^
  File "C:\Users\atikm\AppData\Local\Programs\Python\Python313\Lib\site-packages\httpx\_client.py", line 1730, in _send_single_request
    response = await transport.handle_async_request(request)
               ^^^^^^^^^^^^^^^^^^^^^^^^^^^^^^^^^^^^^^^^^^^^^
  File "C:\Users\atikm\AppData\Local\Programs\Python\Python313\Lib\site-packages\httpx\_transports\default.py", line 393, in handle_async_request
    with map_httpcore_exceptions():
         ~~~~~~~~~~~~~~~~~~~~~~~^^
  File "C:\Users\atikm\AppData\Local\Programs\Python\Python313\Lib\contextlib.py", line 162, in __exit__
    self.gen.throw(value)
    ~~~~~~~~~~~~~~^^^^^^^
  File "C:\Users\atikm\AppData\Local\Programs\Python\Python313\Lib\site-packages\httpx\_transports\default.py", line 118, in map_httpcore_exceptions
    raise mapped_exc(message) from exc
httpx.ConnectError: [Errno 11001] getaddrinfo failed

The above exception was the direct cause of the following exception:

Traceback (most recent call last):
  File "C:\Users\atikm\AppData\Local\Programs\Python\Python313\Lib\site-packages\telegram\ext\_updater.py", line 750, in _network_loop_retry
    if not await do_action():
           ^^^^^^^^^^^^^^^^^
  File "C:\Users\atikm\AppData\Local\Programs\Python\Python313\Lib\site-packages\telegram\ext\_updater.py", line 744, in do_action
    return action_cb_task.result()
           ~~~~~~~~~~~~~~~~~~~~~^^
  File "C:\Users\atikm\AppData\Local\Programs\Python\Python313\Lib\asyncio\futures.py", line 199, in result
    raise self._exception.with_traceback(self._exception_tb)
  File "C:\Users\atikm\AppData\Local\Programs\Python\Python313\Lib\asyncio\tasks.py", line 306, in __step_run_and_handle_result
    result = coro.throw(exc)
  File "C:\Users\atikm\AppData\Local\Programs\Python\Python313\Lib\site-packages\telegram\ext\_updater.py", line 371, in polling_action_cb
    updates = await self.bot.get_updates(
              ^^^^^^^^^^^^^^^^^^^^^^^^^^^
    ...<7 lines>...
    )
    ^
  File "C:\Users\atikm\AppData\Local\Programs\Python\Python313\Lib\site-packages\telegram\ext\_extbot.py", line 650, in get_updates
    updates = await super().get_updates(
              ^^^^^^^^^^^^^^^^^^^^^^^^^^
    ...<9 lines>...
    )
    ^
  File "C:\Users\atikm\AppData\Local\Programs\Python\Python313\Lib\site-packages\telegram\_bot.py", line 4480, in get_updates
    await self._post(
    ^^^^^^^^^^^^^^^^^
    ...<7 lines>...
    ),
    ^
  File "C:\Users\atikm\AppData\Local\Programs\Python\Python313\Lib\site-packages\telegram\_bot.py", line 619, in _post
    return await self._do_post(
           ^^^^^^^^^^^^^^^^^^^^
    ...<6 lines>...
    )
    ^
  File "C:\Users\atikm\AppData\Local\Programs\Python\Python313\Lib\site-packages\telegram\ext\_extbot.py", line 354, in _do_post
    return await super()._do_post(
           ^^^^^^^^^^^^^^^^^^^^^^^
    ...<6 lines>...
    )
    ^
  File "C:\Users\atikm\AppData\Local\Programs\Python\Python313\Lib\site-packages\telegram\_bot.py", line 648, in _do_post
    result = await request.post(
             ^^^^^^^^^^^^^^^^^^^
    ...<6 lines>...
    )
    ^
  File "C:\Users\atikm\AppData\Local\Programs\Python\Python313\Lib\site-packages\telegram\request\_baserequest.py", line 202, in post
    result = await self._request_wrapper(
             ^^^^^^^^^^^^^^^^^^^^^^^^^^^^
    ...<7 lines>...
    )
    ^
  File "C:\Users\atikm\AppData\Local\Programs\Python\Python313\Lib\site-packages\telegram\request\_baserequest.py", line 334, in _request_wrapper
    code, payload = await self.do_request(
                    ^^^^^^^^^^^^^^^^^^^^^^
    ...<7 lines>...
    )
    ^
  File "C:\Users\atikm\AppData\Local\Programs\Python\Python313\Lib\site-packages\telegram\request\_httpxrequest.py", line 317, in do_request
    raise NetworkError(f"httpx.{err.__class__.__name__}: {err}") from err
telegram.error.NetworkError: httpx.ConnectError: [Errno 11001] getaddrinfo failed
2025-01-27 00:33:26,236 - telegram.ext.Application - ERROR - No error handlers are registered, logging exception.
Traceback (most recent call last):
  File "C:\Users\atikm\AppData\Local\Programs\Python\Python313\Lib\site-packages\httpx\_transports\default.py", line 101, in map_httpcore_exceptions
    yield
  File "C:\Users\atikm\AppData\Local\Programs\Python\Python313\Lib\site-packages\httpx\_transports\default.py", line 394, in handle_async_request
    resp = await self._pool.handle_async_request(req)
           ^^^^^^^^^^^^^^^^^^^^^^^^^^^^^^^^^^^^^^^^^^
  File "C:\Users\atikm\AppData\Local\Programs\Python\Python313\Lib\site-packages\httpcore\_async\connection_pool.py", line 256, in handle_async_request
    raise exc from None
  File "C:\Users\atikm\AppData\Local\Programs\Python\Python313\Lib\site-packages\httpcore\_async\connection_pool.py", line 236, in handle_async_request
    response = await connection.handle_async_request(
               ^^^^^^^^^^^^^^^^^^^^^^^^^^^^^^^^^^^^^^
        pool_request.request
        ^^^^^^^^^^^^^^^^^^^^
    )
    ^
  File "C:\Users\atikm\AppData\Local\Programs\Python\Python313\Lib\site-packages\httpcore\_async\connection.py", line 101, in handle_async_request
    raise exc
  File "C:\Users\atikm\AppData\Local\Programs\Python\Python313\Lib\site-packages\httpcore\_async\connection.py", line 78, in handle_async_request
    stream = await self._connect(request)
             ^^^^^^^^^^^^^^^^^^^^^^^^^^^^
  File "C:\Users\atikm\AppData\Local\Programs\Python\Python313\Lib\site-packages\httpcore\_async\connection.py", line 124, in _connect
    stream = await self._network_backend.connect_tcp(**kwargs)
             ^^^^^^^^^^^^^^^^^^^^^^^^^^^^^^^^^^^^^^^^^^^^^^^^^
  File "C:\Users\atikm\AppData\Local\Programs\Python\Python313\Lib\site-packages\httpcore\_backends\auto.py", line 31, in connect_tcp
    return await self._backend.connect_tcp(
           ^^^^^^^^^^^^^^^^^^^^^^^^^^^^^^^^
    ...<5 lines>...
    )
    ^
  File "C:\Users\atikm\AppData\Local\Programs\Python\Python313\Lib\site-packages\httpcore\_backends\anyio.py", line 113, in connect_tcp
    with map_exceptions(exc_map):
         ~~~~~~~~~~~~~~^^^^^^^^^
  File "C:\Users\atikm\AppData\Local\Programs\Python\Python313\Lib\contextlib.py", line 162, in __exit__
    self.gen.throw(value)
    ~~~~~~~~~~~~~~^^^^^^^
  File "C:\Users\atikm\AppData\Local\Programs\Python\Python313\Lib\site-packages\httpcore\_exceptions.py", line 14, in map_exceptions
    raise to_exc(exc) from exc
httpcore.ConnectError: [Errno 11001] getaddrinfo failed

The above exception was the direct cause of the following exception:

Traceback (most recent call last):
  File "C:\Users\atikm\AppData\Local\Programs\Python\Python313\Lib\site-packages\telegram\request\_httpxrequest.py", line 293, in do_request
    res = await self._client.request(
          ^^^^^^^^^^^^^^^^^^^^^^^^^^^
    ...<6 lines>...
    )
    ^
  File "C:\Users\atikm\AppData\Local\Programs\Python\Python313\Lib\site-packages\httpx\_client.py", line 1540, in request
    return await self.send(request, auth=auth, follow_redirects=follow_redirects)
           ^^^^^^^^^^^^^^^^^^^^^^^^^^^^^^^^^^^^^^^^^^^^^^^^^^^^^^^^^^^^^^^^^^^^^^
  File "C:\Users\atikm\AppData\Local\Programs\Python\Python313\Lib\site-packages\httpx\_client.py", line 1629, in send
    response = await self._send_handling_auth(
               ^^^^^^^^^^^^^^^^^^^^^^^^^^^^^^^
    ...<4 lines>...
    )
    ^
  File "C:\Users\atikm\AppData\Local\Programs\Python\Python313\Lib\site-packages\httpx\_client.py", line 1657, in _send_handling_auth
    response = await self._send_handling_redirects(
               ^^^^^^^^^^^^^^^^^^^^^^^^^^^^^^^^^^^^
    ...<3 lines>...
    )
    ^
  File "C:\Users\atikm\AppData\Local\Programs\Python\Python313\Lib\site-packages\httpx\_client.py", line 1694, in _send_handling_redirects
    response = await self._send_single_request(request)
               ^^^^^^^^^^^^^^^^^^^^^^^^^^^^^^^^^^^^^^^^
  File "C:\Users\atikm\AppData\Local\Programs\Python\Python313\Lib\site-packages\httpx\_client.py", line 1730, in _send_single_request
    response = await transport.handle_async_request(request)
               ^^^^^^^^^^^^^^^^^^^^^^^^^^^^^^^^^^^^^^^^^^^^^
  File "C:\Users\atikm\AppData\Local\Programs\Python\Python313\Lib\site-packages\httpx\_transports\default.py", line 393, in handle_async_request
    with map_httpcore_exceptions():
         ~~~~~~~~~~~~~~~~~~~~~~~^^
  File "C:\Users\atikm\AppData\Local\Programs\Python\Python313\Lib\contextlib.py", line 162, in __exit__
    self.gen.throw(value)
    ~~~~~~~~~~~~~~^^^^^^^
  File "C:\Users\atikm\AppData\Local\Programs\Python\Python313\Lib\site-packages\httpx\_transports\default.py", line 118, in map_httpcore_exceptions
    raise mapped_exc(message) from exc
httpx.ConnectError: [Errno 11001] getaddrinfo failed

The above exception was the direct cause of the following exception:

Traceback (most recent call last):
  File "C:\Users\atikm\AppData\Local\Programs\Python\Python313\Lib\site-packages\telegram\ext\_updater.py", line 750, in _network_loop_retry
    if not await do_action():
           ^^^^^^^^^^^^^^^^^
  File "C:\Users\atikm\AppData\Local\Programs\Python\Python313\Lib\site-packages\telegram\ext\_updater.py", line 744, in do_action
    return action_cb_task.result()
           ~~~~~~~~~~~~~~~~~~~~~^^
  File "C:\Users\atikm\AppData\Local\Programs\Python\Python313\Lib\asyncio\futures.py", line 199, in result
    raise self._exception.with_traceback(self._exception_tb)
  File "C:\Users\atikm\AppData\Local\Programs\Python\Python313\Lib\asyncio\tasks.py", line 306, in __step_run_and_handle_result
    result = coro.throw(exc)
  File "C:\Users\atikm\AppData\Local\Programs\Python\Python313\Lib\site-packages\telegram\ext\_updater.py", line 371, in polling_action_cb
    updates = await self.bot.get_updates(
              ^^^^^^^^^^^^^^^^^^^^^^^^^^^
    ...<7 lines>...
    )
    ^
  File "C:\Users\atikm\AppData\Local\Programs\Python\Python313\Lib\site-packages\telegram\ext\_extbot.py", line 650, in get_updates
    updates = await super().get_updates(
              ^^^^^^^^^^^^^^^^^^^^^^^^^^
    ...<9 lines>...
    )
    ^
  File "C:\Users\atikm\AppData\Local\Programs\Python\Python313\Lib\site-packages\telegram\_bot.py", line 4480, in get_updates
    await self._post(
    ^^^^^^^^^^^^^^^^^
    ...<7 lines>...
    ),
    ^
  File "C:\Users\atikm\AppData\Local\Programs\Python\Python313\Lib\site-packages\telegram\_bot.py", line 619, in _post
    return await self._do_post(
           ^^^^^^^^^^^^^^^^^^^^
    ...<6 lines>...
    )
    ^
  File "C:\Users\atikm\AppData\Local\Programs\Python\Python313\Lib\site-packages\telegram\ext\_extbot.py", line 354, in _do_post
    return await super()._do_post(
           ^^^^^^^^^^^^^^^^^^^^^^^
    ...<6 lines>...
    )
    ^
  File "C:\Users\atikm\AppData\Local\Programs\Python\Python313\Lib\site-packages\telegram\_bot.py", line 648, in _do_post
    result = await request.post(
             ^^^^^^^^^^^^^^^^^^^
    ...<6 lines>...
    )
    ^
  File "C:\Users\atikm\AppData\Local\Programs\Python\Python313\Lib\site-packages\telegram\request\_baserequest.py", line 202, in post
    result = await self._request_wrapper(
             ^^^^^^^^^^^^^^^^^^^^^^^^^^^^
    ...<7 lines>...
    )
    ^
  File "C:\Users\atikm\AppData\Local\Programs\Python\Python313\Lib\site-packages\telegram\request\_baserequest.py", line 334, in _request_wrapper
    code, payload = await self.do_request(
                    ^^^^^^^^^^^^^^^^^^^^^^
    ...<7 lines>...
    )
    ^
  File "C:\Users\atikm\AppData\Local\Programs\Python\Python313\Lib\site-packages\telegram\request\_httpxrequest.py", line 317, in do_request
    raise NetworkError(f"httpx.{err.__class__.__name__}: {err}") from err
telegram.error.NetworkError: httpx.ConnectError: [Errno 11001] getaddrinfo failed
2025-01-27 00:33:56,242 - telegram.ext.Application - ERROR - No error handlers are registered, logging exception.
Traceback (most recent call last):
  File "C:\Users\atikm\AppData\Local\Programs\Python\Python313\Lib\site-packages\httpx\_transports\default.py", line 101, in map_httpcore_exceptions
    yield
  File "C:\Users\atikm\AppData\Local\Programs\Python\Python313\Lib\site-packages\httpx\_transports\default.py", line 394, in handle_async_request
    resp = await self._pool.handle_async_request(req)
           ^^^^^^^^^^^^^^^^^^^^^^^^^^^^^^^^^^^^^^^^^^
  File "C:\Users\atikm\AppData\Local\Programs\Python\Python313\Lib\site-packages\httpcore\_async\connection_pool.py", line 256, in handle_async_request
    raise exc from None
  File "C:\Users\atikm\AppData\Local\Programs\Python\Python313\Lib\site-packages\httpcore\_async\connection_pool.py", line 236, in handle_async_request
    response = await connection.handle_async_request(
               ^^^^^^^^^^^^^^^^^^^^^^^^^^^^^^^^^^^^^^
        pool_request.request
        ^^^^^^^^^^^^^^^^^^^^
    )
    ^
  File "C:\Users\atikm\AppData\Local\Programs\Python\Python313\Lib\site-packages\httpcore\_async\connection.py", line 101, in handle_async_request
    raise exc
  File "C:\Users\atikm\AppData\Local\Programs\Python\Python313\Lib\site-packages\httpcore\_async\connection.py", line 78, in handle_async_request
    stream = await self._connect(request)
             ^^^^^^^^^^^^^^^^^^^^^^^^^^^^
  File "C:\Users\atikm\AppData\Local\Programs\Python\Python313\Lib\site-packages\httpcore\_async\connection.py", line 124, in _connect
    stream = await self._network_backend.connect_tcp(**kwargs)
             ^^^^^^^^^^^^^^^^^^^^^^^^^^^^^^^^^^^^^^^^^^^^^^^^^
  File "C:\Users\atikm\AppData\Local\Programs\Python\Python313\Lib\site-packages\httpcore\_backends\auto.py", line 31, in connect_tcp
    return await self._backend.connect_tcp(
           ^^^^^^^^^^^^^^^^^^^^^^^^^^^^^^^^
    ...<5 lines>...
    )
    ^
  File "C:\Users\atikm\AppData\Local\Programs\Python\Python313\Lib\site-packages\httpcore\_backends\anyio.py", line 113, in connect_tcp
    with map_exceptions(exc_map):
         ~~~~~~~~~~~~~~^^^^^^^^^
  File "C:\Users\atikm\AppData\Local\Programs\Python\Python313\Lib\contextlib.py", line 162, in __exit__
    self.gen.throw(value)
    ~~~~~~~~~~~~~~^^^^^^^
  File "C:\Users\atikm\AppData\Local\Programs\Python\Python313\Lib\site-packages\httpcore\_exceptions.py", line 14, in map_exceptions
    raise to_exc(exc) from exc
httpcore.ConnectError: [Errno 11001] getaddrinfo failed

The above exception was the direct cause of the following exception:

Traceback (most recent call last):
  File "C:\Users\atikm\AppData\Local\Programs\Python\Python313\Lib\site-packages\telegram\request\_httpxrequest.py", line 293, in do_request
    res = await self._client.request(
          ^^^^^^^^^^^^^^^^^^^^^^^^^^^
    ...<6 lines>...
    )
    ^
  File "C:\Users\atikm\AppData\Local\Programs\Python\Python313\Lib\site-packages\httpx\_client.py", line 1540, in request
    return await self.send(request, auth=auth, follow_redirects=follow_redirects)
           ^^^^^^^^^^^^^^^^^^^^^^^^^^^^^^^^^^^^^^^^^^^^^^^^^^^^^^^^^^^^^^^^^^^^^^
  File "C:\Users\atikm\AppData\Local\Programs\Python\Python313\Lib\site-packages\httpx\_client.py", line 1629, in send
    response = await self._send_handling_auth(
               ^^^^^^^^^^^^^^^^^^^^^^^^^^^^^^^
    ...<4 lines>...
    )
    ^
  File "C:\Users\atikm\AppData\Local\Programs\Python\Python313\Lib\site-packages\httpx\_client.py", line 1657, in _send_handling_auth
    response = await self._send_handling_redirects(
               ^^^^^^^^^^^^^^^^^^^^^^^^^^^^^^^^^^^^
    ...<3 lines>...
    )
    ^
  File "C:\Users\atikm\AppData\Local\Programs\Python\Python313\Lib\site-packages\httpx\_client.py", line 1694, in _send_handling_redirects
    response = await self._send_single_request(request)
               ^^^^^^^^^^^^^^^^^^^^^^^^^^^^^^^^^^^^^^^^
  File "C:\Users\atikm\AppData\Local\Programs\Python\Python313\Lib\site-packages\httpx\_client.py", line 1730, in _send_single_request
    response = await transport.handle_async_request(request)
               ^^^^^^^^^^^^^^^^^^^^^^^^^^^^^^^^^^^^^^^^^^^^^
  File "C:\Users\atikm\AppData\Local\Programs\Python\Python313\Lib\site-packages\httpx\_transports\default.py", line 393, in handle_async_request
    with map_httpcore_exceptions():
         ~~~~~~~~~~~~~~~~~~~~~~~^^
  File "C:\Users\atikm\AppData\Local\Programs\Python\Python313\Lib\contextlib.py", line 162, in __exit__
    self.gen.throw(value)
    ~~~~~~~~~~~~~~^^^^^^^
  File "C:\Users\atikm\AppData\Local\Programs\Python\Python313\Lib\site-packages\httpx\_transports\default.py", line 118, in map_httpcore_exceptions
    raise mapped_exc(message) from exc
httpx.ConnectError: [Errno 11001] getaddrinfo failed

The above exception was the direct cause of the following exception:

Traceback (most recent call last):
  File "C:\Users\atikm\AppData\Local\Programs\Python\Python313\Lib\site-packages\telegram\ext\_updater.py", line 750, in _network_loop_retry
    if not await do_action():
           ^^^^^^^^^^^^^^^^^
  File "C:\Users\atikm\AppData\Local\Programs\Python\Python313\Lib\site-packages\telegram\ext\_updater.py", line 744, in do_action
    return action_cb_task.result()
           ~~~~~~~~~~~~~~~~~~~~~^^
  File "C:\Users\atikm\AppData\Local\Programs\Python\Python313\Lib\asyncio\futures.py", line 199, in result
    raise self._exception.with_traceback(self._exception_tb)
  File "C:\Users\atikm\AppData\Local\Programs\Python\Python313\Lib\asyncio\tasks.py", line 306, in __step_run_and_handle_result
    result = coro.throw(exc)
  File "C:\Users\atikm\AppData\Local\Programs\Python\Python313\Lib\site-packages\telegram\ext\_updater.py", line 371, in polling_action_cb
    updates = await self.bot.get_updates(
              ^^^^^^^^^^^^^^^^^^^^^^^^^^^
    ...<7 lines>...
    )
    ^
  File "C:\Users\atikm\AppData\Local\Programs\Python\Python313\Lib\site-packages\telegram\ext\_extbot.py", line 650, in get_updates
    updates = await super().get_updates(
              ^^^^^^^^^^^^^^^^^^^^^^^^^^
    ...<9 lines>...
    )
    ^
  File "C:\Users\atikm\AppData\Local\Programs\Python\Python313\Lib\site-packages\telegram\_bot.py", line 4480, in get_updates
    await self._post(
    ^^^^^^^^^^^^^^^^^
    ...<7 lines>...
    ),
    ^
  File "C:\Users\atikm\AppData\Local\Programs\Python\Python313\Lib\site-packages\telegram\_bot.py", line 619, in _post
    return await self._do_post(
           ^^^^^^^^^^^^^^^^^^^^
    ...<6 lines>...
    )
    ^
  File "C:\Users\atikm\AppData\Local\Programs\Python\Python313\Lib\site-packages\telegram\ext\_extbot.py", line 354, in _do_post
    return await super()._do_post(
           ^^^^^^^^^^^^^^^^^^^^^^^
    ...<6 lines>...
    )
    ^
  File "C:\Users\atikm\AppData\Local\Programs\Python\Python313\Lib\site-packages\telegram\_bot.py", line 648, in _do_post
    result = await request.post(
             ^^^^^^^^^^^^^^^^^^^
    ...<6 lines>...
    )
    ^
  File "C:\Users\atikm\AppData\Local\Programs\Python\Python313\Lib\site-packages\telegram\request\_baserequest.py", line 202, in post
    result = await self._request_wrapper(
             ^^^^^^^^^^^^^^^^^^^^^^^^^^^^
    ...<7 lines>...
    )
    ^
  File "C:\Users\atikm\AppData\Local\Programs\Python\Python313\Lib\site-packages\telegram\request\_baserequest.py", line 334, in _request_wrapper
    code, payload = await self.do_request(
                    ^^^^^^^^^^^^^^^^^^^^^^
    ...<7 lines>...
    )
    ^
  File "C:\Users\atikm\AppData\Local\Programs\Python\Python313\Lib\site-packages\telegram\request\_httpxrequest.py", line 317, in do_request
    raise NetworkError(f"httpx.{err.__class__.__name__}: {err}") from err
telegram.error.NetworkError: httpx.ConnectError: [Errno 11001] getaddrinfo failed
2025-01-27 00:34:26,743 - httpx - INFO - HTTP Request: POST https://api.telegram.org/bot8077274379:AAFawJIixuMK47T9RpxiMv0TC_FnYLA6LWI/getUpdates "HTTP/1.1 200 OK"
2025-01-27 00:34:26,744 - __main__ - INFO - INFO - User ERROR (ID: 2142334821) started the bot.
2025-01-27 00:34:27,484 - httpx - INFO - HTTP Request: POST https://api.telegram.org/bot8077274379:AAFawJIixuMK47T9RpxiMv0TC_FnYLA6LWI/sendMessage "HTTP/1.1 200 OK"
2025-01-27 00:34:36,919 - httpx - INFO - HTTP Request: POST https://api.telegram.org/bot8077274379:AAFawJIixuMK47T9RpxiMv0TC_FnYLA6LWI/getUpdates "HTTP/1.1 200 OK"
2025-01-27 00:34:47,135 - httpx - INFO - HTTP Request: POST https://api.telegram.org/bot8077274379:AAFawJIixuMK47T9RpxiMv0TC_FnYLA6LWI/getUpdates "HTTP/1.1 200 OK"
2025-01-27 00:34:58,720 - httpx - INFO - HTTP Request: POST https://api.telegram.org/bot8077274379:AAFawJIixuMK47T9RpxiMv0TC_FnYLA6LWI/getUpdates "HTTP/1.1 200 OK"
2025-01-27 00:35:12,269 - httpx - INFO - HTTP Request: POST https://api.telegram.org/bot8077274379:AAFawJIixuMK47T9RpxiMv0TC_FnYLA6LWI/getUpdates "HTTP/1.1 200 OK"
2025-01-27 00:35:22,776 - httpx - INFO - HTTP Request: POST https://api.telegram.org/bot8077274379:AAFawJIixuMK47T9RpxiMv0TC_FnYLA6LWI/getUpdates "HTTP/1.1 200 OK"
2025-01-27 00:35:33,017 - httpx - INFO - HTTP Request: POST https://api.telegram.org/bot8077274379:AAFawJIixuMK47T9RpxiMv0TC_FnYLA6LWI/getUpdates "HTTP/1.1 200 OK"
2025-01-27 00:35:43,243 - httpx - INFO - HTTP Request: POST https://api.telegram.org/bot8077274379:AAFawJIixuMK47T9RpxiMv0TC_FnYLA6LWI/getUpdates "HTTP/1.1 200 OK"
2025-01-27 00:35:53,508 - httpx - INFO - HTTP Request: POST https://api.telegram.org/bot8077274379:AAFawJIixuMK47T9RpxiMv0TC_FnYLA6LWI/getUpdates "HTTP/1.1 200 OK"
2025-01-27 00:36:03,657 - httpx - INFO - HTTP Request: POST https://api.telegram.org/bot8077274379:AAFawJIixuMK47T9RpxiMv0TC_FnYLA6LWI/getUpdates "HTTP/1.1 200 OK"
2025-01-27 00:36:13,857 - httpx - INFO - HTTP Request: POST https://api.telegram.org/bot8077274379:AAFawJIixuMK47T9RpxiMv0TC_FnYLA6LWI/getUpdates "HTTP/1.1 200 OK"
2025-01-27 00:36:24,297 - httpx - INFO - HTTP Request: POST https://api.telegram.org/bot8077274379:AAFawJIixuMK47T9RpxiMv0TC_FnYLA6LWI/getUpdates "HTTP/1.1 200 OK"
2025-01-27 00:36:34,788 - httpx - INFO - HTTP Request: POST https://api.telegram.org/bot8077274379:AAFawJIixuMK47T9RpxiMv0TC_FnYLA6LWI/getUpdates "HTTP/1.1 200 OK"
2025-01-27 00:36:45,399 - httpx - INFO - HTTP Request: POST https://api.telegram.org/bot8077274379:AAFawJIixuMK47T9RpxiMv0TC_FnYLA6LWI/getUpdates "HTTP/1.1 200 OK"
